Workbook

Sheet Main Center
AF2: Summary Table
D4: Year 00 | E4: Year 01 | F4: Year 02 | G4: Year 03 | H4: Year 04 | I4: Year 05 | J4: Year 06 | K4: Year 07 | L4: Year 08 | M4: Year 09 | N4: Year 10 | O4: Year 11 | P4: Year 12 | Q4: Year 13 | R4: Year 14 | S4: Year 15 | T4: Year 16 | U4: Year 17 | V4: Year 18 | W4: Year 19 | X4: Year 20 | AE4: Year 00 - Year 05 | AF4: Year 06 - Year 10 | AG4: Year 11 - Year 15 | AH4: Year 16 - Year 20
A5: Assumptions
A6: Number of Centers | D6: 1 | AD6: Sales | AE6: =SUM(D23:I23) -> 33003.496 | AF6: =SUM(J23:N23) -> 71306.604 | AG6: =SUM(O23:S23) -> 124220.5 | AH6: =SUM(T23:X23) -> 172839.27
A7: Costs of Center Setup (Investment) | B7: Gross Profit (USD) | D7: =2000000/D13 -> 14814.815 | AD7: Revenue | AE7: =SUM(D28:I28) -> 19.395702 | AF7: =SUM(J28:N28) -> 61.466229 | AG7: =SUM(O28:S28) -> 156.95018 | AH7: =SUM(T28:X28) -> 322.88972
A8: Sales Volumes | E8: 4435 | AD8: Expenses | AE8: =SUM(D30:I30) -> 15.516561 | AF8: =SUM(J30:N30) -> 49.172983 | AG8: =SUM(O30:S30) -> 125.56015 | AH8: =SUM(T30:X30) -> 258.31177
A9: Sales Growth | C9: 0.1 | E9: 0.2 | F9: =E9 -> 0.2 | G9: =F9 -> 0.2 | H9: =G9 -> 0.2 | I9: =H9 -> 0.2 | J9: 0.15 | K9: =J9 -> 0.15 | L9: =K9 -> 0.15 | M9: =L9 -> 0.15 | N9: =M9 -> 0.15 | O9: 0.1 | P9: =O9 -> 0.1 | Q9: =P9 -> 0.1 | R9: =Q9 -> 0.1 | S9: =R9 -> 0.1 | T9: 0.05 | U9: =T9 -> 0.05 | V9: =U9 -> 0.05 | W9: =V9 -> 0.05 | X9: =W9 -> 0.05 | AD9: EBITDA | AE9: =SUM(D43:I43) -> -25.48329 | AF9: =SUM(J43:N43) -> -18.22336 | AG9: =SUM(O43:S43) -> 13.683013 | AH9: =SUM(T43:X43) -> 77.7606
A10: Price Increase | E10: 0.16 | F10: 0.086687643 | G10: 0.087072291 | H10: 0.090769398 | I10: 0.078758145 | J10: 0.07905988 | K10: 0.079373414 | L10: 0.079699048 | M10: 0.080037074 | N10: 0.080387773 | O10: 0.080751414 | P10: 0.08112825 | Q10: 0.081518518 | R10: 0.081922436 | S10: 0.082340198 | T10: 0.082771977 | U10: 0.083217919 | V10: 0.08367814 | W10: 0.084152725 | X10: 0.084641726 | AD10: Net Profit/Loss | AE10: =SUM(D51:I51) -> -27.48329 | AF10: =SUM(J51:N51) -> -18.22336 | AG10: =SUM(O51:S51) -> 13.683013 | AH10: =SUM(T51:X51) -> 77.7606
A11: Salary Increase | E11: 0.16 | F11: 0.1 | G11: 0.1 | H11: 0.11 | I11: 0.07 | J11: 0.07 | K11: 0.07 | L11: 0.07 | M11: 0.07 | N11: 0.07 | O11: 0.07 | P11: 0.07 | Q11: 0.07 | R11: 0.07 | S11: 0.07 | T11: 0.07 | U11: 0.07 | V11: 0.07 | W11: 0.07 | X11: 0.07
A12: Local Inflation | E12: 0.16 | F12: 0.07 | G12: 0.07 | H12: 0.07 | I12: 0.07 | J12: 0.07 | K12: 0.07 | L12: 0.07 | M12: 0.07 | N12: 0.07 | O12: 0.07 | P12: 0.07 | Q12: 0.07 | R12: 0.07 | S12: 0.07 | T12: 0.07 | U12: 0.07 | V12: 0.07 | W12: 0.07 | X12: 0.07
A13: Re. / $ Parity | D13: 135 | E13: 141.75 | F13: 148.8375 | G13: 156.27938 | H13: 164.09334 | I13: 172.29801 | J13: 180.91291 | K13: 189.95856 | L13: 199.45648 | M13: 209.42931 | N13: 219.90077 | O13: 230.89581 | P13: 242.4406 | Q13: 254.56263 | R13: 267.29077 | S13: 280.6553 | T13: 294.68807 | U13: 309.42247 | V13: 324.8936 | W13: 341.13828 | X13: 358.19519
A14: Rent Inflation | E14: 0.1 | F14: =E14 -> 0.1 | G14: =F14 -> 0.1 | H14: =G14 -> 0.1 | I14: =H14 -> 0.1 | J14: =I14 -> 0.1 | K14: =J14 -> 0.1 | L14: =K14 -> 0.1 | M14: =L14 -> 0.1 | ... X14: =W14 -> 0.1
A15: Reagents/Consumables Inflation | E15: 0.09889959 | F15: 0.075175 | G15: 0.075175 | H15: 0.075175 | I15: 0.075175 | J15: 0.075175 | K15: 0.075175 | L15: 0.075175 | M15: 0.075175 | N15: 0.075175 | O15: 0.075175 | P15: 0.075175 | Q15: 0.075175 | R15: 0.075175 | S15: 0.075175 | T15: 0.075175 | U15: 0.075175 | V15: 0.075175 | W15: 0.075175 | X15: 0.075175
A16: Number of FTEs | C16: =COUNT('Staff Costs'!C4:C10) -> 7 | E16: =$C$16*$D$6 -> 7 | F16: =$C$16*$D$6 -> 7 | G16: =$C$16*$D$6 -> 7 | H16: =$C$16*$D$6 -> 7 | I16: =$C$16*$D$6 -> 7 | J16: =$C$16*$D$6 -> 7 | K16: =$C$16*$D$6 -> 7 | L16: =$C$16*$D$6 -> 7 | ... X16: =$C$16*$D$6 -> 7
A17: Salary including Fringe | C17: ='Staff Costs'!D11/1.1/C16 -> 28607.143 | E17: =C17*(1+E11) -> 33184.286 | F17: =E17*(1+F11) -> 36502.714 | G17: =F17*(1+G11) -> 40152.986 | H17: =G17*(1+H11) -> 44569.814 | I17: =H17*(1+I11) -> 47689.701 | J17: =I17*(1+J11) -> 51027.98 | K17: =J17*(1+K11) -> 54599.939 | L17: =K17*(1+L11) -> 58421.935 | M17: =L17*(1+M11) -> 62511.47 | ... X17: =W17*(1+X11) -> 131577.39
A18: =A36 -> Supplies | B18: Supplies | C18: =SUMIF('Overhead Costs'!$B$3:$B$14,'Main Center'!B18,'Overhead Costs'!$C$3:$C$14) -> 31660 | E18: =C18*(1+E12) -> 36725.6 | F18: =E18*(1+F12) -> 39296.392 | G18: =F18*(1+G12) -> 42047.139 | H18: =G18*(1+H12) -> 44990.439 | I18: =H18*(1+I12) -> 48139.77 | J18: =I18*(1+J12) -> 51509.554 | K18: =J18*(1+K12) -> 55115.223 | L18: =K18*(1+L12) -> 58973.288 | M18: =L18*(1+M12) -> 63101.418 | ... X18: =W18*(1+X12) -> 132819.14
A19: =A37 -> Utilities | B19: Utilities | C19: =SUMIF('Overhead Costs'!$B$3:$B$14,'Main Center'!B19,'Overhead Costs'!$C$3:$C$14) -> 29370 | E19: =C19*(1+E12) -> 34069.2 | F19: =E19*(1+F12) -> 36454.044 | G19: =F19*(1+G12) -> 39005.827 | H19: =G19*(1+H12) -> 41736.235 | I19: =H19*(1+I12) -> 44657.771 | J19: =I19*(1+J12) -> 47783.815 | K19: =J19*(1+K12) -> 51128.683 | L19: =K19*(1+L12) -> 54707.69 | M19: =L19*(1+M12) -> 58537.229 | ... X19: =W19*(1+X12) -> 123212.2
A20: SG&A | B20: SG&A | C20: ='Overhead Costs'!C15-'Main Center'!C19-'Main Center'!C18 -> 171995 | E20: =C20*(((1+E14)+(1+E12))/2) -> 194354.35 | F20: =E20*(((1+F14)+(1+F12))/2) -> 210874.47 | G20: =F20*(((1+G14)+(1+G12))/2) -> 228798.8 | H20: =G20*(((1+H14)+(1+H12))/2) -> 248246.7 | I20: =H20*(((1+I14)+(1+I12))/2) -> 269347.67 | J20: =I20*(((1+J14)+(1+J12))/2) -> 292242.22 | K20: =J20*(((1+K14)+(1+K12))/2) -> 317082.81 | L20: =K20*(((1+L14)+(1+L12))/2) -> 344034.85 | M20: =L20*(((1+M14)+(1+M12))/2) -> 373277.81 | ... X20: =W20*(((1+X14)+(1+X12))/2) -> 915712.81
B21: =C21-'Overhead Costs'!C15 -> 0 | C21: =SUM(C18:C20) -> 233025
A22: Stats
A23: Volumes | B23: Laboratory Volumes (`000) | E23: =E8*D6 -> 4435 | F23: =E23*(1+F9) -> 5322 | G23: =F23*(1+G9) -> 6386.4 | H23: =G23*(1+H9) -> 7663.68 | I23: =H23*(1+I9) -> 9196.416 | J23: =I23*(1+J9) -> 10575.878 | K23: =J23*(1+K9) -> 12162.26 | L23: =K23*(1+L9) -> 13986.599 | M23: =L23*(1+M9) -> 16084.589 | ... X23: =W23*(1+X9) -> 38020.492
A24: Average Charge | C24: =Average_charge_3_Main_centers!B9 -> 413.65962 | E24: =C24*(1+E10) -> 479.84516 | F24: =E24*(1+F10) -> 521.44181 | G24: =F24*(1+G10) -> 566.84494 | H24: =G24*(1+H10) -> 618.29711 | I24: =H24*(1+I10) -> 666.99304 | J24: =I24*(1+J10) -> 719.72543 | K24: =J24*(1+K10) -> 776.8525 | L24: =K24*(1+L10) -> 838.7669 | M24: =L24*(1+M10) -> 905.89935 | ... X24: =W24*(1+X10) -> 2164.6438
A27: Financials | C27: 1
A28: Gross Revenue | B28: Outpatient | E28: =E24*E23/1000000 -> 2.1281133 | F28: =F24*F23/1000000 -> 2.7751133 | G28: =G24*G23/1000000 -> 3.6200985 | H28: =H24*H23/1000000 -> 4.7384312 | I28: =I24*I23/1000000 -> 6.1339455 | J28: =J24*J23/1000000 -> 7.6117287 | K28: =K24*K23/1000000 -> 9.4482822 | L28: =L24*L23/1000000 -> 11.731496 | ... X28: =X24*X23/1000000 -> 82.300822
A29: Discount/Referral Incentive | B29: Discounts | C29: -0.2 | E29: =$C$29*E28 -> -0.42562266 | F29: =$C$29*F28 -> -0.55502266 | G29: =$C$29*G28 -> -0.7240197 | H29: =$C$29*H28 -> -0.94768624 | I29: =$C$29*I28 -> -1.2267891 | J29: =$C$29*J28 -> -1.5223457 | K29: =$C$29*K28 -> -1.8896564 | L29: =$C$29*L28 -> -2.3462993 | ... X29: =$C$29*X28 -> -16.460164
A30: Net Revenue | D30: =SUM(D28:D29) -> 0 | E30: =SUM(E28:E29) -> 1.7024906 | F30: =SUM(F28:F29) -> 2.2200906 | G30: =SUM(G28:G29) -> 2.8960788 | H30: =SUM(H28:H29) -> 3.790745 | I30: =SUM(I28:I29) -> 4.9071564 | J30: =SUM(J28:J29) -> 6.0893829 | K30: =SUM(K28:K29) -> 7.5586258 | ... X30: =SUM(X28:X29) -> 65.840658
A32: Expenses
A34: Staff Cost | B34: Staff | E34: =E17*E16*12/1000000 -> 2.78748 | F34: =F17*F16*12/1000000 -> 3.066228 | G34: =G17*G16*12/1000000 -> 3.3728508 | H34: =H17*H16*12/1000000 -> 3.7438644 | I34: =I17*I16*12/1000000 -> 4.0059349 | J34: =J17*J16*12/1000000 -> 4.2863503 | K34: =K17*K16*12/1000000 -> 4.5863949 | L34: =L17*L16*12/1000000 -> 4.9074425 | ... X34: =X17*X16*12/1000000 -> 11.052501
A35: Reagents/Consumables | B35: Reagents/Consumables | C35: =Reagent_Costing!BK39 -> 0.23000483 | E35: =$C$35*E28 -> 0.48947634 | F35: =E35*(1+F9)*(1+F15) -> 0.63152726 | G35: =F35*(1+G9)*(1+G15) -> 0.81480279 | H35: =G35*(1+H9)*(1+H15) -> 1.0512667 | I35: =H35*(1+I9)*(1+I15) -> 1.3563548 | J35: =I35*(1+J9)*(1+J15) -> 1.6770666 | K35: =J35*(1+K9)*(1+K15) -> 2.0736111 | L35: =K35*(1+L9)*(1+L15) -> 2.563919 | M35: =L35*(1+M9)*(1+M15) -> 3.1701609 | ... X35: =W35*(1+X9)*(1+X15) -> 16.632587
A36: Supplies | B36: Supplies | E36: =E18*$D$6/1000000*12 -> 0.4407072 | F36: =F18*$D$6/1000000*12 -> 0.4715567 | G36: =G18*$D$6/1000000*12 -> 0.50456567 | H36: =H18*$D$6/1000000*12 -> 0.53988527 | I36: =I18*$D$6/1000000*12 -> 0.57767724 | J36: =J18*$D$6/1000000*12 -> 0.61811465 | K36: =K18*$D$6/1000000*12 -> 0.66138267 | L36: =L18*$D$6/1000000*12 -> 0.70767946 | ... X36: =X18*$D$6/1000000*12 -> 1.5938297
A37: Utilities | B37: Utilities | E37: =E19*$D$6/1000000*12 -> 0.4088304 | F37: =F19*$D$6/1000000*12 -> 0.43744853 | G37: =G19*$D$6/1000000*12 -> 0.46806992 | H37: =H19*$D$6/1000000*12 -> 0.50083482 | I37: =I19*$D$6/1000000*12 -> 0.53589326 | J37: =J19*$D$6/1000000*12 -> 0.57340579 | K37: =K19*$D$6/1000000*12 -> 0.61354419 | L37: =L19*$D$6/1000000*12 -> 0.65649228 | ... X37: =X19*$D$6/1000000*12 -> 1.4785464
A38: SG&A | B38: General / Administration | E38: =(E20*$D$6/1000000*12) -> 2.3322522 | F38: =(F20*$D$6/1000000*12) -> 2.5304936 | G38: =(G20*$D$6/1000000*12) -> 2.7455856 | H38: =(H20*$D$6/1000000*12) -> 2.9789604 | I38: =(I20*$D$6/1000000*12) -> 3.232172 | J38: =(J20*$D$6/1000000*12) -> 3.5069066 | K38: =(K20*$D$6/1000000*12) -> 3.8049937 | L38: =(L20*$D$6/1000000*12) -> 4.1284182 | ... X38: =(X20*$D$6/1000000*12) -> 10.988554
A39: Central Support | B39: Central Support Services Costs | E39: =(('Central _support'!D10/1000000))/31 -> 0.13583923 | F39: =E39*(1+F12) -> 0.14534797 | G39: =F39*(1+G12) -> 0.15552233 | H39: =G39*(1+H12) -> 0.16640889 | I39: =H39*(1+I12) -> 0.17805752 | J39: =I39*(1+J12) -> 0.19052154 | K39: =J39*(1+K12) -> 0.20385805 | L39: =K39*(1+L12) -> 0.21812811 | M39: =L39*(1+M12) -> 0.23339708 | ... X39: =W39*(1+X12) -> 0.4912663
A40: Marketing | B40: General / Administration | C40: =1% -> 0.01 | E40: =+($C$40*E28) -> 0.021281133 | F40: =+($C$40*F28) -> 0.027751133 | G40: =+($C$40*G28) -> 0.036200985 | H40: =+($C$40*H28) -> 0.047384312 | I40: =+($C$40*I28) -> 0.061339455 | J40: =+($C$40*J28) -> 0.076117287 | K40: =+($C$40*K28) -> 0.094482822 | L40: =+($C$40*L28) -> 0.11731496 | ... X40: =+($C$40*X28) -> 0.82300822
A41: Total Expenses | D41: =SUM(D34:D40) -> 0 | E41: =SUM(E34:E40) -> 6.6158665 | F41: =SUM(F34:F40) -> 7.3103532 | G41: =SUM(G34:G40) -> 8.0975981 | H41: =SUM(H34:H40) -> 9.0286048 | I41: =SUM(I34:I40) -> 9.9474292 | J41: =SUM(J34:J40) -> 10.928483 | K41: =SUM(K34:K40) -> 12.038267 | ... X41: =SUM(X34:X40) -> 43.060292
A43: Earning / (Deficit) before Interest & Depreciation | C43: Rs. | D43: =D30-D41 -> 0 | E43: =E30-E41 -> -4.9133759 | F43: =F30-F41 -> -5.0902626 | G43: =G30-G41 -> -5.2015193 | H43: =H30-H41 -> -5.2378598 | I43: =I30-I41 -> -5.0402728 | J43: =J30-J41 -> -4.8390999 | K43: =K30-K41 -> -4.4796416 | ... X43: =X30-X41 -> 22.780366
C44: $ | D44: 0 | E44: =E43/E13 -> -0.034662264 | F44: =F43/F13 -> -0.034200135 | G44: =G43/G13 -> -0.033283466 | H44: =H43/H13 -> -0.031920002 | I44: =I43/I13 -> -0.029253227 | J44: =J43/J13 -> -0.026748228 | K44: =K43/K13 -> -0.023582205 | L44: =L43/L13 -> -0.019624317 | ... X44: =X43/X13 -> 0.063597631
A46: EBITDA Margin | D46: 0 | E46: =E43/E28 -> -2.3087943 | F46: =F43/F28 -> -1.834254 | G46: =G43/G28 -> -1.4368447 | H46: =H43/H28 -> -1.1053996 | I46: =I43/I28 -> -0.82170159 | J46: =J43/J28 -> -0.63574256 | K46: =K43/K28 -> -0.47412234 | L46: =L43/L28 -> -0.3336486 | ... X46: =X43/X28 -> 0.2767939
A48: Sales Tax | C48: 0 | D48: =D49*D13 -> -2 | E48: =$C$48*E28 -> 0 | F48: =$C$48*F28 -> 0 | G48: =$C$48*G28 -> 0 | H48: =$C$48*H28 -> 0 | I48: =$C$48*I28 -> 0 | J48: =$C$48*J28 -> 0 | K48: =$C$48*K28 -> 0 | L48: =$C$48*L28 -> 0 | ... X48: =$C$48*X28 -> 0
A49: Depreciation | B49: Ongoing Capital Equipment | C49: $ | D49: =-D6*D7/1000000 -> -0.014814815 | E49: =-E6*E7/1000000 -> 0 | F49: =-F6*F7/1000000 -> 0 | G49: =-G6*G7/1000000 -> 0 | H49: =-H6*H7/1000000 -> 0 | I49: =-I6*I7/1000000 -> 0 | J49: =-J6*J7/1000000 -> 0 | K49: =-K6*K7/1000000 -> 0 | ... X49: =-X6*X7/1000000 -> 0 | Y49: =SUM(D49:X49) -> -0.014814815
...

Sheet Satellite Centers
AF2: Summary Table
A4: South Karachi | D4: Satellite Center | E4: Year 01 | F4: Year 02 | G4: Year 03 | H4: Year 04 | I4: Year 05 | J4: Year 06 | K4: Year 07 | L4: Year 08 | M4: Year 09 | N4: Year 10 | O4: Year 11 | P4: Year 12 | Q4: Year 13 | R4: Year 14 | S4: Year 15 | T4: Year 16 | U4: Year 17 | V4: Year 18 | W4: Year 19 | X4: Year 20 | AE4: Year 00 - Year 05 | AF4: Year 06 - Year 10 | AG4: Year 11 - Year 15 | AH4: Year 16 - Year 20
A5: Assumptions
A6: Number of Centers | D6: 1 | AD6: Sales | AE6: =SUM(D23:I23) -> 33003.496 | AF6: =SUM(J23:N23) -> 71306.604 | AG6: =SUM(O23:S23) -> 124220.5 | AH6: =SUM(T23:X23) -> 172839.27
A7: Costs of Center Setup (Investment) | D7: =1000000/D13 -> 7407.4074 | AD7: Revenue | AE7: =SUM(D28:I28) -> 19.395702 | AF7: =SUM(J28:N28) -> 61.466229 | AG7: =SUM(O28:S28) -> 156.95018 | AH7: =SUM(T28:X28) -> 322.88972
A8: Sales Volumes | E8: 4435 | AD8: Expenses | AE8: =SUM(D30:I30) -> 15.516561 | AF8: =SUM(J30:N30) -> 49.172983 | AG8: =SUM(O30:S30) -> 125.56015 | AH8: =SUM(T30:X30) -> 258.31177
A9: Sales Growth | E9: 0.2 | F9: =E9 -> 0.2 | G9: =F9 -> 0.2 | H9: =G9 -> 0.2 | I9: =H9 -> 0.2 | J9: 0.15 | K9: =J9 -> 0.15 | L9: =K9 -> 0.15 | M9: =L9 -> 0.15 | N9: =M9 -> 0.15 | O9: 0.1 | P9: =O9 -> 0.1 | Q9: =P9 -> 0.1 | R9: =Q9 -> 0.1 | S9: =R9 -> 0.1 | T9: 0.05 | U9: =T9 -> 0.05 | V9: =U9 -> 0.05 | W9: =V9 -> 0.05 | X9: =W9 -> 0.05 | AD9: EBITDA | AE9: =SUM(D43:I43) -> -15.449774 | AF9: =SUM(J43:N43) -> -4.591185 | AG9: =SUM(O43:S43) -> 31.800559 | AH9: =SUM(T43:X43) -> 101.33271
A10: Price Increase | E10: 0.16 | F10: 0.086687643 | G10: 0.087072291 | H10: 0.090769398 | I10: 0.078758145 | J10: 0.07905988 | K10: 0.079373414 | L10: 0.079699048 | M10: 0.080037074 | N10: 0.080387773 | O10: 0.080751414 | P10: 0.08112825 | Q10: 0.081518518 | R10: 0.081922436 | S10: 0.082340198 | T10: 0.082771977 | U10: 0.083217919 | V10: 0.08367814 | W10: 0.084152725 | X10: 0.084641726 | AD10: Net Profit/Loss | AE10: =SUM(D51:I51) -> -16.449774 | AF10: =SUM(J51:N51) -> -4.591185 | AG10: =SUM(O51:S51) -> 31.800559 | AH10: =SUM(T51:X51) -> 101.33271
A11: Salary Increase | E11: 0.16 | F11: 0.1 | G11: 0.1 | H11: 0.11 | I11: 0.07 | J11: 0.07 | K11: 0.07 | L11: 0.07 | M11: 0.07 | N11: 0.07 | O11: 0.07 | P11: 0.07 | Q11: 0.07 | R11: 0.07 | S11: 0.07 | T11: 0.07 | U11: 0.07 | V11: 0.07 | W11: 0.07 | X11: 0.07
A12: Local Inflation | E12: 0.16 | F12: 0.07 | G12: 0.07 | H12: 0.07 | I12: 0.07 | J12: 0.07 | K12: 0.07 | L12: 0.07 | M12: 0.07 | N12: 0.07 | O12: 0.07 | P12: 0.07 | Q12: 0.07 | R12: 0.07 | S12: 0.07 | T12: 0.07 | U12: 0.07 | V12: 0.07 | W12: 0.07 | X12: 0.07
A13: Re. / $ Parity | D13: 135 | E13: 141.75 | F13: 148.8375 | G13: 156.27938 | H13: 164.09334 | I13: 172.29801 | J13: 180.91291 | K13: 189.95856 | L13: 199.45648 | M13: 209.42931 | N13: 219.90077 | O13: 230.89581 | P13: 242.4406 | Q13: 254.56263 | R13: 267.29077 | S13: 280.6553 | T13: 294.68807 | U13: 309.42247 | V13: 324.8936 | W13: 341.13828 | X13: 358.19519
A14: Rent Inflation | E14: 0.13 | F14: 0.13 | G14: 0.13 | H14: 0.13 | I14: 0.13 | J14: 0.13 | K14: 0.13 | L14: 0.13 | M14: 0.13 | N14: 0.13 | O14: 0.13 | P14: 0.13 | Q14: 0.13 | R14: 0.13 | S14: 0.13 | T14: 0.13 | U14: 0.13 | V14: 0.13 | W14: 0.13 | X14: 0.13
A15: Reagents/Consumables Inflation | E15: 0.09889959 | F15: 0.075175 | G15: 0.075175 | H15: 0.075175 | I15: 0.075175 | J15: 0.075175 | K15: 0.075175 | L15: 0.075175 | M15: 0.075175 | N15: 0.075175 | O15: 0.075175 | P15: 0.075175 | Q15: 0.075175 | R15: 0.075175 | S15: 0.075175 | T15: 0.075175 | U15: 0.075175 | V15: 0.075175 | W15: 0.075175 | X15: 0.075175
A16: Number of FTEs | C16: =COUNT('Staff Costs'!C15:C20) -> 6 | E16: =$C$16*$D$6 -> 6 | F16: =$C$16*$D$6 -> 6 | G16: =$C$16*$D$6 -> 6 | H16: =$C$16*$D$6 -> 6 | I16: =$C$16*$D$6 -> 6 | J16: =$C$16*$D$6 -> 6 | K16: =$C$16*$D$6 -> 6 | L16: =$C$16*$D$6 -> 6 | ... X16: =$C$16*$D$6 -> 6
A17: Salary including Fringe | C17: ='Staff Costs'!D21/1.1/C16 -> 29825.152 | E17: =C17*(1+E11) -> 34597.176 | F17: =E17*(1+F11) -> 38056.893 | G17: =F17*(1+G11) -> 41862.583 | H17: =G17*(1+H11) -> 46467.467 | I17: =H17*(1+I11) -> 49720.189 | J17: =I17*(1+J11) -> 53200.603 | K17: =J17*(1+K11) -> 56924.645 | L17: =K17*(1+L11) -> 60909.37 | M17: =L17*(1+M11) -> 65173.026 | ... X17: =W17*(1+X11) -> 137179.57
A18: Supplies | B18: Supplies | C18: =SUMIF('Overhead Costs'!$B$19:$B$31,'Main Center'!B18,'Overhead Costs'!$C$19:$C$31) -> 1308 | E18: =C18*(1+E12) -> 1517.28 | F18: =E18*(1+F12) -> 1623.4896 | G18: =F18*(1+G12) -> 1737.1339 | H18: =G18*(1+H12) -> 1858.7332 | I18: =H18*(1+I12) -> 1988.8446 | J18: =I18*(1+J12) -> 2128.0637 | K18: =J18*(1+K12) -> 2277.0281 | L18: =K18*(1+L12) -> 2436.4201 | M18: =L18*(1+M12) -> 2606.9695 | ... X18: =W18*(1+X12) -> 5487.2849
A19: Utilities | B19: Utilities | C19: =SUMIF('Overhead Costs'!$B$19:$B$31,'Main Center'!B19,'Overhead Costs'!$C$19:$C$31) -> 13826 | E19: =C19*(1+E12) -> 16038.16 | F19: =E19*(1+F12) -> 17160.831 | G19: =F19*(1+G12) -> 18362.089 | H19: =G19*(1+H12) -> 19647.436 | I19: =H19*(1+I12) -> 21022.756 | J19: =I19*(1+J12) -> 22494.349 | K19: =J19*(1+K12) -> 24068.953 | L19: =K19*(1+L12) -> 25753.78 | M19: =L19*(1+M12) -> 27556.545 | ... X19: =W19*(1+X12) -> 58002.447
A20: SG&A | B20: SG&A | C20: ='Overhead Costs'!C32-'Satellite Centers'!C18-'Satellite Centers'!C19 -> 110457 | E20: =C20*(((1+E14)+(1+E12))/2) -> 126473.26 | F20: =E20*(((1+F14)+(1+F12))/2) -> 139120.59 | G20: =F20*(((1+G14)+(1+G12))/2) -> 153032.65 | H20: =G20*(((1+H14)+(1+H12))/2) -> 168335.92 | I20: =H20*(((1+I14)+(1+I12))/2) -> 185169.51 | J20: =I20*(((1+J14)+(1+J12))/2) -> 203686.46 | K20: =J20*(((1+K14)+(1+K12))/2) -> 224055.1 | L20: =K20*(((1+L14)+(1+L12))/2) -> 246460.61 | M20: =L20*(((1+M14)+(1+M12))/2) -> 271106.68 | ... X20: =W20*(((1+X14)+(1+X12))/2) -> 773498.99
A22: Stats
A23: Volumes | B23: Laboratory Volumes (`000) | E23: =E8*D6 -> 4435 | F23: =E23*(1+F9) -> 5322 | G23: =F23*(1+G9) -> 6386.4 | H23: =G23*(1+H9) -> 7663.68 | I23: =H23*(1+I9) -> 9196.416 | J23: =I23*(1+J9) -> 10575.878 | K23: =J23*(1+K9) -> 12162.26 | L23: =K23*(1+L9) -> 13986.599 | M23: =L23*(1+M9) -> 16084.589 | ... X23: =W23*(1+X9) -> 38020.492 | Z23: =(X23-E23)/E23 -> 7.5728279
A24: Average Revenue | C24: ='Main Center'!C24 -> 413.65962 | E24: =C24*(1+E10) -> 479.84516 | F24: =E24*(1+F10) -> 521.44181 | G24: =F24*(1+G10) -> 566.84494 | H24: =G24*(1+H10) -> 618.29711 | I24: =H24*(1+I10) -> 666.99304 | J24: =I24*(1+J10) -> 719.72543 | K24: =J24*(1+K10) -> 776.8525 | L24: =K24*(1+L10) -> 838.7669 | M24: =L24*(1+M10) -> 905.89935 | ... X24: =W24*(1+X10) -> 2164.6438
A27: Financials
A28: Gross Revenue | B28: Outpatient | E28: =E24*E23/1000000 -> 2.1281133 | F28: =F24*F23/1000000 -> 2.7751133 | G28: =G24*G23/1000000 -> 3.6200985 | H28: =H24*H23/1000000 -> 4.7384312 | I28: =I24*I23/1000000 -> 6.1339455 | J28: =J24*J23/1000000 -> 7.6117287 | K28: =K24*K23/1000000 -> 9.4482822 | L28: =L24*L23/1000000 -> 11.731496 | ... X28: =X24*X23/1000000 -> 82.300822
A29: Discount | B29: Discounts | C29: =-20% -> -0.2 | E29: =$C$29*E28 -> -0.42562266 | F29: =$C$29*F28 -> -0.55502266 | G29: =$C$29*G28 -> -0.7240197 | H29: =$C$29*H28 -> -0.94768624 | I29: =$C$29*I28 -> -1.2267891 | J29: =$C$29*J28 -> -1.5223457 | K29: =$C$29*K28 -> -1.8896564 | L29: =$C$29*L28 -> -2.3462993 | ... X29: =$C$29*X28 -> -16.460164
A30: Net Revenue | D30: =SUM(D28:D29) -> 0 | E30: =SUM(E28:E29) -> 1.7024906 | F30: =SUM(F28:F29) -> 2.2200906 | G30: =SUM(G28:G29) -> 2.8960788 | H30: =SUM(H28:H29) -> 3.790745 | I30: =SUM(I28:I29) -> 4.9071564 | J30: =SUM(J28:J29) -> 6.0893829 | K30: =SUM(K28:K29) -> 7.5586258 | ... X30: =SUM(X28:X29) -> 65.840658
A32: Expenses
A34: Staff Cost | B34: Staff | E34: =E17*E16*12/1000000 -> 2.4909967 | F34: =F17*F16*12/1000000 -> 2.7400963 | G34: =G17*G16*12/1000000 -> 3.014106 | H34: =H17*H16*12/1000000 -> 3.3456576 | I34: =I17*I16*12/1000000 -> 3.5798536 | J34: =J17*J16*12/1000000 -> 3.8304434 | K34: =K17*K16*12/1000000 -> 4.0985744 | L34: =L17*L16*12/1000000 -> 4.3854746 | ... X34: =X17*X16*12/1000000 -> 9.8769291
A35: Med Surg | B35: Medical / Surgical | C35: =Reagent_Costing!BK39 -> 0.23000483 | E35: =$C$35*E28 -> 0.48947634 | F35: =E35*(1+F9)*(1+F15) -> 0.63152726 | G35: =F35*(1+G9)*(1+G15) -> 0.81480279 | H35: =G35*(1+H9)*(1+H15) -> 1.0512667 | I35: =H35*(1+I9)*(1+I15) -> 1.3563548 | J35: =I35*(1+J9)*(1+J15) -> 1.6770666 | K35: =J35*(1+K9)*(1+K15) -> 2.0736111 | L35: =K35*(1+L9)*(1+L15) -> 2.563919 | M35: =L35*(1+M9)*(1+M15) -> 3.1701609 | ... X35: =W35*(1+X9)*(1+X15) -> 16.632587
A36: Supplies | B36: Supplies | E36: =E18*$D$6/1000000*12 -> 0.01820736 | F36: =F18*$D$6/1000000*12 -> 0.019481875 | G36: =G18*$D$6/1000000*12 -> 0.020845606 | H36: =H18*$D$6/1000000*12 -> 0.022304799 | I36: =I18*$D$6/1000000*12 -> 0.023866135 | J36: =J18*$D$6/1000000*12 -> 0.025536764 | K36: =K18*$D$6/1000000*12 -> 0.027324338 | L36: =L18*$D$6/1000000*12 -> 0.029237041 | ... X36: =X18*$D$6/1000000*12 -> 0.065847419
A37: Utilities | B37: Utilities | E37: =E19*$D$6/1000000*12 -> 0.19245792 | F37: =F19*$D$6/1000000*12 -> 0.20592997 | G37: =G19*$D$6/1000000*12 -> 0.22034507 | H37: =H19*$D$6/1000000*12 -> 0.23576923 | I37: =I19*$D$6/1000000*12 -> 0.25227307 | J37: =J19*$D$6/1000000*12 -> 0.26993219 | K37: =K19*$D$6/1000000*12 -> 0.28882744 | L37: =L19*$D$6/1000000*12 -> 0.30904536 | ... X37: =X19*$D$6/1000000*12 -> 0.69602937
A38: SG & A | B38: General / Administration | E38: =(E20*$D$6/1000000*12) -> 1.5176792 | F38: =(F20*$D$6/1000000*12) -> 1.6694471 | G38: =(G20*$D$6/1000000*12) -> 1.8363918 | H38: =(H20*$D$6/1000000*12) -> 2.020031 | I38: =(I20*$D$6/1000000*12) -> 2.2220341 | J38: =(J20*$D$6/1000000*12) -> 2.4442375 | K38: =(K20*$D$6/1000000*12) -> 2.6886612 | L38: =(L20*$D$6/1000000*12) -> 2.9575274 | ... X38: =(X20*$D$6/1000000*12) -> 9.2819878
A39: Central Support | B39: Central Support Services Costs | E39: =(('Central _support'!D10/1000000))/31 -> 0.13583923 | F39: =E39*(1+F12) -> 0.14534797 | G39: =F39*(1+G12) -> 0.15552233 | H39: =G39*(1+H12) -> 0.16640889 | I39: =H39*(1+I12) -> 0.17805752 | J39: =I39*(1+J12) -> 0.19052154 | K39: =J39*(1+K12) -> 0.20385805 | L39: =K39*(1+L12) -> 0.21812811 | M39: =L39*(1+M12) -> 0.23339708 | ... X39: =W39*(1+X12) -> 0.4912663
A40: Marketing | B40: General / Administration | C40: =1% -> 0.01 | E40: =+($C$40*E28) -> 0.021281133 | F40: =+($C$40*F28) -> 0.027751133 | G40: =+($C$40*G28) -> 0.036200985 | H40: =+($C$40*H28) -> 0.047384312 | I40: =+($C$40*I28) -> 0.061339455 | J40: =+($C$40*J28) -> 0.076117287 | K40: =+($C$40*K28) -> 0.094482822 | L40: =+($C$40*L28) -> 0.11731496 | ... X40: =+($C$40*X28) -> 0.82300822
A41: Total Expenses | D41: =SUM(D34:D40) -> 0 | E41: =SUM(E34:E40) -> 4.8659378 | F41: =SUM(F34:F40) -> 5.4395816 | G41: =SUM(G34:G40) -> 6.0982145 | H41: =SUM(H34:H40) -> 6.8888225 | I41: =SUM(I34:I40) -> 7.6737787 | J41: =SUM(J34:J40) -> 8.5138553 | K41: =SUM(K34:K40) -> 9.4753394 | ... X41: =SUM(X34:X40) -> 37.867655
A43: Earning / (Deficit) before Interest & Depreciation | C43: Rs. | D43: =D30-D41 -> 0 | E43: =E30-E41 -> -3.1634472 | F43: =F30-F41 -> -3.219491 | G43: =G30-G41 -> -3.2021357 | H43: =H30-H41 -> -3.0980776 | I43: =I30-I41 -> -2.7666223 | J43: =J30-J41 -> -2.4244723 | K43: =K30-K41 -> -1.9167137 | ... X43: =X30-X41 -> 27.973003
C44: $ | D44: 0 | E44: =E43/E13 -> -0.022317088 | F44: =F43/F13 -> -0.021630913 | G44: =G43/G13 -> -0.020489817 | H44: =H43/H13 -> -0.018879971 | I44: =I43/I13 -> -0.016057192 | J44: =J43/J13 -> -0.013401323 | K44: =K43/K13 -> -0.010090168 | L44: =L43/L13 -> -0.0059935346 | ... X44: =X43/X13 -> 0.0780943
A46: EBITDA Margin | D46: 0 | E46: =E43/E28 -> -1.4865032 | F46: =F43/F28 -> -1.1601296 | G46: =G43/G28 -> -0.88454381 | H46: =H43/H28 -> -0.65381926 | I46: =I43/I28 -> -0.45103471 | J46: =J43/J28 -> -0.31851797 | K46: =K43/K28 -> -0.20286372 | L46: =L43/L28 -> -0.10190084 | ... X46: =X43/X28 -> 0.33988728
A48: Sales Tax | C48: 0 | D48: =D49*D13 -> -1 | E48: =$C$48*E28 -> 0 | F48: =$C$48*F28 -> 0 | G48: =$C$48*G28 -> 0 | H48: =$C$48*H28 -> 0 | I48: =$C$48*I28 -> 0 | J48: =$C$48*J28 -> 0 | K48: =$C$48*K28 -> 0 | L48: =$C$48*L28 -> 0 | ... X48: =$C$48*X28 -> 0 | Y48: =SUM(D48:X48) -> -1
A49: Depreciation | B49: Ongoing Capital Equipment | C49: $ | D49: =-D6*D7/1000000 -> -0.0074074074 | K49: =-0.007*0 -> 0 | O49: =D49*0.25 -> -0.0018518519 | P49: =E49*0.25 -> 0 | Q49: =F49*0.25 -> 0 | R49: =G49*0.25 -> 0 | S49: =H49*0.25 -> 0 | T49: =I49*0.25 -> 0 | U49: =J49*0.25 -> 0 | V49: =K49*0.25 -> 0 | ... X49: =M49*0.25 -> 0
A51: Excess / (Shortfall) of Revenues over Expenditure before Depreciation | C51: Rs. | D51: =+D43+D48 -> -1 | E51: =+E43+E48 -> -3.1634472 | F51: =+F43+F48 -> -3.219491 | G51: =+G43+G48 -> -3.2021357 | H51: =+H43+H48 -> -3.0980776 | I51: =+I43+I48 -> -2.7666223 | J51: =+J43+J48 -> -2.4244723 | K51: =+K43+K48 -> -1.9167137 | ... X51: =+X43+X48 -> 27.973003 | Y51: =SUM(D51:X51) -> 112.09231
...

Sheet Staff Costs
A1: Main Centers
A2: Staff Member | B2: Average Monthly Salary | C2: Fringe Benefits (PKR) | D2: Monthly Total Salary (PKR) | E2: Annual Salary (PKR)
B3: (PKR)
A4: Senior Medical Officer | B4: 65370 | C4: 8059 | D4: 73429 | E4: 881150
A5: Medical Representative | B5: 27540 | C5: 3771 | D5: 31312 | E5: 375743
A6: Centre Technicians | B6: 20330 | C6: 2954 | D6: 23284 | E6: 279409
A7: Screener / Nurse | B7: 20716 | C7: 2998 | D7: 23714 | E7: 284569
A8: Medical Receptionist | B8: 24341 | C8: 3409 | D8: 27750 | E8: 332997
A9: Van Drivers | B9: 20461 | C9: 2969 | D9: 23430 | E9: 281155
A10: Cleaner/Helper | B10: 15006 | C10: 2351 | D10: 17357 | E10: 208283
A11: Total | B11: 193764 | C11: 26511 | D11: 220275 | E11: 2643305
A13: Satellite Centers
A14: Staff Member | B14: Average Monthly Salary (PKR) | C14: Fringe Benefits (PKR) | D14: Monthly Total Salary (PKR) | E14: Annual Salary (PKR)
A15: Senior Medical Officer | B15: 65370 | C15: 8059 | D15: 73429 | E15: 881150
A16: Medical Representative | B16: 27540 | C16: 3771 | D16: 31312 | E16: 375743
A17: Centre Technicians | B17: 20330 | C17: 2954 | D17: 23284 | E17: 279409
A18: Screener / Nurse | B18: 20716 | C18: 2998 | D18: 23714 | E18: 284569
A19: Medical Receptionist | B19: 24341 | C19: 3409 | D19: 27750 | E19: 332997
A20: Cleaner/Helper | B20: 15006 | C20: 2351 | D20: 17357 | E20: 208283
A21: Total | B21: 173304 | C21: 23542 | D21: 196846 | E21: 2362150

Sheet Reagent_Costing
M1: INDIRECT MATERIALS | T1: DIRECT MATERIALS CONSUMABLES | AA1: DIRECT MATERIALS REAGENTS | AH1: TESTS COSTING
A2: Platform | B2: Test | C2: Expected No. of Tests | D2: Tests Conducted | E2: Difference from Target | F2: Cost Efficiency (%) | M2: Cost Item | N2: Quantity in Unit | O2: Units Consumed | P2: Total Quantity | Q2: Total Cost | R2: Per Test | T2: Cost Item | U2: Quantity in Unit | V2: Units Consumed | W2: Total Quantity | X2: Total Cost | Y2: Per Test | AA2: Platform | AB2: Test | AC2: Regents Procured | AD2: Cost per Unit (PKR) | AE2: Total Cost | AF2: Reagent Cost Per Test (PKR) | AH2: Platform | AI2: Test | AJ2: Tests Conducted | AK2: Direct Materials (Reagents) | AL2: Direct Materials (Consumables) | AM2: Indirect Material (Consumables) | AN2: Total Cost (PKR) | AQ2: Platform | AR2: Test | AS2: Price | AT2: Cost (PKR) | AU2: Gross Profit | AV2: Gross Profit (%)
A3: Hematology | B3: Complete Blood Count | C3: 11500 | D3: 8131 | E3: -3369 | F3: 0.71 | Q3: (PKR) | X3: (PKR) | AC3: (Units) | AE3: (PKR) | AH3: Hematology | AI3: Complete Blood Count | AJ3: 8131 | AK3: 33.64 | AL3: =Y21+Y5 -> 25.821029 | AM3: =R8 -> 1.5988193 | AN3: =AK3+AL3+AM3 -> 61.059849 | AQ3: Hematology | AR3: Complete Blood Count | AS3: 380 | AT3: =AN3 -> 61.059849 | AU3: =AS3-AT3 -> 318.94015 | AV3: =AU3/AS3 -> 0.83931619
A4: Biochemistry | B4: Alkaline phosphate | C4: 1950 | D4: 1278 | E4: -672 | F4: 0.66 | M4: Hematology | T4: Hematology | AA4: Hematology | AB4: Complete Blood Count | AC4: 250 | AD4: 3400 | AE4: 273500 | AF4: 30.64 | AH4: Biochemistry | AI4: Alkaline phosphate | AJ4: 1278 | AK4: 17.25 | AL4: =Y21+Y7 -> 22.582925 | AM4: =R18 -> 8.2415805 | AN4: =AK4+AL4+AM4 -> 48.074506 | AQ4: Biochemistry | AR4: Alkaline phosphate | AS4: 290 | AT4: =AN4 -> 48.074506 | AU4: =AS4-AT4 -> 241.92549 | AV4: =AU4/AS4 -> 0.83422584
A5: Biochemistry | B5: Gamma GT | C5: 3000 | D5: 1274 | E5: -1726 | F5: 0.42 | M5: Anitseraset | N5: 1 | O5: 3 | P5: 3 | Q5: 6000 | T5: EDTA Vacutainer (1x100) - Purple | U5: 100 | V5: 129 | W5: 12900 | X5: 93525 | Y5: =X5/AJ3 -> 11.502275 | AB5: (Diluent + Lyse) | AC5: 30 | AD5: 450 | AH5: Biochemistry | AI5: Gamma GT | AJ5: 1274 | AK5: 32.88 | AL5: =AL4 -> 22.582925 | AM5: =AM4 -> 8.2415805 | AN5: =AK5+AL5+AM5 -> 63.704506 | AQ5: Biochemistry | AR5: Gamma GT | AS5: 350 | AT5: =AN5 -> 63.704506 | AU5: =AS5-AT5 -> 286.29549 | AV5: =AU5/AS5 -> 0.81798713
A6: Biochemistry | B6: Bilirubin Total | C6: 2700 | D6: 1274 | E6: -1426 | F6: 0.47 | M6: Eight Calibration Control 1.5 (Normal) | N6: 0 | O6: 0 | P6: - | Q6: 3500 | T6: Biochemistry and HbA1c | AA6: Biochemistry | AB6: Alkaline phosphate | AC6: 26 | AD6: 848 | AE6: 22048 | AF6: 17.25 | AH6: Biochemistry | AI6: Bilirubin Total | AJ6: 1274 | AK6: 12.66 | AL6: =AL5 -> 22.582925 | AM6: =AM5 -> 8.2415805 | AN6: =AK6+AL6+AM6 -> 43.484506 | AQ6: Biochemistry | AR6: Bilirubin Total | AS6: 350 | AT6: =AN6 -> 43.484506 | AU6: =AS6-AT6 -> 306.51549 | AV6: =AU6/AS6 -> 0.87575856
A7: Biochemistry | B7: Bilirubin Direct | C7: 2250 | D7: 1274 | E7: -976 | F7: 0.57 | M7: Eight Calibration Control 1.5 (Low) | N7: 1 | O7: 1 | P7: 1 | Q7: 3500 | T7: Gel Vacutainer (1x100) - Yellow | U7: 100 | V7: 104 | W7: 10400 | X7: 93600 | Y7: =X7/SUM(AJ4:AJ17) -> 8.2641709 | AA7: Biochemistry | AB7: Gamma GT | AC7: 40 | AD7: 1047 | AE7: 41888 | AF7: 32.88 | AH7: Biochemistry | AI7: Bilirubin Direct | AJ7: 1274 | AK7: 10.55 | AL7: =AL6 -> 22.582925 | AM7: =AM6 -> 8.2415805 | AN7: =AK7+AL7+AM7 -> 41.374506 | AQ7: Biochemistry | AR7: Bilirubin Direct | AS7: 350 | AT7: =AN7 -> 41.374506 | AU7: =AS7-AT7 -> 308.62549 | AV7: =AU7/AS7 -> 0.88178713
A8: Biochemistry | B8: Alanine Transferase | C8: 3600 | D8: 1274 | E8: -2326 | F8: 0.35 | M8: Total | Q8: 13000 | R8: =Q8/AJ3 -> 1.5988193 | T8: General Consumables | AA8: Biochemistry | AB8: Bilirubin Total | AC8: 36 | AD8: 448 | AE8: 16128 | AF8: 12.66 | AH8: Biochemistry | AI8: Alanine Transferase | AJ8: 1274 | AK8: 23.31 | AL8: =AL7 -> 22.582925 | AM8: =AM7 -> 8.2415805 | AN8: =AK8+AL8+AM8 -> 54.134506 | AQ8: Biochemistry | AR8: Alanine Transferase | AS8: 330 | AT8: =AN8 -> 54.134506 | AU8: =AS8-AT8 -> 275.86549 | AV8: =AU8/AS8 -> 0.83595604
A9: Biochemistry | B9: HDL Direct | C9: 840 | D9: 194 | E9: -646 | F9: 0.23 | M9: Biochemistry | T9: Syringes | U9: 100 | V9: 256 | W9: 25600 | X9: 152400 | AA9: Biochemistry | AB9: Bilirubin Direct | AC9: 30 | AD9: 448 | AE9: 13440 | AF9: 10.55 | AH9: Biochemistry | AI9: HDL Direct | AJ9: 194 | AK9: 196.29 | AL9: =AL8 -> 22.582925 | AM9: =AM8 -> 8.2415805 | AN9: =AK9+AL9+AM9 -> 227.11451 | AQ9: Biochemistry | AR9: HDL Direct | AS9: 350 | AT9: =AN9 -> 227.11451 | AU9: =AS9-AT9 -> 122.88549 | AV9: =AU9/AS9 -> 0.35110141
A10: Biochemistry | B10: Triglycerides | C10: 975 | D10: 196 | E10: -779 | F10: 0.2 | M10: Eppindrof Cup | N10: 2 | O10: 2 | P10: 4 | Q10: 800 | T10: Alcohol Swab | U10: 200 | V10: 118 | W10: 23600 | X10: 20060 | AA10: Biochemistry | AB10: Alanine Transferase | AC10: 48 | AD10: 619 | AE10: 29702 | AF10: 23.31 | AH10: Biochemistry | AI10: Triglycerides | AJ10: 196 | AK10: 49.52 | AL10: =AL9 -> 22.582925 | AM10: =AM9 -> 8.2415805 | AN10: =AK10+AL10+AM10 -> 80.344506 | AQ10: Biochemistry | AR10: Triglycerides | AS10: 290 | AT10: =AN10 -> 80.344506 | AU10: =AS10-AT10 -> 209.65549 | AV10: =AU10/AS10 -> 0.72294998
A11: Biochemistry | B11: Total Cholesterol | C11: 1275 | D11: 251 | E11: -1024 | F11: 0.2 | M11: Selectra cup | N11: 1 | O11: 1 | P11: 1 | Q11: 5500 | T11: Bandage | U11: 200 | V11: 97 | W11: 19400 | X11: 27370 | AA11: Biochemistry | AB11: HDL Direct | AC11: 14 | AD11: 2720 | AE11: 38080 | AF11: 196.29 | AH11: Biochemistry | AI11: Total Cholesterol | AJ11: 251 | AK11: 87.84 | AL11: =AL10 -> 22.582925 | AM11: =AM10 -> 8.2415805 | AN11: =AK11+AL11+AM11 -> 118.66451 | AQ11: Biochemistry | AR11: Total Cholesterol | AS11: 190 | AT11: =AN11 -> 118.66451 | AU11: =AS11-AT11 -> 71.335494 | AV11: =AU11/AS11 -> 0.37544997
A12: Biochemistry | B12: LDL Direct | C12: 960 | D12: 204 | E12: -756 | F12: 0.21 | M12: D/W Ampule glass | N12: 1 | O12: 1 | P12: 1 | Q12: 2000 | T12: Butterfly needle | U12: 100 | V12: 4 | W12: 400 | X12: 30000 | AA12: Biochemistry | AB12: Triglycerides | AC12: 13 | AD12: 747 | AE12: 9707 | AF12: 49.52 | AH12: Biochemistry | AI12: LDL Direct | AJ12: 204 | AK12: 387.76 | AL12: =AL11 -> 22.582925 | AM12: =AM11 -> 8.2415805 | AN12: =AK12+AL12+AM12 -> 418.58451 | AQ12: Biochemistry | AR12: LDL Direct | AS12: 350 | AT12: =AN12 -> 418.58451 | AU12: =AS12-AT12 -> -68.584506 | AV12: =AU12/AS12 -> -0.19595573
A13: Biochemistry | B13: Uric Acid | C13: 975 | D13: 137 | E13: -838 | F13: 0.14 | M13: Boule Control (Normal) | N13: 1 | O13: 1 | P13: 1 | Q13: 5000 | T13: Vacant Needle Holder | U13: 100 | V13: 138 | W13: 13800 | X13: 13800 | AA13: Biochemistry | AB13: Total Cholesterol | AC13: 17 | AD13: 848 | AE13: 22048 | AF13: 32.96 | AH13: Biochemistry | AI13: Uric Acid | AJ13: 137 | AK13: 49.34 | AL13: =AL12 -> 22.582925 | AM13: =AM12 -> 8.2415805 | AN13: =AK13+AL13+AM13 -> 80.164506 | AQ13: Biochemistry | AR13: Uric Acid | AS13: 290 | AT13: =AN13 -> 80.164506 | AU13: =AS13-AT13 -> 209.83549 | AV13: =AU13/AS13 -> 0.72357067
A14: Biochemistry | B14: Urea UV | C14: 1425 | D14: 409 | E14: -1016 | F14: 0.29 | M14: Cleaning Solution | N14: - | O14: 2 | P14: 2 | Q14: 7140 | T14: Tagging roll | U14: 1 | V14: 60 | W14: 60 | X14: 4800 | AA14: Biochemistry | AB14: LDL Direct | AC14: 16 | AD14: 4944 | AE14: 79104 | AF14: 387.76 | AH14: Biochemistry | AI14: Urea UV | AJ14: 409 | AK14: 15.79 | AL14: =AL13 -> 22.582925 | AM14: =AM13 -> 8.2415805 | AN14: =AK14+AL14+AM14 -> 46.614506 | AQ14: Biochemistry | AR14: Urea UV | AS14: 290 | AT14: =AN14 -> 46.614506 | AU14: =AS14-AT14 -> 243.38549 | AV14: =AU14/AS14 -> 0.83926033
A15: Biochemistry | B15: Glucose PAP | C15: 300 | D15: 771 | E15: 471 | F15: 2.57 | M15: HSN - Normal Calibration | N15: - | O15: 13 | P15: 13 | Q15: 18893 | T15: Blood Tube rack | U15: - | V15: 20 | W15: 20 | X15: 8000 | AA15: Biochemistry | AB15: Uric Acid | AC15: 13 | AD15: 520 | AE15: 6760 | AF15: 49.34 | AH15: Biochemistry | AI15: Glucose PAP | AJ15: 771 | AK15: 0.33 | AL15: =AL14 -> 22.582925 | AM15: =AM14 -> 8.2415805 | AN15: =AK15+AL15+AM15 -> 31.154506 | AQ15: Biochemistry | AR15: Glucose PAP | AS15: 170 | AT15: =AN15 -> 31.154506 | AU15: =AS15-AT15 -> 138.84549 | AV15: =AU15/AS15 -> 0.8167382
A16: Biochemistry | B16: Creatinine | C16: 3375 | D16: 550 | E16: -2825 | F16: 0.17 | M16: HSP - Pathology Calibration | N16: - | O16: 17 | P16: 17 | Q16: 25840 | T16: Danger Box | U16: - | V16: 14 | W16: 14 | X16: 3500 | AA16: Biochemistry | AB16: Urea UV | AC16: 19 | AD16: 340 | AE16: 6460 | AF16: 15.79 | AH16: Biochemistry | AI16: Creatinine | AJ16: 550 | AK16: 23.18 | AL16: =AL15 -> 22.582925 | AM16: =AM15 -> 8.2415805 | AN16: =AK16+AL16+AM16 -> 54.004506 | AQ16: Biochemistry | AR16: Creatinine | AS16: 250 | AT16: =AN16 -> 54.004506 | AU16: =AS16-AT16 -> 195.99549 | AV16: =AU16/AS16 -> 0.78398198
A17: HbA1c | B17: Hemoglobin (A1c) | C17: 300 | D17: 2240 | E17: -712 | F17: 0.76 | M17: System Solution | N17: - | O17: 1.5 | P17: 1.5 | Q17: 9710 | T17: Tourniquet | U17: - | V17: 6 | W17: 6 | X17: 450 | AA17: Biochemistry | AB17: Glucose PAP | AC17: 1 | AD17: 256 | AE17: 256 | AF17: 0.33 | AH17: HbA1c | AI17: Hemoglobin (A1c) | AJ17: 2240 | AK17: 276.79 | AL17: =AL16 -> 22.582925 | AM17: =R22 -> 4.6875 | AN17: =AK17+AL17+AM17 -> 304.06043 | AQ17: HbA1c | AR17: Hemoglobin (A1c) | AS17: 850 | AT17: =AN17 -> 304.06043 | AU17: =AS17-AT17 -> 545.93957 | AV17: =AU17/AS17 -> 0.64228185
A18: Total | C18: =SUM(C3:C17) -> 35425 | D18: =SUM(D3:D17) -> 19457 | E18: =SUM(E3:E17) -> -18620 | F18: =D18/C18 -> 0.54924488 | M18: Total | Q18: 74883 | R18: =Q18/SUM(AJ4:AJ16) -> 8.2415805 | T18: Immersion oil | U18: - | V18: 1 | W18: 1 | X18: 4300 | AA18: Biochemistry | AB18: Creatinine | AC18: 1 | AD18: 283 | AE18: 12750 | AF18: 23.18
M19: HbA1c | T19: Normal Saline | V19: 1 | W19: 1 | X19: 120 | AA19: HbA1c | AB19: Hemoglobin (A1c) | AC19: 31 | AD19: 20000 | AE19: 620000 | AF19: 276.79
M20: Yellow tip | N20: - | O20: 3 | P20: 3 | Q20: 750 | T20: Vacant Needle Holder | U20: - | V20: 100 | W20: 100 | X20: 13800
M21: Plastic tube | N21: - | O21: 15 | P21: 15 | Q21: 9750 | T21: Total | X21: 278600 | Y21: =X21/SUM(AJ3:AJ17) -> 14.318754
M22: Total | Q22: 10500 | R22: =Q22/AJ17 -> 4.6875 | AH22: Q3 TESTS COSTING
AH24: Platform | AI24: Test | AJ24: Tests Conducted | AK24: Direct Materials (Reagents) | AL24: Direct Materials (Consumables) | AM24: Indirect Material (Consumables) | AN24: Total Cost (PKR) | AO24: Q3-Q1 | AQ24: Platform | AR24: Test | AS24: Price | AT24: Cost (PKR) | AU24: Gross Profit | AV24: Gross Profit (%) | AW24: Q3-Q1 | AZ24: No. | BA24: Test | BB24: Test Price | BC24: Per Test Cost (PKR) | BD24: Gross Profit | BE24: Gross Profit (%) | BG24: Test | BH24: Tests Conducted | BI24: Gross Profit | BJ24: Contribution Mix | BK24: Weighted Gross Profit
AH25: Hematology | AI25: Complete Blood Count | AJ25: 5583 | AK25: 51.504567 | AL25: 28.03 | AM25: 10.02 | AN25: =AK25+AL25+AM25 -> 89.554567 | AO25: =AN25-AN3 -> 28.494719 | AQ25: Hematology | AR25: Complete Blood Count | AS25: 380 | AT25: =AN25 -> 89.554567 | AU25: =AS25-AT25 -> 290.44543 | AV25: =AU25/AS25 -> 0.76433009 | AW25: =AV25-AV3 -> -0.074986102 | BB25: (PKR) | BD25: (PKR) | BG25: Complete Blood Count | BH25: 5583 | BI25: 0.76 | BJ25: =BH25/$BH$37 -> 0.35841304 | BK25: =BJ25*BI25 -> 0.27239391
AH26: Biochemistry | AI26: Alkaline phosphate | AJ26: 1147 | AK26: 7.2233653 | AL26: 24.05 | AM26: 5.06 | AN26: =AK26+AL26+AM26 -> 36.333365 | AO26: =AN26-AN4 -> -11.74114 | AQ26: Biochemistry | AR26: Alkaline phosphate | AS26: 290 | AT26: =AN26 -> 36.333365 | AU26: =AS26-AT26 -> 253.66663 | AV26: =AU26/AS26 -> 0.87471253 | AW26: =AV26-AV4 -> 0.040486691 | AZ26: 1 | BA26: Alkaline phosphate | BC26: 36.33 | BG26: Liver Function Tests | BH26: =SUM(AJ26:AJ30) -> 6021 | BI26: 0.8 | BJ26: =BH26/$BH$37 -> 0.38653142 | BK26: =BJ26*BI26 -> 0.30922514
AH27: Biochemistry | AI27: Gamma GT | AJ27: 1147 | AK27: 17.585562 | AL27: =AL26 -> 24.05 | AM27: 5.06 | AN27: =AK27+AL27+AM27 -> 46.695562 | AO27: =AN27-AN5 -> -17.008943 | AQ27: Biochemistry | AR27: Gamma GT | AS27: 350 | AT27: =AN27 -> 46.695562 | AU27: =AS27-AT27 -> 303.30444 | AV27: =AU27/AS27 -> 0.86658411 | AW27: =AV27-AV5 -> 0.048596981 | AZ27: 2 | BA27: Gamma GT | BC27: 46.7 | BG27: Lipid Profie | BH27: =SUM(AJ31:AJ34) -> 1088 | BI27: 0.63 | BJ27: =BH27/$BH$37 -> 0.069846569 | BK27: =BJ27*BI27 -> 0.044003338
AH28: Biochemistry | AI28: Bilirubin Total | AJ28: 1147 | AK28: 6.4680732 | AL28: =AL27 -> 24.05 | AM28: 5.06 | AN28: =AK28+AL28+AM28 -> 35.578073 | AO28: =AN28-AN6 -> -7.9064323 | AQ28: Biochemistry | AR28: Bilirubin Total | AS28: 350 | AT28: =AN28 -> 35.578073 | AU28: =AS28-AT28 -> 314.42193 | AV28: =AU28/AS28 -> 0.89834836 | AW28: =AV28-AV6 -> 0.022589807 | AZ28: 3 | BA28: Bilirubin Total | BC28: 35.58 | BG28: Uric Acid | BH28: 205 | BI28: 0.86113457 | BJ28: =BH28/$BH$37 -> 0.013160429 | BK28: =BJ28*BI28 -> 0.0113329
AH29: Biochemistry | AI29: Bilirubin Direct | AJ29: 1147 | AK29: 6.5149433 | AL29: =AL28 -> 24.05 | AM29: 5.06 | AN29: =AK29+AL29+AM29 -> 35.624943 | AO29: =AN29-AN7 -> -5.7495622 | AQ29: Biochemistry | AR29: Bilirubin Direct | AS29: 350 | AT29: =AN29 -> 35.624943 | AU29: =AS29-AT29 -> 314.37506 | AV29: =AU29/AS29 -> 0.89821445 | AW29: =AV29-AV7 -> 0.016427321 | AZ29: 4 | BA29: Bilirubin Direct | BC29: 35.62 | BG29: Urea UV | BH29: 409 | BI29: 0.87955493 | BJ29: =BH29/$BH$37 -> 0.02625666 | BK29: =BJ29*BI29 -> 0.023094175
AH30: Biochemistry | AI30: Alanine Transferase | AJ30: 1433 | AK30: 9.8863364 | AL30: =AL29 -> 24.05 | AM30: 5.06 | AN30: =AK30+AL30+AM30 -> 38.996336 | AO30: =AN30-AN8 -> -15.138169 | AQ30: Biochemistry | AR30: Alanine Transferase | AS30: 330 | AT30: =AN30 -> 38.996336 | AU30: =AS30-AT30 -> 291.00366 | AV30: =AU30/AS30 -> 0.88182928 | AW30: =AV30-AV8 -> 0.04587324 | AZ30: 5 | BA30: Alanine Transferase | BC30: 39 | BG30: Glucose PAP | BH30: 910 | BI30: 0.82353549 | BJ30: =BH30/$BH$37 -> 0.058419465 | BK30: =BJ30*BI30 -> 0.048110502
AH31: Biochemistry | AI31: HDL Direct | AJ31: 244 | AK31: 69.672131 | AL31: =AL30 -> 24.05 | AM31: 5.06 | AN31: =AK31+AL31+AM31 -> 98.782131 | AO31: =AN31-AN9 -> -128.33237 | AQ31: Biochemistry | AR31: HDL Direct | AS31: 350 | AT31: =AN31 -> 98.782131 | AU31: =AS31-AT31 -> 251.21787 | AV31: =AU31/AS31 -> 0.71776534 | AW31: =AV31-AV9 -> 0.36666393 | AZ31: 6 | BA31: Total | BB31: 990 | BC31: =SUM(BC26:BC30) -> 193.23 | BD31: =BB31-BC31 -> 796.77 | BE31: =BD31/BB31 -> 0.80481818 | BG31: Creatinine | BH31: 429 | BI31: 0.85428883 | BJ31: =BH31/$BH$37 -> 0.027540605 | BK31: =BJ31*BI31 -> 0.023527631
AH32: Biochemistry | AI32: Triglycerides | AJ32: 260 | AK32: 17.23077 | AL32: =AL31 -> 24.05 | AM32: 5.06 | AN32: =AK32+AL32+AM32 -> 46.34077 | AO32: =AN32-AN10 -> -34.003736 | AQ32: Biochemistry | AR32: Triglycerides | AS32: 290 | AT32: =AN32 -> 46.34077 | AU32: =AS32-AT32 -> 243.65923 | AV32: =AU32/AS32 -> 0.84020424 | AW32: =AV32-AV10 -> 0.11725426 | BG32: Hemoglobin (A1c) | BH32: 815 | BI32: 0.71632154 | BJ32: =BH32/$BH$37 -> 0.052320729 | BK32: =BJ32*BI32 -> 0.037478466
AH33: Biochemistry | AI33: Total Cholesterol | AJ33: 340 | AK33: 8.5882359 | AL33: =AL32 -> 24.05 | AM33: 5.06 | AN33: =AK33+AL33+AM33 -> 37.698236 | AO33: =AN33-AN11 -> -80.96627 | AQ33: Biochemistry | AR33: Total Cholesterol | AS33: 190 | AT33: =AN33 -> 37.698236 | AU33: =AS33-AT33 -> 152.30176 | AV33: =AU33/AS33 -> 0.80158823 | AW33: =AV33-AV11 -> 0.42613826 | BG33: HBV PCR Qualitative | BH33: 11 | BI33: -0.19458128 | BJ33: =BH33/$BH$37 -> 0.00070616935 | BK33: =BJ33*BI33 -> -0.00013740734
AH34: Biochemistry | AI34: LDL Direct | AJ34: 244 | AK34: 116.5082 | AL34: =AL33 -> 24.05 | AM34: 5.06 | AN34: =AK34+AL34+AM34 -> 145.6182 | AO34: =AN34-AN12 -> -272.96631 | AQ34: Biochemistry | AR34: LDL Direct | AS34: 350 | AT34: =AN34 -> 145.6182 | AU34: =AS34-AT34 -> 204.3818 | AV34: =AU34/AS34 -> 0.58394801 | AW34: =AV34-AV12 -> 0.77990374 | BG34: HBV PCR Quantitative | BH34: 9 | BI34: 0.11172161 | BJ34: =BH34/$BH$37 -> 0.00057777492 | BK34: =BJ34*BI34 -> 6.4549946e-05
AH35: Biochemistry | AI35: Uric Acid | AJ35: 205 | AK35: 11.160976 | AL35: =AL34 -> 24.05 | AM35: 5.06 | AN35: =AK35+AL35+AM35 -> 40.270976 | AO35: =AN35-AN13 -> -39.89353 | AQ35: Biochemistry | AR35: Uric Acid | AS35: 290 | AT35: =AN35 -> 40.270976 | AU35: =AS35-AT35 -> 249.72902 | AV35: =AU35/AS35 -> 0.86113457 | AW35: =AV35-AV13 -> 0.1375639 | BG35: HCV RNA PCR Qualitative | BH35: 52 | BI35: 0.13546798 | BJ35: =BH35/$BH$37 -> 0.0033382551 | BK35: =BJ35*BI35 -> 0.00045222668
AH36: Biochemistry | AI36: Urea UV | AJ36: 409 | AK36: 5.8190709 | AL36: =AL35 -> 24.05 | AM36: 5.06 | AN36: =AK36+AL36+AM36 -> 34.929071 | AO36: =AN36-AN14 -> -11.685435 | AQ36: Biochemistry | AR36: Urea UV | AS36: 290 | AT36: =AN36 -> 34.929071 | AU36: =AS36-AT36 -> 255.07093 | AV36: =AU36/AS36 -> 0.87955493 | AW36: =AV36-AV14 -> 0.040294602 | BG36: HCV RNA Quantitative | BH36: 45 | BI36: 0.15567766 | BJ36: =BH36/$BH$37 -> 0.0028888746 | BK36: =BJ36*BI36 -> 0.00044973323
AH37: Biochemistry | AI37: Glucose PAP | AJ37: 910 | AK37: 0.88896703 | AL37: =AL36 -> 24.05 | AM37: 5.06 | AN37: =AK37+AL37+AM37 -> 29.998967 | AO37: =AN37-AN15 -> -1.1555385 | AQ37: Biochemistry | AR37: Glucose PAP | AS37: 170 | AT37: =AN37 -> 29.998967 | AU37: =AS37-AT37 -> 140.00103 | AV37: =AU37/AS37 -> 0.82353549 | AW37: =AV37-AV15 -> 0.0067972855 | BH37: =SUM(BH25:BH36) -> 15577 | BK37: =SUM(BK25:BK36) -> 0.76999517
AH38: Biochemistry | AI38: Creatinine | AJ38: 429 | AK38: 7.3177925 | AL38: =AL37 -> 24.05 | AM38: 5.06 | AN38: =AK38+AL38+AM38 -> 36.427792 | AO38: =AN38-AN16 -> -17.576713 | AQ38: Biochemistry | AR38: Creatinine | AS38: 250 | AT38: =AN38 -> 36.427792 | AU38: =AS38-AT38 -> 213.57221 | AV38: =AU38/AS38 -> 0.85428883 | AW38: =AV38-AV16 -> 0.070306852
AH39: HbA1c | AI39: Hemoglobin (A1c) | AJ39: 815 | AK39: 212.57669 | AL39: =AL38 -> 24.05 | AM39: 4.5 | AN39: =AK39+AL39+AM39 -> 241.12669 | AO39: =AN39-AN17 -> -62.933738 | AQ39: HbA1c | AR39: Hemoglobin (A1c) | AS39: 850 | AT39: =AN39 -> 241.12669 | AU39: =AS39-AT39 -> 608.87331 | AV39: =AU39/AS39 -> 0.71632154 | AW39: =AV39-AV17 -> 0.074039692 | BG39: Reagents Cost % | BK39: =1-BK37 -> 0.23000483

Sheet Overhead Costs
A1: Main Centers
A2: Line-Item | B2: Cost-Head | C2: Average Cost Per Center PKR) | D2: Annual Cost Per Center PKR) | E2: Weightage
A3: Rent | B3: SG&A | C3: 125806 | D3: 1509672 | E3: =D3/$D$15 -> 0.53988701
A4: Electricity Bill | B4: Utilities | C4: 20198 | D4: 242379 | E4: =D4/$D$15 -> 0.086679274
A5: Generator Fuel | B5: Utilities | C5: 8885 | D5: 106620 | E5: =D5/$D$15 -> 0.038129311
A6: Internet | B6: SG&A | C6: 10120 | D6: 121435 | E6: =D6/$D$15 -> 0.043427432
A7: Water-Tanker | B7: Utilities | C7: 287 | D7: 3440 | E7: =D7/$D$15 -> 0.0012302085
A8: Grocery | B8: SG&A | C8: 5168 | D8: 62010 | E8: =D8/$D$15 -> 0.022175938
A9: Drinking Water | B9: SG&A | C9: 1694 | D9: 20330 | E9: =D9/$D$15 -> 0.0072703891
A10: PTCL Bill | B10: SG&A | C10: 2888 | D10: 34661 | E10: =D10/$D$15 -> 0.012395423
A11: Security services | B11: SG&A | C11: 15751 | D11: 189007 | E11: =D11/$D$15 -> 0.067592446
A12: Repairs & Maintenance | B12: SG&A | C12: 10568 | D12: 126811 | E12: =D12/$D$15 -> 0.045349991
A13: Stationery | B13: Supplies | C13: 13225 | D13: 158694 | E13: =D13/$D$15 -> 0.056751949
A14: Office Supplies | B14: Supplies | C14: 18435 | D14: 221215 | E14: =D14/$D$15 -> 0.079110631
A15: Total | C15: =SUM(C3:C14) -> 233025 | D15: =SUM(D3:D14) -> 2796274 | E15: =D15/$D$15 -> 1
A17: Satellite Centers
A18: Line-Item | B18: Cost-Head | C18: Average Cost Per Center PKR) | D18: Annual Cost Per Center PKR)
A19: Rent | B19: SG&A | C19: 63651 | D19: 763815 | E19: =D19/$D$32 -> 0.50680201
A20: Electricity Bill | B20: Utilities | C20: 4805 | D20: 57661 | E20: =D20/$D$32 -> 0.038258886
A21: Generator Fuel | B21: Utilities | C21: 5329 | D21: 63952 | E21: =D21/$D$32 -> 0.042433053
A22: Internet | B22: SG&A | C22: 9276 | D22: 111315 | E22: =D22/$D$32 -> 0.073859071
A23: Water-Tanker | B23: Utilities | C23: 3692 | D23: 44305 | E23: =D23/$D$32 -> 0.029396992
A24: Grocery | B24: SG&A | C24: 2290 | D24: 27483 | E24: =D24/$D$32 -> 0.018235358
A25: Drinking Water | B25: SG&A | C25: 826 | D25: 9918 | E25: =D25/$D$32 -> 0.0065807327
A26: PTCL Bill | B26: SG&A | C26: 2400 | D26: 28806 | E26: =D26/$D$32 -> 0.019113187
A27: Security services | B27: SG&A | C27: 15074 | D27: 180894 | E27: =D27/$D$32 -> 0.12002572
A28: Bike Fuel | B28: SG&A | C28: 9675 | D28: 116097 | E28: =D28/$D$32 -> 0.077031995
A29: Repairs & Maintenance | B29: SG&A | C29: 7265 | D29: 87182 | E29: =D29/$D$32 -> 0.057846485
A30: Stationery | B30: Supplies | C30: 1014 | D30: 12169 | E30: =D30/$D$32 -> 0.008074303
A31: Office Supplies | B31: Supplies | C31: 294 | D31: 3530 | E31: =D31/$D$32 -> 0.0023422047
A32: Total | C32: =SUM(C19:C31) -> 125591 | D32: =SUM(D19:D31) -> 1507127 | E32: =D32/$D$32 -> 1
C34: =C15-C32 -> 107434 | D34: =D15-D32 -> 1289147

Sheet Average_charge_3_Main_centers
A1: Sr. # | B1: Net Sales | C1: Commerical Tests
A2: SZC-KORANGI | B2: 2706395 | C2: 6913
A3: SZC-MALIR | B3: 2243231 | C3: 5469
A4: SZC-NAZIMABAD MAIN CENTER | B4: 3366587 | C4: 7722
A7: Total | B7: =SUM(B2:B6) -> 8316213 | C7: =SUM(C2:C6) -> 20104
A9: Average Charge | B9: =B7/C7 -> 413.65962
A11: Average Sales | C11: =AVERAGE(C2:C4) -> 6701.3333

Sheet Central _support
A1: Staff Member | B1: Monthly Salary | C1: Fringe | D1: Monthly Total Salary | E1: Annual Salary | G1: Line-Item | H1: Avearge Monthly Costs (PKR) | I1: Annual
A2: Lab Manager | B2: 90000 | C2: =B2*0.15 -> 13500 | D2: =B2+C2 -> 103500 | E2: =D2*12 -> 1242000 | G2: Rent | H2: 20000 | I2: =H2*12 -> 240000
A3: Technicians | B3: 20330 | C3: =B3*0.15 -> 3049.5 | D3: =B3+C3 -> 23379.5 | E3: =D3*12 -> 280554 | G3: Electricity Bill | H3: 37230 | I3: =H3*12 -> 446760
A4: Technicians | B4: 20330 | C4: =B4*0.15 -> 3049.5 | D4: =B4+C4 -> 23379.5 | E4: =D4*12 -> 280554 | G4: Internet | H4: 18000 | I4: =H4*12 -> 216000
A5: Technicians | B5: 20330 | C5: =B5*0.15 -> 3049.5 | D5: =B5+C5 -> 23379.5 | E5: =D5*12 -> 280554 | G5: PTCL Bill | H5: 3670 | I5: =H5*12 -> 44040
A6: Technicians | B6: 20330 | C6: =B6*0.15 -> 3049.5 | D6: =B6+C6 -> 23379.5 | E6: =D6*12 -> 280554 | G6: Stationery | H6: 5000 | I6: =H6*12 -> 60000
A7: Total | B7: =SUM(B2:B6) -> 171320 | C7: =SUM(C2:C6) -> 25698 | D7: =SUM(D2:D6) -> 197018 | E7: =SUM(E2:E6) -> 2364216 | G7: Office Supplies | H7: 70000 | I7: =H7*12 -> 840000
G8: Total | H8: =SUM(H2:H7) -> 153900 | I8: =H8*12 -> 1846800
C9: Monthly | D9: Annual
A10: Total Cost | C10: =H8+D7 -> 350918 | D10: =I8+E7 -> 4211016
D11: =D10/135 -> 31192.711

Sheet Summary_Tables
A1: Revenue Per Lab Collection Unit
B2: Tests | C2: Spending | D2: Daily TR | E2: Monthly TR | F2: Annual TR
A3: Lower | B3: 40 | C3: 1500 | D3: =B3*C3 -> 60000 | E3: =D3*24 -> 1440000 | F3: =E3*12 -> 17280000
A4: Median | B4: 45 | C4: 1750 | D4: =B4*C4 -> 78750 | E4: =D4*24 -> 1890000 | F4: =E4*12 -> 22680000
A5: Upper | B5: 50 | C5: 2000 | D5: =B5*C5 -> 100000 | E5: =D5*24 -> 2400000 | F5: =E5*12 -> 28800000 | M5: Projected Revenues From Labs
A7: Revenue Per HealthCare Provider | N7: Labs | O7: Providers | P7: Patients | Q7: Average Monthly | R7: Average Annual
B8: OPD | C8: % Tests | D8: Spending | E8: Daily TR | F8: Monthly TR | G8: Annual TR | H8: Providers | I8: Monthly TR | J8: Annual TR | M8: Lower | N8: =E3 -> 1440000 | O8: =I9 -> 360000 | P8: =F17 -> 60000 | Q8: =AVERAGE(N8:P8) -> 620000 | R8: =Q8*12 -> 7440000
A9: Lower | B9: 30 | C9: 0.1 | D9: 1000 | E9: =B9*C9*D9 -> 3000 | F9: =E9*24 -> 72000 | G9: =F9*12 -> 864000 | H9: 5 | I9: =H9*F9 -> 360000 | J9: =H9*G9 -> 4320000 | M9: Median | N9: =E4 -> 1890000 | O9: =I10 -> 1575000 | P9: =F18 -> 360000 | Q9: =AVERAGE(N9:P9) -> 1275000 | R9: =Q9*12 -> 15300000
A10: Median | B10: 35 | C10: 0.15 | D10: 1250 | E10: =B10*C10*D10 -> 6562.5 | F10: =E10*24 -> 157500 | G10: =F10*12 -> 1890000 | H10: 10 | I10: =H10*F10 -> 1575000 | J10: =H10*G10 -> 18900000 | M10: Upper | N10: =E5 -> 2400000 | O10: =I11 -> 4320000 | P10: =F19 -> 1080000 | Q10: =AVERAGE(N10:P10) -> 2600000 | R10: =Q10*12 -> 31200000
A11: Upper | B11: 40 | C11: 0.2 | D11: 1500 | E11: =B11*C11*D11 -> 12000 | F11: =E11*24 -> 288000 | G11: =F11*12 -> 3456000 | H11: 15 | I11: =H11*F11 -> 4320000 | J11: =H11*G11 -> 51840000
A14: Revenue Patients
B16: OPD | C16: Tests | D16: Spending | E16: Daily TR | F16: Monthly TR | G16: Annual TR
A17: Lower | B17: 10 | C17: 0.5 | D17: 500 | E17: =B17*C17*D17 -> 2500 | F17: =E17*24 -> 60000 | G17: =F17*12 -> 720000
A18: Median | B18: 15 | C18: 1 | D18: 1000 | E18: =B18*C18*D18 -> 15000 | F18: =E18*24 -> 360000 | G18: =F18*12 -> 4320000
A19: Upper | B19: 20 | C19: 1.5 | D19: 1500 | E19: =B19*C19*D19 -> 45000 | F19: =E19*24 -> 1080000 | G19: =F19*12 -> 12960000
B22: *Green cells are assumptions not based on survey

Sheet Charts_Labs
A1: Row Labels | B1: Count of How many daily clients come for lab tests in your branch? | D1: Row Labels | E1: Count of On average how much does each patient spend during one visit
A2: 10-20 | B2: 9 | D2: 1000-1500 | E2: 25 | K2: Revenue Per Lab Collection Unit
A3: 20-30 | B3: 9 | D3: 1500-2000 | E3: 13 | F3: Median
A4: 30-40 | B4: 11 | D4: 2000-2500 | E4: 3 | J4: Tests | K4: Spending | L4: Daily TR | M4: Monthly TR | N4: Annual TR
A5: 40-50 | B5: 8 | C5: Median | D5: 2500-3000 | E5: 5 | I5: Lower | J5: 40 | K5: 1500 | L5: =J5*K5 -> 60000 | M5: =L5*24 -> 1440000 | N5: =M5*12 -> 17280000
A6: 50-60 | B6: 8 | D6: 500-1000 | E6: 11 | I6: Median | J6: 45 | K6: 1750 | L6: =J6*K6 -> 78750 | M6: =L6*24 -> 1890000 | N6: =M6*12 -> 22680000
A7: Less than 10 | B7: 3 | D7: Less than 500 | E7: 3 | I7: Upper | J7: 50 | K7: 2000 | L7: =J7*K7 -> 100000 | M7: =L7*24 -> 2400000 | N7: =M7*12 -> 28800000
A8: More than 60 | B8: 14 | D8: More than 3,000 | E8: 2
A9: (blank) | D9: (blank)
A10: Grand Total | B10: 62 | D10: Grand Total | E10: 62

Sheet Charts_Providers
A1: Row Labels | B1: Count of Daily Average OPD | E1: Row Labels | F1: Count of What percentage of patients are prescribed lab tests? | I1: Row Labels | J1: Count of On average how much does each patient spend on lab tests in your clinic?
A2: 10-20 | B2: 7 | E2: 0-10% | F2: 20 | I2: < 500 | J2: 20 | N2: Revenue Per HealthCare Provider
A3: 20-30 | B3: 16 | E3: 10-20% | F3: 18 | G3: Median | I3: 1000-1500 | J3: 13 | K3: Median
A4: 30 - 40 | B4: 13 | C4: Median | E4: 20-30% | F4: 9 | I4: 1500-2000 | J4: 7 | M4: OPD | N4: % Tests | O4: Spending | P4: Daily TR | Q4: Monthly TR | R4: Annual TR | S4: Providers | T4: Monthly TR | U4: Annual TR
A5: 40 - 50 | B5: 13 | E5: 30-40% | F5: 7 | I5: 2000-2500 | J5: 3 | L5: Lower | M5: 30 | N5: 0.1 | O5: 1000 | P5: =M5*N5*O5 -> 3000 | Q5: =P5*24 -> 72000 | R5: =Q5*12 -> 864000 | S5: 5 | T5: =S5*Q5 -> 360000 | U5: =S5*R5 -> 4320000
A6: 50-60 | B6: 4 | E6: 40-50% | F6: 4 | I6: 500-1000 | J6: 18 | L6: Median | M6: 35 | N6: 0.15 | O6: 1250 | P6: =M6*N6*O6 -> 6562.5 | Q6: =P6*24 -> 157500 | R6: =Q6*12 -> 1890000 | S6: 10 | T6: =S6*Q6 -> 1575000 | U6: =S6*R6 -> 18900000
A7: Less than 10 | B7: 5 | E7: More than 50% | F7: 3 | I7: (blank) | L7: Upper | M7: 40 | N7: 0.2 | O7: 1500 | P7: =M7*N7*O7 -> 12000 | Q7: =P7*24 -> 288000 | R7: =Q7*12 -> 3456000 | S7: 15 | T7: =S7*Q7 -> 4320000 | U7: =S7*R7 -> 51840000
A8: More than 60 | B8: 3 | E8: (blank) | I8: Grand Total | J8: 61
A9: (blank) | E9: Grand Total | F9: 61
A10: Grand Total | B10: 61

Sheet Charts_Patients
A1: Row Labels | B1: Count of Total family members have had a lab test in past one month (incl self) | E1: Row Labels | F1: Count of Total spending on lab tests in past one month | I1: Row Labels | J1: Count of How many tests were done last month.?
A2: Four or More | B2: 4 | E2: 1000-2000 | F2: 17 | I2: Four or More | J2: 13
A3: None | B3: 32 | E3: 2000-3000 | F3: 11 | I3: None | J3: 35
A4: One | B4: 56 | C4: Median | E4: 3000-5000 | F4: 6 | I4: One | J4: 32 | K4: Median | O4: OPD | P4: Tests | Q4: Spending | R4: Daily TR | S4: Monthly TR | T4: Annual TR
A5: Three | B5: 2 | E5: 5000-8000 | F5: 2 | I5: Three | J5: 15 | N5: Lower | O5: 20 | P5: 0.5 | Q5: 500 | R5: =O5*P5*Q5 -> 5000 | S5: =R5*24 -> 120000 | T5: =S5*12 -> 1440000
A6: Two | B6: 17 | E6: 8000-10000 | F6: 1 | I6: Two | J6: 16 | N6: Median | O6: 25 | P6: 1 | Q6: 1000 | R6: =O6*P6*Q6 -> 25000 | S6: =R6*24 -> 600000 | T6: =S6*12 -> 7200000
A7: Grand Total | B7: 111 | E7: Less than 1000 | F7: 72 | G7: Median | I7: (blank) | N7: Upper | O7: 30 | P7: 1.5 | Q7: 1500 | R7: =O7*P7*Q7 -> 67500 | S7: =R7*24 -> 1620000 | T7: =S7*12 -> 19440000
E8: More than 10,000 | F8: 2 | I8: Grand Total | J8: 111
E9: (blank)
E10: Grand Total | F10: 111

Sheet Labs
A1: Timestamp | B1: Name of Interviewer | C1: Responder name | D1: Designation | E1: Years of employment at current employer | F1: Qualifications | G1: Total Years of Experience | H1: How many daily clients come for lab tests in your branch? | I1: How many of the following tests are conducted on daily basis | J1: On average how much does each patient spend during one visit | K1: How many of the following tests are conducted on daily basis [0-5] | L1: What are the three most important reasons that patients choose your service? | M1: What is the staffing at your collection centers? | N1: What is the average area of each collection center? | O1: On average what is the daily clientele of your centers? | P1: On average what is the revenue of your collection centers? | Q1: What is the revenue of the highest performing centers? | R1: What is the revenue of the lowest performing centers? | S1: Monthly cost of running your center | T1: How many full-time staff at your center? | U1: How many part-time staff at your center? | V1: What is the percentage of revenues for other management, marketing, development and overhead costs? | W1: Most important factor in deciding lab for testing | X1: What are the three best marketing strategies and initiatives? | Y1: How long does it take for a center to be sustainable—covering operating costs? | Z1: How long does it take for sales to become stable once centers are open? | AA1: What is the average annual growth for a center once sales are stable? | AB1: What are the top performing cities by average sales per center? | AC1: Is there difference between rural vs urban in average sales per center? | AD1: Is there difference between provinces? | AE1: [Row 1] | AF1: % Spent on Tests: [What % is spent on CBC or CBC/ESR] | AG1: % Spent on Tests: [What % is spent on Biochemistry (LFTs, Lipid Profile, Creatinine, Diabetes tests)] | AH1: % Spent on Tests: [What % is spent on urine tests] | AI1: % Spent on Tests: [What % is spent on special chemistry] | AJ1: LAB Name | AK1: Branch | AL1: How many of the following tests are conducted on daily basis [6-10] | AM1: How many of the following tests are conducted on daily basis [15-20] | AN1: How many of the following tests are conducted on daily basis [20-25] | AO1: How many of the following tests are conducted on daily basis [11-15] | AP1: How many of the following tests are conducted on daily basis [25+] | AQ1: How many of the following tests are conducted on daily basis [2. LFT] | AR1: How many of the following tests are conducted on daily basis [3. Lipid Profile] | AS1: How many of the following tests are conducted on daily basis [4. Dengue] | AT1: How many of the following tests are conducted on daily basis [5. Malaria] | AU1: How many of the following tests are conducted on daily basis [6. Typhoid] | AV1: How many of the following tests are conducted on daily basis [7. Sugar test] | AW1: How many of the following tests are conducted on daily basis [8. HbA1c] | AX1: How many of the following tests are conducted on daily basis [9. Creatinine] | AY1: How many of the following tests are conducted on daily basis [10. Hormones] | AZ1: How many of the following tests are conducted on daily basis [11. Urine] | BA1: How many of the following tests are conducted on daily basis [12. PCRs]
A2: 43231.655 | C2: Usama | D2: Reception | E2: 1.5 | H2: Less than 10 | J2: Less than 500 | K2: Lipid Profile, Dengue, Malaria, PCRs | S2: 100000-150000 | T2: 25 | U2: 0 | W2: Lab Reputation | AJ2: Radiology | AK2: Bahadurabad | AL2: CBC / ESR, LFT, Typhoid, Sugar test, HbA1c, Creatinine, Hormones, Urine
A3: 43231.669 | C3: Hafiza Shabana Ashraf | D3: Shift Incharge | E3: 3 | H3: More than 60 | J3: 500-1000 | S3: no Idea | T3: 25 | U3: 0 | W3: Lab Reputation, Lab Quality, Lab Staff, Referral by Doctor, Pathologist | AJ3: Chugtai Lab | AK3: Bahadurabad | AL3: Dengue, Malaria, PCRs | AP3: CBC / ESR, LFT, Lipid Profile, Typhoid, Sugar test, HbA1c, Creatinine, Hormones, Urine
