Workbook

Sheet Cover
B2: Investment & Corporate Finance Models
B3: A fully dynamic, formula-driven Excel toolkit: DCF, Trading Comps, LBO, and M&A Accretion/Dilution
B6: How this workbook works
B7: All operating assumptions live on the 'Scenario Control' and 'Assumptions' tabs. Every other tab pulls its
B8: numbers from those two tabs with live formulas change an assumption once and the DCF, Comps, LBO, M&A,
B9: and Summary tabs all recalculate.
B11: Start on 'Scenario Control': pick Base, Bull, or Bear from the dropdown in cell C3. That single choice drives
B12: revenue growth, margins, capex, terminal growth, and the exit multiple used throughout the model.
B14: Tab guide
B15: Scenario Control: Base / Bull / Bear switch and the operating drivers that feed every scenario.
B16: Assumptions: Company financials, WACC build, and the 5-year operating projection (shared by all models).
B17: Trading Comps: Comparable company multiples and an implied valuation range for the target.
... B29: All figures are illustrative placeholders for a hypothetical company. Replace every blue input cell with your own data.

Sheet Scenario Control
B2: Scenario Control
B3: Pick a scenario in C3 it drives every operating assumption used across the workbook.
B5: Active Scenario: | C5: Base
B7: Driver | C7: Base | D7: Bull | E7: Bear | F7: Selected
B8: Revenue Growth Year 1 | C8: 0.08 | D8: 0.12 | E8: 0.04 | F8: =INDEX(C8:E8,MATCH($C$5,$C$7:$E$7,0)) -> 0.08
B9: Revenue Growth Year 2 | C9: 0.07 | D9: 0.1 | E9: 0.03 | F9: =INDEX(C9:E9,MATCH($C$5,$C$7:$E$7,0)) -> 0.07
B10: Revenue Growth Year 3 | C10: 0.06 | D10: 0.09 | E10: 0.03 | F10: =INDEX(C10:E10,MATCH($C$5,$C$7:$E$7,0)) -> 0.06
B11: Revenue Growth Year 4 | C11: 0.05 | D11: 0.08 | E11: 0.02 | F11: =INDEX(C11:E11,MATCH($C$5,$C$7:$E$7,0)) -> 0.05
B12: Revenue Growth Year 5 | C12: 0.04 | D12: 0.07 | E12: 0.02 | F12: =INDEX(C12:E12,MATCH($C$5,$C$7:$E$7,0)) -> 0.04
B13: EBITDA Margin Year 1 | C13: 0.22 | D13: 0.24 | E13: 0.19 | F13: =INDEX(C13:E13,MATCH($C$5,$C$7:$E$7,0)) -> 0.22
B14: EBITDA Margin Year 5 | C14: 0.26 | D14: 0.29 | E14: 0.21 | F14: =INDEX(C14:E14,MATCH($C$5,$C$7:$E$7,0)) -> 0.26
B15: D&A (% of Revenue) | C15: 0.04 | D15: 0.04 | E15: 0.045 | F15: =INDEX(C15:E15,MATCH($C$5,$C$7:$E$7,0)) -> 0.04
B16: Capex (% of Revenue) | C16: 0.05 | D16: 0.055 | E16: 0.045 | F16: =INDEX(C16:E16,MATCH($C$5,$C$7:$E$7,0)) -> 0.05
B17: Δ NWC (% of Revenue Growth $) | C17: 0.15 | D17: 0.15 | E17: 0.15 | F17: =INDEX(C17:E17,MATCH($C$5,$C$7:$E$7,0)) -> 0.15
B18: Tax Rate | C18: 0.25 | D18: 0.25 | E18: 0.25 | F18: =INDEX(C18:E18,MATCH($C$5,$C$7:$E$7,0)) -> 0.25
B19: Terminal Growth Rate (Gordon) | C19: 0.025 | D19: 0.03 | E19: 0.02 | F19: =INDEX(C19:E19,MATCH($C$5,$C$7:$E$7,0)) -> 0.025
B20: Exit EV/EBITDA Multiple | C20: 9 | D20: 10.5 | E20: 7.5 | F20: =INDEX(C20:E20,MATCH($C$5,$C$7:$E$7,0)) -> 9

Sheet Assumptions
B2: Assumptions
B3: Company financials, WACC build, and the 5-year operating projection shared by every model tab.
B5: Company & Market Inputs
B6: Company Name | C6: Creatify
B7: LTM Revenue ($mm) | C7: 1000
B8: LTM EBITDA Margin (%) | C8: 0.21
B9: LTM EBITDA ($mm) | C9: =C7*C8 -> 210
B10: LTM Net Income ($mm) | C10: 130
B11: Total Debt ($mm) | C11: 350
B12: Cash & Equivalents ($mm) | C12: 50
B13: Net Debt ($mm) | C13: =C11-C12 -> 300
B14: Diluted Shares Outstanding (mm) | C14: 100
B15: Current Share Price ($) | C15: 18
B16: Current Market Cap ($mm) | C16: =C14*C15 -> 1800
B17: Implied Current EV ($mm) | C17: =C16+C13 -> 2100
B19: WACC Build (CAPM)
B20: Risk-Free Rate | C20: 0.042
B21: Levered Beta | C21: 1.15
B22: Equity Risk Premium | C22: 0.055
B23: Cost of Equity (CAPM) | C23: =C20+C21*C22 -> 0.10525
B24: Pre-Tax Cost of Debt | C24: 0.065
B25: Tax Rate (linked to Scenario) | C25: ='Scenario Control'!$F$18 -> 0.25
B26: After-Tax Cost of Debt | C26: =C24*(1-C25) -> 0.04875
B27: Target Debt / Total Capitalization | C27: 0.35
B28: Target Equity / Total Capitalization | C28: =1-C27 -> 0.65
B29: WACC | C29: =C28*C23+C27*C26 -> 0.085475
B31: 5-Year Operating Projection
B32: Fiscal Year | D32: 2026 | E32: 2027 | F32: 2028 | G32: 2029 | H32: 2030
B33: Revenue Growth % | D33: ='Scenario Control'!$F$8 -> 0.08 | E33: ='Scenario Control'!$F$9 -> 0.07 | F33: ='Scenario Control'!$F$10 -> 0.06 | G33: ='Scenario Control'!$F$11 -> 0.05 | H33: ='Scenario Control'!$F$12 -> 0.04
B34: Revenue ($mm) | D34: =C7*(1+D33) -> 1080 | E34: =D34*(1+E33) -> 1155.6 | F34: =E34*(1+F33) -> 1224.936 | G34: =F34*(1+G33) -> 1286.1828 | H34: =G34*(1+H33) -> 1337.6301
B35: EBITDA Margin % | D35: ='Scenario Control'!$F$13 -> 0.22 | E35: =D35+('Scenario Control'!$F$14-'Scenario Control'!$F$13)*1/4 -> 0.23 | F35: =D35+('Scenario Control'!$F$14-'Scenario Control'!$F$13)*2/4 -> 0.24 | G35: =D35+('Scenario Control'!$F$14-'Scenario Control'!$F$13)*3/4 -> 0.25 | H35: ='Scenario Control'!$F$14 -> 0.26
B36: EBITDA ($mm) | D36: =D34*D35 -> 237.6 | E36: =E34*E35 -> 265.788 | F36: =F34*F35 -> 293.98464 | G36: =G34*G35 -> 321.5457 | H36: =H34*H35 -> 347.78383
B37: D&A (% of Revenue) | D37: ='Scenario Control'!$F$15 -> 0.04 | E37: ='Scenario Control'!$F$15 -> 0.04 | F37: ='Scenario Control'!$F$15 -> 0.04 | G37: ='Scenario Control'!$F$15 -> 0.04 | H37: ='Scenario Control'!$F$15 -> 0.04
B38: D&A ($mm) | D38: =D34*D37 -> 43.2 | E38: =E34*E37 -> 46.224 | F38: =F34*F37 -> 48.99744 | G38: =G34*G37 -> 51.447312 | H38: =H34*H37 -> 53.505204
B39: EBIT ($mm) | D39: =D36-D38 -> 194.4 | E39: =E36-E38 -> 219.564 | F39: =F36-F38 -> 244.9872 | G39: =G36-G38 -> 270.09839 | H39: =H36-H38 -> 294.27862
B40: Tax Rate % | D40: ='Scenario Control'!$F$18 -> 0.25 | E40: ='Scenario Control'!$F$18 -> 0.25 | F40: ='Scenario Control'!$F$18 -> 0.25 | G40: ='Scenario Control'!$F$18 -> 0.25 | H40: ='Scenario Control'!$F$18 -> 0.25
B41: NOPAT ($mm) | D41: =D39*(1-D40) -> 145.8 | E41: =E39*(1-E40) -> 164.673 | F41: =F39*(1-F40) -> 183.7404 | G41: =G39*(1-G40) -> 202.57379 | H41: =H39*(1-H40) -> 220.70897
B42: Capex (% of Revenue) | D42: ='Scenario Control'!$F$16 -> 0.05 | E42: ='Scenario Control'!$F$16 -> 0.05 | F42: ='Scenario Control'!$F$16 -> 0.05 | G42: ='Scenario Control'!$F$16 -> 0.05 | H42: ='Scenario Control'!$F$16 -> 0.05
B43: Capex ($mm) | D43: =D34*D42 -> 54 | E43: =E34*E42 -> 57.78 | F43: =F34*F42 -> 61.2468 | G43: =G34*G42 -> 64.30914 | H43: =H34*H42 -> 66.881506
B44: Δ Net Working Capital ($mm) | D44: =(D34-C7)*'Scenario Control'!$F$17 -> 12 | E44: =(E34-D34)*'Scenario Control'!$F$17 -> 11.34 | F44: =(F34-E34)*'Scenario Control'!$F$17 -> 10.4004 | G44: =(G34-F34)*'Scenario Control'!$F$17 -> 9.18702 | H44: =(H34-G34)*'Scenario Control'!$F$17 -> 7.7170968
...

Sheet Trading Comps
B2: Trading Comparables Analysis
B3: Comparable company multiples applied to the target's LTM metrics (linked from Assumptions).
B5: Company | C5: Share Price ($) | D5: Diluted Shares (mm) | E5: Market Cap ($mm) | F5: Total Debt ($mm) | G5: Cash ($mm) | H5: Enterprise Value ($mm) | I5: LTM Revenue ($mm) | J5: LTM EBITDA ($mm) | K5: LTM Net Income ($mm) | L5: EV / Revenue | M5: EV / EBITDA | N5: P / E
B6: Comp A Holdings | C6: 24.5 | D6: 120 | E6: =C6*D6 -> 2940 | F6: 200 | G6: 40 | H6: =E6+F6-G6 -> 3100 | I6: 1150 | J6: 265 | K6: 150 | L6: =IFERROR(H6/I6,"-") -> 2.6956522 | M6: =IFERROR(H6/J6,"-") -> 11.698113 | N6: =IFERROR(E6/K6,"-") -> 19.6
B7: Comp B Industries | C7: 31.2 | D7: 85 | E7: =C7*D7 -> 2652 | F7: 150 | G7: 25 | H7: =E7+F7-G7 -> 2777 | I7: 950 | J7: 210 | K7: 118 | L7: =IFERROR(H7/I7,"-") -> 2.9231579 | M7: =IFERROR(H7/J7,"-") -> 13.22381 | N7: =IFERROR(E7/K7,"-") -> 22.474576
B8: Comp C Global | C8: 18.75 | D8: 140 | E8: =C8*D8 -> 2625 | F8: 300 | G8: 60 | H8: =E8+F8-G8 -> 2865 | I8: 1400 | J8: 300 | K8: 165 | L8: =IFERROR(H8/I8,"-") -> 2.0464286 | M8: =IFERROR(H8/J8,"-") -> 9.55 | N8: =IFERROR(E8/K8,"-") -> 15.909091
B9: Comp D Partners | C9: 42 | D9: 60 | E9: =C9*D9 -> 2520 | F9: 100 | G9: 80 | H9: =E9+F9-G9 -> 2540 | I9: 700 | J9: 175 | K9: 105 | L9: =IFERROR(H9/I9,"-") -> 3.6285714 | M9: =IFERROR(H9/J9,"-") -> 14.514286 | N9: =IFERROR(E9/K9,"-") -> 24
B10: Comp E Corp | C10: 15.3 | D10: 200 | E10: =C10*D10 -> 3060 | F10: 400 | G10: 50 | H10: =E10+F10-G10 -> 3410 | I10: 1600 | J10: 336 | K10: 190 | L10: =IFERROR(H10/I10,"-") -> 2.13125 | M10: =IFERROR(H10/J10,"-") -> 10.14881 | N10: =IFERROR(E10/K10,"-") -> 16.105263
B11: Comp F Enterprises | C11: 27.8 | D11: 95 | E11: =C11*D11 -> 2641 | F11: 180 | G11: 35 | H11: =E11+F11-G11 -> 2786 | I11: 1020 | J11: 235 | K11: 135 | L11: =IFERROR(H11/I11,"-") -> 2.7313725 | M11: =IFERROR(H11/J11,"-") -> 11.855319 | N11: =IFERROR(E11/K11,"-") -> 19.562963
B12: Comp G Solutions | C12: 22.1 | D12: 110 | E12: =C12*D12 -> 2431 | F12: 220 | G12: 45 | H12: =E12+F12-G12 -> 2606 | I12: 1080 | J12: 245 | K12: 140 | L12: =IFERROR(H12/I12,"-") -> 2.412963 | M12: =IFERROR(H12/J12,"-") -> 10.636735 | N12: =IFERROR(E12/K12,"-") -> 17.364286
B14: Mean | L14: =AVERAGE(L6:L12) -> 2.6527708 | M14: =AVERAGE(M6:M12) -> 11.66101 | N14: =AVERAGE(N6:N12) -> 19.288026
B15: Median | L15: =MEDIAN(L6:L12) -> 2.6956522 | M15: =MEDIAN(M6:M12) -> 11.698113 | N15: =MEDIAN(N6:N12) -> 19.562963
B16: Min | L16: =MIN(L6:L12) -> 2.0464286 | M16: =MIN(M6:M12) -> 9.55 | N16: =MIN(N6:N12) -> 15.909091
B17: Max | L17: =MAX(L6:L12) -> 3.6285714 | M17: =MAX(M6:M12) -> 14.514286 | N17: =MAX(N6:N12) -> 24
B19: Implied Valuation of Target Co. (linked from Assumptions)
B20: Target LTM Revenue ($mm) | C20: =Assumptions!$C$7 -> 1000
B21: Target LTM EBITDA ($mm) | C21: =Assumptions!$C$9 -> 210
B22: Target LTM Net Income ($mm) | C22: =Assumptions!$C$10 -> 130
B23: Target Net Debt ($mm) | C23: =Assumptions!$C$13 -> 300
B24: Target Diluted Shares (mm) | C24: =Assumptions!$C$14 -> 100
B26: Method | C26: Multiple Applied | D26: Implied EV ($mm) | E26: Implied Equity Value ($mm) | F26: Implied Share Price ($)
B27: EV / Revenue (Median) | C27: =L15 -> 2.6956522 | D27: =C27*C20 -> 2695.6522 | E27: =D27-C23 -> 2395.6522 | F27: =E27/C24 -> 23.956522
B28: EV / EBITDA (Median) | C28: =M15 -> 11.698113 | D28: =C28*C21 -> 2456.6038 | E28: =D28-C23 -> 2156.6038 | F28: =E28/C24 -> 21.566038
B29: P / E (Median) | C29: =N15 -> 19.562963 | D29: n/a (equity method) | E29: =C29*C22 -> 2543.1852 | F29: =E29/C24 -> 25.431852
B30: EV / EBITDA (Min Comp — Low) | C30: =M16 -> 9.55 | D30: =C30*C21 -> 2005.5 | E30: =D30-C23 -> 1705.5 | F30: =E30/C24 -> 17.055
B31: EV / EBITDA (Max Comp — High) | C31: =M17 -> 14.514286 | D31: =C31*C21 -> 3048 | E31: =D31-C23 -> 2748 | F31: =E31/C24 -> 27.48

Sheet DCF Valuation
B2: DCF Valuation
B3: Unlevered FCF discounted at WACC; Gordon Growth and Exit Multiple terminal value methods, cross-checked.
B5: Fiscal Year | D5: =Assumptions!D32 -> 2026 | E5: =Assumptions!E32 -> 2027 | F5: =Assumptions!F32 -> 2028 | G5: =Assumptions!G32 -> 2029 | H5: =Assumptions!H32 -> 2030
B6: Period | D6: 1 | E6: 2 | F6: 3 | G6: 4 | H6: 5
B7: Unlevered Free Cash Flow ($mm) | D7: =Assumptions!D45 -> 123 | E7: =Assumptions!E45 -> 141.777 | F7: =Assumptions!F45 -> 161.09064 | G7: =Assumptions!G45 -> 180.52494 | H7: =Assumptions!H45 -> 199.61557
B8: Discount Factor | D8: =1/(1+$C$11)^D6 -> 0.92125567 | E8: =1/(1+$C$11)^E6 -> 0.84871201 | F8: =1/(1+$C$11)^F6 -> 0.78188075 | G8: =1/(1+$C$11)^G6 -> 0.72031208 | H8: =1/(1+$C$11)^H6 -> 0.66359159
B9: PV of Free Cash Flow ($mm) | D9: =D7*D8 -> 113.31445 | E9: =E7*E8 -> 120.32784 | F9: =F7*F8 -> 125.95367 | G9: =G7*G8 -> 130.0343 | H9: =H7*H8 -> 132.46321
B11: WACC | C11: =Assumptions!$C$29 -> 0.085475
B12: Terminal Growth Rate | C12: ='Scenario Control'!$F$19 -> 0.025
B14: Gordon Growth Method
B15: Sum of PV of Explicit FCF (Yr 1–5) | C15: =SUM(D9:H9) -> 622.09347
B16: Terminal Value (Year 5) | C16: =H7*(1+$C$12)/($C$11-$C$12) -> 3383.3148
B17: PV of Terminal Value | C17: =C16/(1+$C$11)^5 -> 2245.1392
B18: Enterprise Value (Gordon Growth) | C18: =C15+C17 -> 2867.2327
B20: Exit Multiple Method (Cross-Check)
B21: Exit EV/EBITDA Multiple | C21: ='Scenario Control'!$F$20 -> 9
B22: Terminal Value (Exit Multiple) | C22: =Assumptions!H36*C21 -> 3130.0545
B23: PV of Terminal Value | C23: =C22/(1+$C$11)^5 -> 2077.0778
B24: Enterprise Value (Exit Multiple) | C24: =C15+C23 -> 2699.1713
B26: Equity Value Bridge
B27: Less: Net Debt | C27: =Assumptions!$C$13 -> 300
B28: Equity Value — Gordon Growth ($mm) | C28: =C18-C27 -> 2567.2327
B29: Equity Value — Exit Multiple ($mm) | C29: =C24-C27 -> 2399.1713
B30: Diluted Shares Outstanding (mm) | C30: =Assumptions!$C$14 -> 100
B31: Implied Share Price — Gordon Growth ($) | C31: =C28/C30 -> 25.672327
B32: Implied Share Price — Exit Multiple ($) | C32: =C29/C30 -> 23.991713
B34: Sensitivity: Implied Share Price ($) — WACC (rows) vs. Terminal Growth Rate (cols)
C36: WACC \ g | D36: =$C$12+(-0.01) -> 0.015 | E36: =$C$12+(-0.005) -> 0.02 | F36: =$C$12+(0) -> 0.025 | G36: =$C$12+(0.005) -> 0.03 | H36: =$C$12+(0.01) -> 0.035
C37: =$C$11+(-0.01) -> 0.075475 | D37: =IFERROR(((SUMPRODUCT($D$7:$H$7,(1+$C37)^-$D$6:$H$6)+$H$7*(1+D$36)/($C37-D$36)/(1+$C37)^5)-$C$27)/$C$30,"n/a") -> 26.686557 | E37: =IFERROR(((SUMPRODUCT($D$7:$H$7,(1+$C37)^-$D$6:$H$6)+$H$7*(1+E$36)/($C37-E$36)/(1+$C37)^5)-$C$27)/$C$30,"n/a") -> 28.910327 | F37: =IFERROR(((SUMPRODUCT($D$7:$H$7,(1+$C37)^-$D$6:$H$6)+$H$7*(1+F$36)/($C37-F$36)/(1+$C37)^5)-$C$27)/$C$30,"n/a") -> 31.574666 | G37: =IFERROR(((SUMPRODUCT($D$7:$H$7,(1+$C37)^-$D$6:$H$6)+$H$7*(1+G$36)/($C37-G$36)/(1+$C37)^5)-$C$27)/$C$30,"n/a") -> 34.824896 | H37: =IFERROR(((SUMPRODUCT($D$7:$H$7,(1+$C37)^-$D$6:$H$6)+$H$7*(1+H$36)/($C37-H$36)/(1+$C37)^5)-$C$27)/$C$30,"n/a") -> 38.878148
C38: =$C$11+(-0.005) -> 0.080475 | D38: =IFERROR(((SUMPRODUCT($D$7:$H$7,(1+$C38)^-$D$6:$H$6)+$H$7*(1+D$36)/($C38-D$36)/(1+$C38)^5)-$C$27)/$C$30,"n/a") -> 24.324206 | E38: =IFERROR(((SUMPRODUCT($D$7:$H$7,(1+$C38)^-$D$6:$H$6)+$H$7*(1+E$36)/($C38-E$36)/(1+$C38)^5)-$C$27)/$C$30,"n/a") -> 26.173705 | F38: =IFERROR(((SUMPRODUCT($D$7:$H$7,(1+$C38)^-$D$6:$H$6)+$H$7*(1+F$36)/($C38-F$36)/(1+$C38)^5)-$C$27)/$C$30,"n/a") -> 28.356597 | G38: =IFERROR(((SUMPRODUCT($D$7:$H$7,(1+$C38)^-$D$6:$H$6)+$H$7*(1+G$36)/($C38-G$36)/(1+$C38)^5)-$C$27)/$C$30,"n/a") -> 30.97196 | H38: =IFERROR(((SUMPRODUCT($D$7:$H$7,(1+$C38)^-$D$6:$H$6)+$H$7*(1+H$36)/($C38-H$36)/(1+$C38)^5)-$C$27)/$C$30,"n/a") -> 34.162443
C39: =$C$11+(0) -> 0.085475 | D39: =IFERROR(((SUMPRODUCT($D$7:$H$7,(1+$C39)^-$D$6:$H$6)+$H$7*(1+D$36)/($C39-D$36)/(1+$C39)^5)-$C$27)/$C$30,"n/a") -> 22.298645 | E39: =IFERROR(((SUMPRODUCT($D$7:$H$7,(1+$C39)^-$D$6:$H$6)+$H$7*(1+E$36)/($C39-E$36)/(1+$C39)^5)-$C$27)/$C$30,"n/a") -> 23.85667 | F39: =IFERROR(((SUMPRODUCT($D$7:$H$7,(1+$C39)^-$D$6:$H$6)+$H$7*(1+F$36)/($C39-F$36)/(1+$C39)^5)-$C$27)/$C$30,"n/a") -> 25.672327 | G39: =IFERROR(((SUMPRODUCT($D$7:$H$7,(1+$C39)^-$D$6:$H$6)+$H$7*(1+G$36)/($C39-G$36)/(1+$C39)^5)-$C$27)/$C$30,"n/a") -> 27.815276 | H39: =IFERROR(((SUMPRODUCT($D$7:$H$7,(1+$C39)^-$D$6:$H$6)+$H$7*(1+H$36)/($C39-H$36)/(1+$C39)^5)-$C$27)/$C$30,"n/a") -> 30.382782
C40: =$C$11+(0.005) -> 0.090475 | D40: =IFERROR(((SUMPRODUCT($D$7:$H$7,(1+$C40)^-$D$6:$H$6)+$H$7*(1+D$36)/($C40-D$36)/(1+$C40)^5)-$C$27)/$C$30,"n/a") -> 20.542905 | E40: =IFERROR(((SUMPRODUCT($D$7:$H$7,(1+$C40)^-$D$6:$H$6)+$H$7*(1+E$36)/($C40-E$36)/(1+$C40)^5)-$C$27)/$C$30,"n/a") -> 21.869882 | F40: =IFERROR(((SUMPRODUCT($D$7:$H$7,(1+$C40)^-$D$6:$H$6)+$H$7*(1+F$36)/($C40-F$36)/(1+$C40)^5)-$C$27)/$C$30,"n/a") -> 23.399528 | G40: =IFERROR(((SUMPRODUCT($D$7:$H$7,(1+$C40)^-$D$6:$H$6)+$H$7*(1+G$36)/($C40-G$36)/(1+$C40)^5)-$C$27)/$C$30,"n/a") -> 25.182113 | H40: =IFERROR(((SUMPRODUCT($D$7:$H$7,(1+$C40)^-$D$6:$H$6)+$H$7*(1+H$36)/($C40-H$36)/(1+$C40)^5)-$C$27)/$C$30,"n/a") -> 27.286029
C41: =$C$11+(0.01) -> 0.095475 | D41: =IFERROR(((SUMPRODUCT($D$7:$H$7,(1+$C41)^-$D$6:$H$6)+$H$7*(1+D$36)/($C41-D$36)/(1+$C41)^5)-$C$27)/$C$30,"n/a") -> 19.006662 | E41: =IFERROR(((SUMPRODUCT($D$7:$H$7,(1+$C41)^-$D$6:$H$6)+$H$7*(1+E$36)/($C41-E$36)/(1+$C41)^5)-$C$27)/$C$30,"n/a") -> 20.147675 | F41: =IFERROR(((SUMPRODUCT($D$7:$H$7,(1+$C41)^-$D$6:$H$6)+$H$7*(1+F$36)/($C41-F$36)/(1+$C41)^5)-$C$27)/$C$30,"n/a") -> 21.450591 | G41: =IFERROR(((SUMPRODUCT($D$7:$H$7,(1+$C41)^-$D$6:$H$6)+$H$7*(1+G$36)/($C41-G$36)/(1+$C41)^5)-$C$27)/$C$30,"n/a") -> 22.952501 | H41: =IFERROR(((SUMPRODUCT($D$7:$H$7,(1+$C41)^-$D$6:$H$6)+$H$7*(1+H$36)/($C41-H$36)/(1+$C41)^5)-$C$27)/$C$30,"n/a") -> 24.702763

Sheet LBO Model
B2: LBO Model
B3: Sources & Uses, a two-tranche debt schedule with cash sweep, and sponsor returns (MOIC / IRR).
B5: Transaction Assumptions
B6: Entry EV/EBITDA Multiple | C6: 8.5
B7: Entry EBITDA (LTM, $mm) | C7: =Assumptions!$C$9 -> 210
B8: Entry Enterprise Value ($mm) | C8: =C6*C7 -> 1785
B9: Transaction Fees (% of EV) | C9: 0.02
B10: Transaction Fees ($mm) | C10: =C8*C9 -> 35.7
B11: Total Uses ($mm) | C11: =C8+C10 -> 1820.7
B13: Sources of Funds
B14: Senior Debt / EBITDA (x) | C14: 4
B15: Senior Debt ($mm) | C15: =C14*C7 -> 840
B16: Subordinated (Mezz) Debt / EBITDA (x) | C16: 1.5
B17: Subordinated Debt ($mm) | C17: =C16*C7 -> 315
B18: Sponsor Equity ($mm) — plug | C18: =C11-C15-C17 -> 665.7
B19: Total Sources ($mm) | C19: =C15+C17+C18 -> 1820.7
B20: Check: Sources − Uses (must be $0) | C20: =C19-C11 -> 0
B22: Financing Terms
B23: Senior Debt Interest Rate | C23: 0.07
B24: Subordinated Debt Interest Rate | C24: 0.105
B25: Mandatory Amortization (% of Original Senior Principal / Yr) | C25: 0.05
B26: Hold Period (Years) | C26: 5
B27: Exit EV/EBITDA Multiple | C27: ='Scenario Control'!$F$20 -> 9
B29: Operating & Free Cash Flow Build
B30: Fiscal Year | D30: =Assumptions!D32 -> 2026 | E30: =Assumptions!E32 -> 2027 | F30: =Assumptions!F32 -> 2028 | G30: =Assumptions!G32 -> 2029 | H30: =Assumptions!H32 -> 2030
B31: EBITDA ($mm) | D31: =Assumptions!D36 -> 237.6 | E31: =Assumptions!E36 -> 265.788 | F31: =Assumptions!F36 -> 293.98464 | G31: =Assumptions!G36 -> 321.5457 | H31: =Assumptions!H36 -> 347.78383
B32: Capex ($mm) | D32: =Assumptions!D43 -> 54 | E32: =Assumptions!E43 -> 57.78 | F32: =Assumptions!F43 -> 61.2468 | G32: =Assumptions!G43 -> 64.30914 | H32: =Assumptions!H43 -> 66.881506
B33: Δ Net Working Capital ($mm) | D33: =Assumptions!D44 -> 12 | E33: =Assumptions!E44 -> 11.34 | F33: =Assumptions!F44 -> 10.4004 | G33: =Assumptions!G44 -> 9.18702 | H33: =Assumptions!H44 -> 7.7170968
B34: D&A ($mm) | D34: =Assumptions!D38 -> 43.2 | E34: =Assumptions!E38 -> 46.224 | F34: =Assumptions!F38 -> 48.99744 | G34: =Assumptions!G38 -> 51.447312 | H34: =Assumptions!H38 -> 53.505204
B35: Tax Rate % | D35: =Assumptions!D40 -> 0.25 | E35: =Assumptions!E40 -> 0.25 | F35: =Assumptions!F40 -> 0.25 | G35: =Assumptions!G40 -> 0.25 | H35: =Assumptions!H40 -> 0.25
B37: Debt Schedule & Cash Sweep
B38: Senior Debt — Beginning Balance ($mm) | D38: =$C$15 -> 840 | E38: =D49 -> 785.90625 | F38: =E49 -> 710.19558 | G38: =F49 -> 611.19646 | H38: =G49 -> 487.56558
B39: Mandatory Amortization ($mm) | D39: =MIN(D38,$C$25*$C$15) -> 42 | E39: =MIN(E38,$C$25*$C$15) -> 42 | F39: =MIN(F38,$C$25*$C$15) -> 42 | G39: =MIN(G38,$C$25*$C$15) -> 42 | H39: =MIN(H38,$C$25*$C$15) -> 42
B40: Interest Expense — Senior ($mm) | D40: =D38*$C$23 -> 58.8 | E40: =E38*$C$23 -> 55.013438 | F40: =F38*$C$23 -> 49.71369 | G40: =G38*$C$23 -> 42.783752 | H40: =H38*$C$23 -> 34.12959
B41: Subordinated Debt — Beginning Balance ($mm) | D41: =$C$17 -> 315 | E41: =D50 -> 315 | F41: =E50 -> 315 | G41: =F50 -> 315 | H41: =G50 -> 315
B42: Interest Expense — Subordinated ($mm) | D42: =D41*$C$24 -> 33.075 | E42: =E41*$C$24 -> 33.075 | F42: =F41*$C$24 -> 33.075 | G42: =G41*$C$24 -> 33.075 | H42: =H41*$C$24 -> 33.075
B43: Total Cash Interest Expense ($mm) | D43: =D40+D42 -> 91.875 | E43: =E40+E42 -> 88.088437 | F43: =F40+F42 -> 82.78869 | G43: =G40+G42 -> 75.858752 | H43: =H40+H42 -> 67.20459
B44: EBT ($mm) | D44: =D31-D34-D43 -> 102.525 | E44: =E31-E34-E43 -> 131.47556 | F44: =F31-F34-F43 -> 162.19851 | G44: =G31-G34-G43 -> 194.23964 | H44: =H31-H34-H43 -> 227.07403
B45: Cash Taxes ($mm) | D45: =MAX(D44,0)*D35 -> 25.63125 | E45: =MAX(E44,0)*E35 -> 32.868891 | F45: =MAX(F44,0)*F35 -> 40.549627 | G45: =MAX(G44,0)*G35 -> 48.559909 | H45: =MAX(H44,0)*H35 -> 56.768509
B46: Free Cash Flow Before Debt Paydown ($mm) | D46: =D31-D32-D33-D43-D45 -> 54.09375 | E46: =E31-E32-E33-E43-E45 -> 75.710672 | F46: =F31-F32-F33-F43-F45 -> 98.999122 | G46: =G31-G32-G33-G43-G45 -> 123.63088 | H46: =H31-H32-H33-H43-H45 -> 149.21213
...

Sheet MA Accretion-Dilution
B2: M&A Accretion / Dilution Analysis
B3: Illustrative acquirer/target replace the blue inputs with a real deal's figures.
B5: Acquirer Standalone
B6: Acquirer Net Income ($mm) | C6: 150
B7: Acquirer Diluted Shares (mm) | C7: 100
B8: Acquirer Share Price ($) | C8: 22
B9: Acquirer Standalone EPS ($) | C9: =C6/C7 -> 1.5
B11: Target Standalone
B12: Target Net Income ($mm) | C12: 40
B13: Target Diluted Shares (mm) | C13: 45
B14: Target Share Price ($) | C14: 12
B15: Target Standalone EPS ($) | C15: =C12/C13 -> 0.88888889
B17: Deal Terms
B18: Offer Premium (%) | C18: 0.25
B19: Offer Price per Target Share ($) | C19: =C14*(1+C18) -> 15
B20: Total Purchase Price ($mm) | C20: =C19*C13 -> 675
B21: % Cash Consideration | C21: 0.6
B22: % Stock Consideration | C22: =1-C21 -> 0.4
B23: Cash Consideration ($mm) | C23: =C20*C21 -> 405
B24: Stock Consideration ($mm) | C24: =C20*C22 -> 270
B25: New Debt Issued to Fund Cash ($mm) | C25: =C23 -> 405
B26: New Shares Issued (mm) | C26: =C24/C8 -> 12.272727
B27: New Debt Interest Rate (%) | C27: 0.065
B29: Synergies & Financing Impact
B30: Pre-Tax Annual Synergies ($mm) | C30: 8
B31: Combined Tax Rate (%) | C31: 0.25
B32: After-Tax Synergies ($mm) | C32: =C30*(1-C31) -> 6
B33: Incremental Interest Expense ($mm) | C33: =C25*C27 -> 26.325
B34: After-Tax Incremental Interest Expense ($mm) | C34: =C33*(1-C31) -> 19.74375
B35: Incremental D&A from Purchase Accounting, Pre-Tax ($mm) | C35: 5
B36: After-Tax Incremental D&A ($mm) | C36: =C35*(1-C31) -> 3.75
B38: Pro Forma Combined
B39: Pro Forma Net Income ($mm) | C39: =C6+C12+C32-C34-C36 -> 172.50625
B40: Pro Forma Diluted Shares (mm) | C40: =C7+C26 -> 112.27273
B41: Pro Forma EPS ($) | C41: =C39/C40 -> 1.5364929
B42: Acquirer Standalone EPS ($) | C42: =C9 -> 1.5
B43: Accretion / (Dilution) per Share ($) | C43: =C41-C42 -> 0.036492915
B44: Accretion / (Dilution) (%) | C44: =C41/C42-1 -> 0.02432861
B45: Deal Status | C45: =IF(C44>=0,"Accretive","Dilutive") -> Accretive

Sheet Valuation Summary
B2: Valuation Summary
B3: Implied per-share value ranges from each method, linked live from DCF Valuation, Trading Comps, and LBO Model.
B5: Method | C5: Low ($) | D5: High ($) | E5: Range ($)
B6: DCF Gordon Growth (Sensitivity Range) | C6: =MIN('DCF Valuation'!D37:H41) -> 19.006662 | D6: =MAX('DCF Valuation'!D37:H41) -> 38.878148 | E6: =D6-C6 -> 19.871486
B7: DCF Exit Multiple (±5%) | C7: ='DCF Valuation'!C32*0.95 -> 22.792127 | D7: ='DCF Valuation'!C32*1.05 -> 25.191298 | E7: =D7-C7 -> 2.3991713
B8: Trading Comps EV/EBITDA (Min–Max) | C8: ='Trading Comps'!F30 -> 17.055 | D8: ='Trading Comps'!F31 -> 27.48 | E8: =D8-C8 -> 10.425
B9: LBO Implied Entry Price (20%–25% IRR Hurdle) | C9: =MIN('LBO Model'!C86,'LBO Model'!C87) -> 16.280053 | D9: =MAX('LBO Model'!C86,'LBO Model'!C87) -> 18.081672 | E9: =D9-C9 -> 1.8016196
B11: Current Trading Price (reference, not shown as a range) | C11: =Assumptions!$C$15 -> 18
