Workbook
Name Additional_Commissioning_Costs: 'Step 2.3 - Data Input (CapEx)'!$F$18
Name Additional_Component_Costs: 'Step 2.4 - Data Input (OpEx)'!$F$92
Name Additional_Ongoing_Property_Costs: 'Step 2.4 - Data Input (OpEx)'!$F$33
Name Additional_Special_Costs: 'Step 2.4 - Data Input (OpEx)'!$F$11
Name Administrative_Overhead: 'Step 2.1 - Data Input (General)'!$F$8
Name Annual_Depreciation: 'Step 2.1 - Data Input (General)'!$F$9
Name Annual_Efficiency_Increase_Automated_Labour: 'Step 2.4 - Data Input (OpEx)'!$F$18
Name Annual_Efficiency_Increase_Backward_Logistics: 'Step 2.4 - Data Input (OpEx)'!$F$19
Name Annual_Efficiency_Increase_Forward_Logistics: 'Step 2.4 - Data Input (OpEx)'!$F$20
Name Annual_Efficiency_Increase_Manual_Labour: 'Step 2.4 - Data Input (OpEx)'!$F$17
Name Annual_Price_Rental_Contract: 'Step 2.2 - Data Input (Revenue)'!$F$16
Name Annual_Price_Trend_Electricity: 'Step 2.4 - Data Input (OpEx)'!$F$16
Name Annual_Price_Trend_Heating: 'Step 2.4 - Data Input (OpEx)'!$F$15
Name Annual_Price_Trend_Virgin_Materials: 'Step 2.4 - Data Input (OpEx)'!$F$14
Name Automated_Labour_Assembly: 'Step 2.4 - Data Input (OpEx)'!$F$90
Name Automated_Labour_Cleaning: 'Step 2.4 - Data Input (OpEx)'!$F$79
Name Automated_Labour_Disassembly: 'Step 2.4 - Data Input (OpEx)'!$F$65
Name Automated_Labour_Dismantling: 'Step 2.4 - Data Input (OpEx)'!$F$54
Name Automated_Labour_Identification___Sorting: 'Step 2.4 - Data Input (OpEx)'!$F$59
Name Automated_Labour_Inspection: 'Step 2.4 - Data Input (OpEx)'!$F$70
Name Automated_Labour_Linear_Production: 'Step 2.4 - Data Input (OpEx)'!$F$39
Name Automated_Labour_Restoring: 'Step 2.4 - Data Input (OpEx)'!$F$84
Name Automated_Labour_Testing: 'Step 2.4 - Data Input (OpEx)'!$F$97
Name Base_Costs_Electricity: 'Step 2.4 - Data Input (OpEx)'!$F$26
Name Base_Costs_Heating: 'Step 2.4 - Data Input (OpEx)'!$F$23
Name Basic_Rent: 'Step 2.4 - Data Input (OpEx)'!$F$31
Name BL_Distance_Core_Acquisition_Site: 'Step 2.4 - Data Input (OpEx)'!$F$45
Name BL_Distance_Customer: 'Step 2.4 - Data Input (OpEx)'!$F$44
Name BL_Flat_Rate: 'Step 2.4 - Data Input (OpEx)'!$F$43
Name BL_KM_Cost: 'Step 2.4 - Data Input (OpEx)'!$F$46
Name BL_Packaging_Cost: 'Step 2.4 - Data Input (OpEx)'!$F$47
Name BL_Shipment_Cost: 'Step 2.4 - Data Input (OpEx)'!$F$48
Name BL_Type: 'Step 2.1 - Data Input (General)'!$F$21
Name Calculator_Code: 'Step 2.2 - Data Input (Revenue)'!#REF!
Name Calculator_Code: 'Step 2.3 - Data Input (CapEx)'!#REF!
Name Calculator_Code: 'Step 2.4 - Data Input (OpEx)'!#REF!
Name Calculator_Code: 'Step 2.1 - Data Input (General)'!#REF!
Name Certification_Costs: 'Step 2.4 - Data Input (OpEx)'!$F$98
Name Commissioning_Costs_Research___Development: 'Step 2.3 - Data Input (CapEx)'!$F$15
Name Commissioning_Time_Administration: 'Step 2.3 - Data Input (CapEx)'!$F$16
Name Commissioning_Time_Production_Staff: 'Step 2.3 - Data Input (CapEx)'!$F$17
Name Consumption_Cost_Electricity: 'Step 2.4 - Data Input (OpEx)'!$F$28
Name Consumption_Cost_Heating: 'Step 2.4 - Data Input (OpEx)'!$F$25
Name Core_Premium: 'Step 2.4 - Data Input (OpEx)'!$F$49
Name Core_Reuse_Rate: 'Step 2.1 - Data Input (General)'!$F$24
Name Corporate_Tax_Rate: 'Step 2.1 - Data Input (General)'!$F$6
Name Debt_Capital: 'Step 2.1 - Data Input (General)'!$F$16
Name Discount_Rate: 'Step 2.1 - Data Input (General)'!$F$7
Name Disposal_Cost_Component: 'Step 2.4 - Data Input (OpEx)'!$F$74
Name Disposal_Cost_Core: 'Step 2.4 - Data Input (OpEx)'!$F$60
Name Disposal_Cost_Linear_Production: 'Step 2.4 - Data Input (OpEx)'!$F$37
Name Energy_Consumption_Electricity: 'Step 2.4 - Data Input (OpEx)'!$F$27
Name Energy_Consumption_Heating: 'Step 2.4 - Data Input (OpEx)'!$F$24
Name FL_Average_Journey_Number: 'Step 2.4 - Data Input (OpEx)'!$F$104
Name FL_Distance_Customer: 'Step 2.4 - Data Input (OpEx)'!$F$103
Name FL_Flat_Rate: 'Step 2.4 - Data Input (OpEx)'!$F$102
Name FL_KM_Cost: 'Step 2.4 - Data Input (OpEx)'!$F$105
Name FL_Packaging_Cost: 'Step 2.4 - Data Input (OpEx)'!$F$106
Name FL_Shipment_Cost: 'Step 2.4 - Data Input (OpEx)'!$F$107
Name FL_Type: 'Step 2.1 - Data Input (General)'!$F$22

Sheet Start
C3: CE Business Case Calculator v1.1 powered by R-evolve
C6: Welcome!
C8: Introduction The CE Business Case Calculator is an Excel-based tool designed to assist companies in the economic evaluation of circular economy business models (CBMs). It enables a structured and transparent assessment of financial viability by modelling revenue streams, capital and operating expenditures (CapEX, OpEx) as well as financing costs in detail. The tool provides a clear and visually intuitive graphical representation of the results as an output. The current version (v1.1) of the calculator, developed by the Wuppertal Institute as part of the R-evolve project, covers the following CBMs, including several sub-strategies: Repair, Reuse, Refurbish, Remanufacture, Repurpose, Recycle and Rental. It also enables the parallel calculation and comparison of several scenarios, such as different sales markets or forecasts. Further features and business models will be included in future updates. This tool has been carefully developed and tested. However, minor errors cannot be entirely ruled out. Please note that we accept no liability for any misrepresentations or miscalculations, nor for decisions made on the basis of the results. We welcome your feedback to help us further improve and refine the calculator (see Contact). How to use the tool The calculator follows a clear three-step structure to guide users through the analysis: Step 1: By answering a short questionnaire, a case is selected and the tool is pre-configured to meet your specific requirements. Step 2: Starting with general financial figures (2.1), the tool guides you through the data entry for revenue (2.2), CapEx (2.3) and OpEx (2.4). Step 3: Based on the input, results are prepared automatically, focusing on key financial indicators and detailed cost analyses. The tool provides both an in-depth assessment of the base case (3.1) and an optional comparison with up to three scenarios (3.2). Calculation: All calculations are carried out in the calculation sheets and should not be altered to ensure the integrity of the tool. License This tool is published under the Creative Commons Attribution (CC BY) license: https://creativecommons.org/licenses/by/4.0/ Authors: Niklas Hoffmann, Martin Perau | Contact: niklas.hoffmann@wupperinst.org DOI: 10.5281/zenodo.20799159 22.06.2026
P36: This work has recived founding from the European Union's Horizon Europe research and innovation programme under GA nº101182221.

Sheet Step 1 - Case Selection
C3: Step 1 - Case Selection
C6: 1. Instructions
D7: You will be asked to answer a few questions about your company and the business case you are interested in. This serves to preset the calculator so that you get the best possible results with as little data entry as possible. To ensure an accurate and complete analysis, all highlighted questions must be answered. Where available, use the drop-down menus to answer. Manually overwriting data in this table will cause an error in the calculator!
D12: Company Name: | J12: Test Company
D14: Case Name: | J14: Test Case
D16: Short Case Description: | J16: …
C20: 2. Questionaire
D21: The following questions determine the basic configuration of the calculator. Depending on your answers, further detailed questions may appear, which must also be answered in this case. Conversely, greyed-out questions can be ignored. The results of the questionnaire have a significant influence on which data must be collected in Step 2. The term 'core' refers to a returned/retrieved item intended to be reprocessed and (or) resold.
D25: What type of business case would you like to calculate?
E27: What R-strategy (s.b.) does your business case follow or support?
F29: Do you sell a service or a product (incl. component)?
G31: What subtype service strategy do you employ?
F33: How many cores are required per output instance (e.g. per remanufactured product)? | W33: *usually it is 1
F35: What percentage of cores is discarded because they are not suitable for use? | W35: *fill in manually
F37: Do you pay a premium for the take back of cores?
E39: Does backward logistic play a relevant role in your business case?
F41: How do you want to calculate your backwards logistic?
G43: What model does your backwards logistic follow?
H45: Do you employ a direct or multi-stage pickup system?
H47: Are returns already sorted before being transported to the processing site?
E49: Do you receive public funding or other subsidies for realising this business case?
D51: How do you want to calculate your forward logistic?
E53: What model does your forward logistic follow?
D55: Does the implementation of this business case require major investments (CapEx)?
E57: Is a loan being taken out to cover (a part) of this investment costs?
D59: How many years should be considered for this business case analysis?
D61: Should depreciation be taken into account for this analysis?
C64: R-strategies: Repair: Repair of defective product so it can be used with its original function; Reuse: Reuse by another customer of discarded product which is still in good condition and fulfils its original function; Refurbishment: Restore an old product and bring it up to date; Remanufacturing: Use parts of discarded product in a new (!) product with the same function; Repurpose: Use discarded product or its parts in a new (!) product with a different function; Recycling: Process materials to obtain the same (high grade) or lower (low grade) quality; Rental: Offering a product as a service in exchange for receiving regular payments

Sheet Step 2.1 - Data Input (General)
B2: Step 2.1 - Data Input (General Data)
B3: Instructions If you completed the questionnaire in Step 1, you can now enter the data required to calculate your case. Fields that are greyed out are not relevant to your case. You can start with the Overall Financial Figures. You always have to fill out the "Base Case" (Column F). The calculation of additional scenarios (G - I) is optional. Core vs. Product: In the following, the word "core" is frequently used to describe a commodity that is taken back as input material for a CE business case (e.g. a used furniture item). The aim is to distinguish it clearly from a "product" that is an output of production and gets sold.
B4: Category | C4: Name | D4: Remark | E4: Calculator Code | F4: Base Case | G4: Scenario I | H4: Scenario II | I4: Scenario III | J4: Unit
B5: Basic Parameters
C6: Corporate Tax Rate | D6: on profits | E6: Corporate Tax Rate | J6: %
C7: Discount Rate | E7: Discount Rate | J7: %
C8: Administrative Overhead | E8: Administrative Overhead | J8: %
C9: Annual Depreciation | E9: Annual Depreciation | J9: €
B11: Public Funding
C12: One Time Public Funding | E12: Public Funding Initial | J12: €
C13: Annual Public Funding | E13: Public Funding Annual | J13: € / Year
B15: Financing Costs
C16: Debt Capital | E16: Debt Capital | J16: €
C17: Loan Term | E17: Loan Term | J17: Years
C18: Yearly Interest Cost | D18: only interest, not repayment | E18: Yearly Interest Cost | J18: € / Year
B20: Imported Values (Don't change)
C21: Backward Logistic Type | D21: 1 = Direct Pick-up; 2 = Multi Stage w/o sorting; 3 = Multi Stage with Sorting; 4 = Shipment | E21: BL Type | F21: {=IFERROR(_xlfn.IFS(AND('Step 1 - Case Selection'!V43="Company-Led Pickup", 'Step 1 - Case Selection'!V45="Direct Transport"), 1, AND('Step 1 - Case Selection'!V43="Company-Led Pickup", 'Step 1 - Case Selection'!V45="Multi Stage System", 'Step 1 - Case Selection'!V47="No"), 2, AND('Step 1 - Case Selection'!V43="Company-Led Pickup", 'Step 1 - Case Selection'!V45="Multi Stage System", 'Step 1 - Case Selection'!V47="Yes"), 3, 'Step 1 - Case Selection'!V43="Customer-Led Return", 4),0)} -> 0
C22: Forward Logistic Type | D22: 1 = Delivery, 2 = Shipment, 3 = Repair Service Team | E22: FL Type | F22: {=IFERROR(_xlfn.IFS('Step 1 - Case Selection'!V31="Customer-Site Service", 3, 'Step 1 - Case Selection'!V53="Delivery Service", 1, 'Step 1 - Case Selection'!V53="Shipment (e.g. postal)", 2),0)} -> 0
C23: Required Cores per Business Instance (e.g. Production, Repair) | D23: without considering waste; usually 1 | E23: Required Input Cores | F23: =IF('Step 1 - Case Selection'!V33=0, 1, 'Step 1 - Case Selection'!V33) -> 1 | G23: =IF('Step 1 - Case Selection'!V33=0, 1, 'Step 1 - Case Selection'!V33) -> 1 | H23: =IF('Step 1 - Case Selection'!V33=0, 1, 'Step 1 - Case Selection'!V33) -> 1 | I23: =IF('Step 1 - Case Selection'!V33=0, 1, 'Step 1 - Case Selection'!V33) -> 1 | J23: Cores / Product
C24: Share of Useable Cores | D24: for Rental: after the renting period | E24: Core Reuse Rate | F24: =IF('Step 1 - Case Selection'!V35=0, 1, 1-'Step 1 - Case Selection'!V35) -> 1 | G24: =IF('Step 1 - Case Selection'!V35=0, 1, 1-'Step 1 - Case Selection'!V35) -> 1 | H24: =IF('Step 1 - Case Selection'!V35=0, 1, 1-'Step 1 - Case Selection'!V35) -> 1 | I24: =IF('Step 1 - Case Selection'!V35=0, 1, 1-'Step 1 - Case Selection'!V35) -> 1 | J24: %

Sheet Step 2.2 - Data Input (Revenue)
B2: Step 2.2 - Data Input (Revenue)
B3: Instructions If you completed the questionnaire in Step 1, you can now enter the data required to calculate your case. Fields that are greyed out are not relevant to your case. You can now proceed with Revenue related information. You always have to fill out the "Base Case" (Column F). The calculation of additional scenarios (G - I) is optional. Core vs. Product: In the following, the word “core” is frequently used to describe a commodity that is taken back as input material for a CE business case (e.g. a used furniture item). The aim is to distinguish it clearly from a "product" that is an output of production and gets sold.
B4: Category | C4: Name | D4: Remark | E4: Calculator Code | F4: Base Case | G4: Scenario I | H4: Scenario II | I4: Scenario III | J4: Unit
B5: Sales
C6: Price per Product | D6: net price; including all aditional (service) fees passed onto the customer | E6: Price Product | J6: € / Product
C7: Price per Unit of Material | D7: net price; including all aditional (service) fees passed onto the customer | E7: Price Material for Recycling | J7: € / Mass (t OR kg)
C8: Price per Service (e.g. Repair, Refurbishment) | D8: net price; including all aditional (service) fees passed onto the customer | E8: Price Service | J8: € / Product
C9: Sales in Year 1 | E9: Sales Year 1 | J9: Products OR Mass (t OR kg)
C10: Sales in Year 2 | E10: Sales Year 2 | J10: Products OR Mass (t OR kg)
C11: Sales in Year 3 | E11: Sales Year 3 | J11: Products OR Mass (t OR kg)
C12: Sales in Year 4 | E12: Sales Year 4 | J12: Products OR Mass (t OR kg)
C13: Sales in Year 5 | E13: Sales Year 5 | J13: Products OR Mass (t OR kg)
B15: Rental Agreements
C16: Annual Price per Rented Product | D16: net price | E16: Annual Price Rental Contract | J16: € / Contract
C17: Average Duration of Rental Contract | D17: one month corresponds to approx. 0,083 years | E17: Rental Contract Duration | J17: Years
C18: Newly Rented Products in Year 1 | D18: this only concerns new contracts, not ongoing ones | E18: New Rental Contracts Year 1 | J18: Contracts
C19: Newly Rented Products in Year 2 | D19: this only concerns new contracts, not ongoing ones | E19: New Rental Contracts Year 2 | J19: Contracts
C20: Newly Rented Products in Year 3 | D20: this only concerns new contracts, not ongoing ones | E20: New Rental Contracts Year 3 | J20: Contracts
C21: Newly Rented Products in Year 4 | D21: this only concerns new contracts, not ongoing ones | E21: New Rental Contracts Year 4 | J21: Contracts
C22: Newly Rented Products in Year 5 | D22: this only concerns new contracts, not ongoing ones | E22: New Rental Contracts Year 5 | J22: Contracts

Sheet Step 2.3 - Data Input (CapEx)
B2: Step 2.3 - Data Input (CapEx)
B3: Instructions If you completed the questionnaire in Step 1, you can now enter the data required to calculate your case. Fields that are greyed out are not relevant to your case. You can now proceed with CapEx related information. You always have to fill out the "Base Case" (Column F). The calculation of additional scenarios (G - I) is optional. Core vs. Product: In the following, the word “core” is frequently used to describe a commodity that is taken back as input material for a CE business case (e.g. a used furniture item). The aim is to distinguish it clearly from a "product" that is an output of production and gets sold.
B4: Category | C4: Name | D4: Remark | E4: Calculator Code | F4: Base Case | G4: Scenario I | H4: Scenario II | I4: Scenario III | J4: Unit
B5: Assets
C6: Investments in Land or Buildings | E6: Invest Land/Building | J6: €
C7: Investments in Technical Equipment and Machinery | E7: Invest Technical Equipment/Machinery | J7: €
C8: Investments in Office Equipment | E8: Invest Office Equipment | J8: €
C9: Investments in Patents & Licences | E9: Invest Patents/Licences | J9: €
C10: Investments in Certificates | E10: Invest Certificates | J10: €
C11: Investments in Software | E11: Invest Software | J11: €
C12: Investments in Equity Holdings | E12: Invest Equity Holdings | J12: €
B14: Commissioning Costs
C15: Research and Development Costs | E15: Commissioning Costs Research & Development | J15: €
C16: Required Time for Commissioning (Administration) | D16: incl. training and hiring | E16: Commissioning Time Administration | J16: h
C17: Required Time for Commissioning (Working Staff) | D17: incl. training | E17: Commissioning Time Production Staff | J17: h
C18: Additional Commissioning Costs | E18: Additional Commissioning Costs | J18: €

Sheet Step 2.4 - Data Input (OpEx)
B2: Step 2.4 - Data Input (OpEx)
B3: Instructions If you completed the questionnaire in Step 1, you can now enter the data required to calculate your case. Fields that are greyed out are not relevant to your case. You can finish with OpEx related information. You always have to fill out the "Base Case" (Column F). The calculation of additional scenarios (G - I) is optional. Core vs. Product: In the following, the word “core” is frequently used to describe a commodity that is taken back as input material for a CE business case (e.g. a used furniture item). The aim is to distinguish it clearly from a "product" that is an output of production and gets sold.
B4: Category | C4: Name | D4: Remark | E4: Calculator Code | F4: Base Case | G4: Scenario I | H4: Scenario II | I4: Scenario III | J4: Unit
B5: Overarching Values
C6: Average Hourly Rate of non-Administrative Staff | D6: e.g. production | E6: Hourly Rate Production Staff | J6: € / h
C7: Average Hourly Rate Administrative Staff | E7: Hourly Rate Administration | J7: € / h
C8: Average Hourly Machine Costs | D8: wear (and energy if possible) | E8: Hourly Rate Machines | J8: € / h
C9: Average Material per Core | D9: this refers to the average quantity (kg / t) of material that can be derived from a dismantled product and sold | E9: Output Core Material for Recycling | J9: kg / Core OR t / Core
C10: Production or Aquisition Cost of a Product for Rental | E10: Total Cost Rental Product | J10: € / Product
C11: Special Costs not included in the Calculator | E11: Additional Special Costs | J11: € / Year
B13: Trends
C14: Annual Price Trend of Virgin Materials | D14: without considering general inflation | E14: Annual Price Trend Virgin Materials | J14: % / Year
C15: Annual Price Trend of Heating | D15: without considering general inflation | E15: Annual Price Trend Heating | J15: % / Year
C16: Annual Price Trend of Electricity | D16: without considering general inflation | E16: Annual Price Trend Electricity | J16: % / Year
C17: Annual Efficiency Increase of Manual Labour | E17: Annual Efficiency Increase Manual Labour | J17: % / Year
C18: Annual Efficiency Increase of Automated Labour | E18: Annual Efficiency Increase Automated Labour | J18: % / Year
C19: Annual Efficiency Increase of Backward Logistics | E19: Annual Efficiency Increase Backward Logistics | J19: % / Year
C20: Annual Efficiency Increase of Forward Logistics | E20: Annual Efficiency Increase Forward Logistics | J20: % / Year
B22: Energy Costs
C23: Fixed Basic Costs for Heating | D23: if electricity is used for heating, it must not be listed twice here | E23: Base Costs Heating | J23: € / Year
C24: Energy Consumption Heating | E24: Energy Consumption Heating | J24: kWh / Year
C25: Consumption Costs for Heating per k/Wh | E25: Consumption Cost Heating | J25: € / kWh
C26: Fixed Basic Costs for Electricity | D26: if the energy consumption of machines is already included in “Average Hourly Machine Costs”, it must not be entered here again | E26: Base Costs Electricity | J26: € / Year
C27: Energy Consumption Electricity | E27: Energy Consumption Electricity | J27: kWh / Year
C28: Consumption Costs for Electricity per k/Wh | E28: Consumption Cost Electricity | J28: € / kWh
B30: Property Costs
C31: Basic Rent | E31: Basic Rent | J31: € / Year
C32: Property Insurance | E32: Property Insurance | J32: € / Year
C33: Additional Ongoing Property Costs | E33: Additional Ongoing Property Costs | J33: € / Year
B35: Linear Production
C36: Material Cost for Linear Production | E36: Material Cost Linear Production | J36: € / Product
C37: Disposal Cost in Linear Production | E37: Disposal Cost Linear Production | J37: € / Product
C38: Manual Working Hours in the Linear Production Process | E38: Manual Labour Linear Production | J38: h / Product
C39: Automated Working Hours in the Linear Production Process | E39: Automated Labour Linear Production | J39: h / Product
C40: Additional Linear Production Costs | E40: Special Costs Linear Production | J40: € / Year
B42: Backward Logistics: The core is transported from its current location to a processing facility.
C43: Average Pick-up Cost (Flat Rate) | E43: BL Flat Rate | J43: € / Core
C44: Average Distance from Company Site to Pickup Location | D44: if you employ a multi-stage logistics approach, calculate the distance between your core aquisition site and the customer | E44: BL Distance Customer | J44: km
C45: Distance between Core-Acquisition and Processing Site | E45: BL Distance Core-Acquisition Site | J45: km
C46: Transportation Cost per KM | E46: BL KM Cost | J46: € / (km * Core)
...

Sheet Step 3.1 - Base Case Results
B2: CE Business Case Calculator | Q2: =IF('Step 1 - Case Selection'!J12="","",'Step 1 - Case Selection'!J12) -> Test Company
C4: Case name: | G4: =IF('Step 1 - Case Selection'!J14="","",'Step 1 - Case Selection'!J14) -> Test Case | V4: =TODAY() -> 46195
B6: Core KPIs (before / after taxes)
C8: Net Present Value | Q8: Internal Rate of Return | AE8: Dynamic Payback Period
C9: ='Calculation (BC)'!G148 -> 0 | H9: / | I9: ='Calculation (BC)'!G157 -> 0 | Q9: ='Calculation (BC)'!G150 -> #NUM! | V9: / | W9: ='Calculation (BC)'!G159 -> #NUM! | AE9: ="ca. " & ROUND('Calculation (BC)'!G153,1) & " Years" -> #VALUE! | AJ9: / | AK9: ="ca. " & ROUND('Calculation (BC)'!G162,1) & " Years" -> #VALUE!
W12: Margin Breakdown (first year | before taxes)
X14: Ø Total Cost per Sales Unit | AG14: = | AH14: ='Calculation (BC)'!I139/Sales_Year_1 -> #DIV/0!
X15: Net Price per Sales Unit | AG15: = | AH15: =Price_Product+Price_Material_for_Recycling+Price_Service -> 0
X17: Ø Margin per Sales Unit | AG17: = | AH17: =AH15-AH14 -> #DIV/0!
B35: CE Business Case Calculator | Q35: =IF('Step 1 - Case Selection'!J12="","",'Step 1 - Case Selection'!J12) -> Test Company
C37: Case name: | G37: =IF('Step 1 - Case Selection'!J14="","",'Step 1 - Case Selection'!J14) -> Test Case | V37: =TODAY() -> 46195

Sheet Step 3.2 - Scenario Analysis
B2: CE Business Case Calculator | Q2: =IF('Step 1 - Case Selection'!J12="","",'Step 1 - Case Selection'!J12) -> Test Company
C4: Case name: | G4: =IF('Step 1 - Case Selection'!J14="","",'Step 1 - Case Selection'!J14) -> Test Case | V4: =TODAY() -> 46195
AB6: KPI Comparison
AC8: Net Present Value
AC9: Base Case | AJ9: S1 | AL9: S2 | AN9: S3
AC10: ='Calculation (BC)'!G157 -> 0 | AJ10: =IF('Calculation (sI)'!F155 = 0, "/", ('Calculation (sI)'!F155 - 'Calculation (BC)'!G157)/'Calculation (BC)'!G157) -> / | AL10: =IF('Calculation (sII)'!F155 = 0, "/", ('Calculation (sII)'!F155 - 'Calculation (BC)'!G157)/'Calculation (BC)'!G157) -> / | AN10: =IF('Calculation (sIII)'!F155=0,"/",('Calculation (sIII)'!F155-'Calculation (BC)'!G157)/'Calculation (BC)'!G157) -> /
AC12: Internal Rate of Return
AC13: Base Case | AJ13: S1 | AL13: S2 | AN13: S3
AC14: ='Calculation (BC)'!G159 -> #NUM! | AJ14: =IFERROR(('Calculation (sI)'!F157 - 'Calculation (BC)'!G159)/'Calculation (BC)'!G159,"/") -> / | AL14: =IFERROR(('Calculation (sII)'!F157 - 'Calculation (BC)'!G159)/'Calculation (BC)'!G159,"/") -> / | AN14: =IFERROR(('Calculation (sIII)'!F157 - 'Calculation (BC)'!G159)/'Calculation (BC)'!G159,"/") -> /
AC16: Dynamic Payback Period
AC17: Base Case | AJ17: S1 | AL17: S2 | AN17: S3
AC18: ="ca. " & ROUND('Calculation (BC)'!G162,1) & " Years" -> #VALUE! | AJ18: =IFERROR(('Calculation (sI)'!F160 - 'Calculation (BC)'!G162)/'Calculation (BC)'!G162, "/") -> / | AL18: =IFERROR(('Calculation (sII)'!F160 - 'Calculation (BC)'!G162)/'Calculation (BC)'!G162, "/") -> / | AN18: =IFERROR(('Calculation (sIII)'!F160 - 'Calculation (BC)'!G162)/'Calculation (BC)'!G162, "/") -> /

Sheet Calculation (BC)
A1: Type | B1: Category | C1: Sub-Categoy | D1: Auxiliary Calculations | E1: Calculation Formular | F1: Unit | G1: Total Value | H1: Year 0 - Value | I1: Year 1 - Value | J1: Year 2 - Value | K1: Year 3 - Value | L1: Year 4 - Value | M1: Year 5 - Value | N1: After | O1: Auxiliary Column
A2: Income Flows | E2: Total Income Flow (SUM) | F2: € | G2: =SUM(H2:M2) -> 0 | H2: =SUM(H4,H13) -> 0 | I2: =SUM(I4,I13) -> 0 | J2: =SUM(J4,J13) -> 0 | K2: =SUM(K4,K13) -> 0 | L2: =SUM(L4,L13) -> 0 | M2: =SUM(M4,M13) -> 0
B4: Revenue | E4: SUM of all Revenue from Business Activities | F4: € | G4: =SUM(H4:M4) -> 0 | I4: =SUM(I5+I9) -> 0 | J4: =SUM(J5+J9) -> 0 | K4: =SUM(K5+K9) -> 0 | L4: =SUM(L5+L9) -> 0 | M4: =SUM(M5+M9) -> 0
C5: Sales Revenue | E5: SUM of all Sales Revenue from Product, Material and Service Sales | F5: € | G5: =SUM(H5:M5) -> 0 | I5: =SUM(I6:I8) -> 0 | J5: =SUM(J6:J8) -> 0 | K5: =SUM(K6:K8) -> 0 | L5: =SUM(L6:L8) -> 0 | M5: =SUM(M6:M8) -> 0
D6: Product Sales Revenue | E6: Sales_Year_t*Price_Product | F6: € | G6: =SUM(H6:M6) -> 0 | I6: =Sales_Year_1*Price_Product -> 0 | J6: =Sales_Year_2*Price_Product -> 0 | K6: =Sales_Year_3*Price_Product -> 0 | L6: =Sales_Year_4*Price_Product -> 0 | M6: =Sales_Year_5*Price_Product -> 0
D7: Materials for Recycling Sales Revenue | E7: Sales_Year_t*Price_Material_for_Recycling | F7: € | G7: =SUM(H7:M7) -> 0 | I7: =Sales_Year_1*Price_Material_for_Recycling -> 0 | J7: =Sales_Year_2*Price_Material_for_Recycling -> 0 | K7: =Sales_Year_3*Price_Material_for_Recycling -> 0 | L7: =Sales_Year_4*Price_Material_for_Recycling -> 0 | M7: =Sales_Year_5*Price_Material_for_Recycling -> 0
D8: Service Sales Revenue | E8: Sales_Year_t*Price_Service | F8: € | G8: =SUM(H8:M8) -> 0 | I8: =Sales_Year_1*Price_Service -> 0 | J8: =Sales_Year_2*Price_Service -> 0 | K8: =Sales_Year_3*Price_Service -> 0 | L8: =Sales_Year_4*Price_Service -> 0 | M8: =Sales_Year_5*Price_Service -> 0
C9: Rental Agreements Revenue | E9: x10*Annual_Price_Rental_Contract | F9: € | G9: =SUM(H9:M9) -> 0 | I9: =I10*Annual_Price_Rental_Contract -> 0 | J9: =J10*Annual_Price_Rental_Contract -> 0 | K9: =K10*Annual_Price_Rental_Contract -> 0 | L9: =L10*Annual_Price_Rental_Contract -> 0 | M9: =M10*Annual_Price_Rental_Contract -> 0
D10: Active Rental Agreements | E10: IF query of Rental_Contract_Duration followed by SUM of all active Agreements per Year | F10: I | I10: =New_Rental_Contracts_Year_1 -> 0 | J10: =IF(Rental_Contract_Duration>1,New_Rental_Contracts_Year_1+New_Rental_Contracts_Year_2,New_Rental_Contracts_Year_2) -> 0 | K10: {=_xlfn.IFS(Rental_Contract_Duration>2, New_Rental_Contracts_Year_1+New_Rental_Contracts_Year_2+New_Rental_Contracts_Year_3,Rental_Contract_Duration>1,New_Rental_Contracts_Year_2+New_Rental_Contracts_Year_3, Rental_Contract_Duration<=1, New_Rental_Contracts_Year_3)} -> 0 | L10: {=_xlfn.IFS(Rental_Contract_Duration>3, New_Rental_Contracts_Year_1+New_Rental_Contracts_Year_2+New_Rental_Contracts_Year_3+ New_Rental_Contracts_Year_4, Rental_Contract_Duration>2,New_Rental_Contracts_Year_2+New_Rental_Contracts_Year_3+New_Rental_Contracts_Year_4, Rental_Contract_Duration>1, New_Rental_Contracts_Year_3+New_Rental_Contracts_Year_4, Rental_Contract_Duration<=1, New_Rental_Contracts_Year_4)} -> 0 | M10: {=_xlfn.IFS(Rental_Contract_Duration>4, New_Rental_Contracts_Year_1+New_Rental_Contracts_Year_2+New_Rental_Contracts_Year_3+ New_Rental_Contracts_Year_4+New_Rental_Contracts_Year_5, Rental_Contract_Duration>3,New_Rental_Contracts_Year_2+New_Rental_Contracts_Year_3+New_Rental_Contracts_Year_4+New_Rental_Contracts_Year_5, Rental_Contract_Duration>2, New_Rental_Contracts_Year_3+New_Rental_Contracts_Year_4+New_Rental_Contracts_Year_5, Rental_Contract_Duration>1, New_Rental_Contracts_Year_4+New_Rental_Contracts_Year_5,Rental_Contract_Duration<=1, New_Rental_Contracts_Year_5)} -> 0
D11: Residual Value after Period of Review | E11: IF query of Rental_Contract_Duration for years >5 (SUM) | F11: € | G11: =SUM(H11:N11) -> 0 | N11: {=_xlfn.IFS(Rental_Contract_Duration>5, ((Rental_Contract_Duration-5)*New_Rental_Contracts_Year_1+(Rental_Contract_Duration-4)*New_Rental_Contracts_Year_2+(Rental_Contract_Duration-3)*New_Rental_Contracts_Year_3+(Rental_Contract_Duration-2)*New_Rental_Contracts_Year_4+(Rental_Contract_Duration-1)*New_Rental_Contracts_Year_5)*Annual_Price_Rental_Contract, Rental_Contract_Duration>4, ((Rental_Contract_Duration-4)*New_Rental_Contracts_Year_2+(Rental_Contract_Duration-3)*New_Rental_Contracts_Year_3+(Rental_Contract_Duration-2)*New_Rental_Contracts_Year_4+(Rental_Contract_Duration-1)*New_Rental_Contracts_Year_5)*Annual_Price_Rental_Contract, Rental_Contract_Duration>3, ((Rental_Contract_Duration-3)*New_Rental_Contracts_Year_3+(Rental_Contract_Duration-2)*New_Rental_Contracts_Year_4+(Rental_Contract_Duration-1)*New_Rental_Contracts_Year_5)*Annual_Price_Rental_Contract, Rental_Contract_Duration>2,((Rental_Contract_Duration-2)*New_Rental_Contracts_Year_4+(Rental_Contract_Duration-1)*New_Rental_Contracts_Year_5)*Annual_Price_Rental_Contract, Rental_Contract_Duration>1, (Rental_Contract_Duration-1)*New_Rental_Contracts_Year_5*Annual_Price_Rental_Contract, Rental_Contract_Duration<=1, 0)} -> 0
B13: Other positive balance sheet positions | E13: Total other positive positions (SUM) | F13: € | G13: =SUM(H13:M13) -> 0 | H13: =SUM(H14:H15) -> 0 | I13: =SUM(I14:I15) -> 0 | J13: =SUM(J14:J15) -> 0 | K13: =SUM(K14:K15) -> 0 | L13: =SUM(L14:L15) -> 0 | M13: =SUM(M14:M15) -> 0
C14: Loans | E14: Debt_Capital | F14: € | G14: =SUM(H14:M14) -> 0 | H14: =Debt_Capital -> 0
C15: Subsidies | E15: Public_Funding_Initial // Public_Funding_Annual | F15: € | G15: =SUM(H15:M15) -> 0 | H15: =Public_Funding_Initial -> 0 | I15: =Public_Funding_Annual -> 0 | J15: =Public_Funding_Annual -> 0 | K15: =Public_Funding_Annual -> 0 | L15: =Public_Funding_Annual -> 0 | M15: =Public_Funding_Annual -> 0
A17: CapEx | E17: Total CapEx (SUM) | F17: € | G17: =SUM(H17:M17) -> 0 | H17: =SUM(H19+H24) -> 0
B19: Assets | E19: SUM of all CapEX into Assets | G19: =SUM(H19:M19) -> 0 | H19: =SUM(H20:H22) -> 0
C20: Tangible Assets | E20: SUM(Invest_Land_Building+Invest_Technical_Equipment_Machinery+Invest_Office_Equipment) | F20: € | G20: =SUM(H20:M20) -> 0 | H20: =SUM(Invest_Land_Building+Invest_Technical_Equipment_Machinery+Invest_Office_Equipment) -> 0
C21: Intangible Assets | E21: SUM(Invest_Certificates+Invest_Patents_Licences+Invest_Software) | F21: € | G21: =SUM(H21:M21) -> 0 | H21: =SUM(Invest_Certificates+Invest_Patents_Licences+Invest_Software) -> 0
C22: Equity Holdings | E22: Invest_Equity_Holdings | F22: € | G22: =SUM(H22:M22) -> 0 | H22: =Invest_Equity_Holdings -> 0
B24: Comissioning Costs | E24: SUM of all Comissioning Costs | F24: € | G24: =SUM(H24:M24) -> 0 | H24: =SUM(H25:H28) -> 0
C25: Administrative Staff Costs | E25: Commissioning_Time_Administration_Year*Hourly_Rate_Administration | F25: € | G25: =SUM(H25:M25) -> 0 | H25: =Commissioning_Time_Administration*Hourly_Rate_Administration -> 0
C26: Production Staff Costs | E26: Commissioning_Time_Production_Staff_Year*Hourly_Rate_Production_Staff | F26: € | G26: =SUM(H26:M26) -> 0 | H26: =Commissioning_Time_Production_Staff*Hourly_Rate_Production_Staff -> 0
C27: Research and Development | E27: Commissioning_Costs_Research___Development | F27: € | G27: =SUM(H27:M27) -> 0 | H27: =Commissioning_Costs_Research___Development -> 0
C28: Other Comissioning Costs | E28: Additional_Commissioning_Costs_Year | F28: € | G28: =SUM(H28:M28) -> 0 | H28: =Additional_Commissioning_Costs -> 0
A30: OpEx | E30: Total OpEx (SUM) | F30: € | G30: =SUM(H30:M30) -> 0 | I30: =SUM(I32:I33) -> 0 | J30: =SUM(J32:J33) -> 0 | K30: =SUM(K32:K33) -> 0 | L30: =SUM(L32:L33) -> 0 | M30: =SUM(M32:M33) -> 0
B32: Administrative Overhead | E32: x% Mark-Up on other OpEx | F32: € | G32: =SUM(H32:M32) -> 0 | I32: =SUM(I33*Administrative_Overhead) -> 0 | J32: =SUM(J33*Administrative_Overhead) -> 0 | K32: =SUM(K33*Administrative_Overhead) -> 0 | L32: =SUM(L33*Administrative_Overhead) -> 0 | M32: =SUM(M33*Administrative_Overhead) -> 0
D33: Subtotal OpEx | E33: Total OpEx Subtotal (SUM)+Additional_Special_Costs | F33: € | I33: =SUM(I35,I37,I41,I47,I70,I74,I79,I83,I89,I93,I98,I103,I108)+Additional_Special_Costs -> 0 | J33: =SUM(J35,J37,J41,J47,J70,J74,J79,J83,J89,J93,J98,J103,J108)+Additional_Special_Costs -> 0 | K33: =SUM(K35,K37,K41,K47,K70,K74,K79,K83,K89,K93,K98,K103,K108)+Additional_Special_Costs -> 0 | L33: =SUM(L35,L37,L41,L47,L70,L74,L79,L83,L89,L93,L98,L103,L108)+Additional_Special_Costs -> 0 | M33: =SUM(M35,M37,M41,M47,M70,M74,M79,M83,M89,M93,M98,M103,M108)+Additional_Special_Costs -> 0
B35: Property Costs (exc. Energy) | E35: Basic_Rent+Property_Insurance+Additional_Ongoing_Property_Costs | F35: € | G35: =SUM(H35:M35) -> 0 | I35: =Basic_Rent+Property_Insurance+Additional_Ongoing_Property_Costs -> 0 | J35: =Basic_Rent+Property_Insurance+Additional_Ongoing_Property_Costs -> 0 | K35: =Basic_Rent+Property_Insurance+Additional_Ongoing_Property_Costs -> 0 | L35: =Basic_Rent+Property_Insurance+Additional_Ongoing_Property_Costs -> 0 | M35: =Basic_Rent+Property_Insurance+Additional_Ongoing_Property_Costs -> 0
B37: Energy Costs | E37: SUM of all Energy Costs | F37: € | G37: =SUM(H37:M37) -> 0 | I37: =SUM(I38:I39) -> 0 | J37: =SUM(J38:J39) -> 0 | K37: =SUM(K38:K39) -> 0 | L37: =SUM(L38:L39) -> 0 | M37: =SUM(M38:M39) -> 0
C38: Electricity | E38: (Base_Costs_Electricity+Energy_Consumption_Electricity*Consumption_Cost_Electricity)*(1+Annual_Price_Trend_Electricity)^t-1 | F38: € | G38: =SUM(H38:M38) -> 0 | I38: =(Base_Costs_Electricity+Energy_Consumption_Electricity*Consumption_Cost_Electricity)*(1+Annual_Price_Trend_Electricity)^0 -> 0 | J38: =(Base_Costs_Electricity+Energy_Consumption_Electricity*Consumption_Cost_Electricity)*(1+Annual_Price_Trend_Electricity)^1 -> 0 | K38: =(Base_Costs_Electricity+Energy_Consumption_Electricity*Consumption_Cost_Electricity)*(1+Annual_Price_Trend_Electricity)^2 -> 0 | L38: =(Base_Costs_Electricity+Energy_Consumption_Electricity*Consumption_Cost_Electricity)*(1+Annual_Price_Trend_Electricity)^3 -> 0 | M38: =(Base_Costs_Electricity+Energy_Consumption_Electricity*Consumption_Cost_Electricity)*(1+Annual_Price_Trend_Electricity)^4 -> 0
C39: Heating (Oil, Gas) | E39: (Base_Costs_Heating+Energy_Consumption_Heating*Consumption_Cost_Heating)*(1+Annual_Price_Trend_Heating)^t-1 | F39: € | G39: =SUM(H39:M39) -> 0 | I39: =(Base_Costs_Heating+Energy_Consumption_Heating*Consumption_Cost_Heating)*(1+Annual_Price_Trend_Heating)^0 -> 0 | J39: =(Base_Costs_Heating+Energy_Consumption_Heating*Consumption_Cost_Heating)*(1+Annual_Price_Trend_Heating)^1 -> 0 | K39: =(Base_Costs_Heating+Energy_Consumption_Heating*Consumption_Cost_Heating)*(1+Annual_Price_Trend_Heating)^2 -> 0 | L39: =(Base_Costs_Heating+Energy_Consumption_Heating*Consumption_Cost_Heating)*(1+Annual_Price_Trend_Heating)^3 -> 0 | M39: =(Base_Costs_Heating+Energy_Consumption_Heating*Consumption_Cost_Heating)*(1+Annual_Price_Trend_Heating)^4 -> 0
B41: Linear Production Base Case | E41: SUM of Costs in Linear Production + Special_Costs_Linear_Production | F41: € | G41: =SUM(H41:M41) -> 0 | I41: =SUM(I42:I45)+Special_Costs_Linear_Production -> 0 | J41: =SUM(J42:J45)+Special_Costs_Linear_Production -> 0 | K41: =SUM(K42:K45)+Special_Costs_Linear_Production -> 0 | L41: =SUM(L42:L45)+Special_Costs_Linear_Production -> 0 | M41: =SUM(M42:M45)+Special_Costs_Linear_Production -> 0
C42: Material Costs | E42: Sales_Year_t*Material_Cost_Linear_Production*(1+Annual_Price_Trend_Virgin_Materials)^t-1 | F42: € | G42: =SUM(H42:M42) -> 0 | I42: =Sales_Year_1*Material_Cost_Linear_Production*(1+Annual_Price_Trend_Virgin_Materials)^0 -> 0 | J42: =Sales_Year_2*Material_Cost_Linear_Production*(1+Annual_Price_Trend_Virgin_Materials)^1 -> 0 | K42: =Sales_Year_3*Material_Cost_Linear_Production*(1+Annual_Price_Trend_Virgin_Materials)^2 -> 0 | L42: =Sales_Year_4*Material_Cost_Linear_Production*(1+Annual_Price_Trend_Virgin_Materials)^3 -> 0 | M42: =Sales_Year_5*Material_Cost_Linear_Production*(1+Annual_Price_Trend_Virgin_Materials)^4 -> 0
C43: Disposal Costs | E43: Sales_Year_t*Disposal_Cost_Linear_Production | F43: € | G43: =SUM(H43:M43) -> 0 | I43: =Sales_Year_1*Disposal_Cost_Linear_Production -> 0 | J43: =Sales_Year_2*Disposal_Cost_Linear_Production -> 0 | K43: =Sales_Year_3*Disposal_Cost_Linear_Production -> 0 | L43: =Sales_Year_4*Disposal_Cost_Linear_Production -> 0 | M43: =Sales_Year_5*Disposal_Cost_Linear_Production -> 0
C44: Personel Costs | E44: Sales_Year_t*(Manual_Labour_Linear_Production*Hourly_Rate_Production_Staff)*(1-Annual_Efficiency_Increase_Manual_Labour)^t-1 | F44: € | G44: =SUM(H44:M44) -> 0 | I44: =Sales_Year_1*(Manual_Labour_Linear_Production*Hourly_Rate_Production_Staff)*(1-Annual_Efficiency_Increase_Manual_Labour)^0 -> 0 | J44: =Sales_Year_2*(Manual_Labour_Linear_Production*Hourly_Rate_Production_Staff)*(1-Annual_Efficiency_Increase_Manual_Labour)^1 -> 0 | K44: =Sales_Year_3*(Manual_Labour_Linear_Production*Hourly_Rate_Production_Staff)*(1-Annual_Efficiency_Increase_Manual_Labour)^2 -> 0 | L44: =Sales_Year_4*(Manual_Labour_Linear_Production*Hourly_Rate_Production_Staff)*(1-Annual_Efficiency_Increase_Manual_Labour)^3 -> 0 | M44: =Sales_Year_5*(Manual_Labour_Linear_Production*Hourly_Rate_Production_Staff)*(1-Annual_Efficiency_Increase_Manual_Labour)^4 -> 0
C45: Machine Costs | E45: Sales_Year_t*(Automated_Labour_Total_Linear_Production_Process*Hourly_Rate_Machines)*(1-Annual_Efficiency_Increase_Automated_Labour)^t-1 | F45: € | G45: =SUM(H45:M45) -> 0 | I45: =Sales_Year_1*(Automated_Labour_Linear_Production*Hourly_Rate_Machines)*(1-Annual_Efficiency_Increase_Automated_Labour)^0 -> 0 | J45: =Sales_Year_2*(Automated_Labour_Linear_Production*Hourly_Rate_Machines)*(1-Annual_Efficiency_Increase_Automated_Labour)^1 -> 0 | K45: =Sales_Year_3*(Automated_Labour_Linear_Production*Hourly_Rate_Machines)*(1-Annual_Efficiency_Increase_Automated_Labour)^2 -> 0 | L45: =Sales_Year_4*(Automated_Labour_Linear_Production*Hourly_Rate_Machines)*(1-Annual_Efficiency_Increase_Automated_Labour)^3 -> 0 | M45: =Sales_Year_5*(Automated_Labour_Linear_Production*Hourly_Rate_Machines)*(1-Annual_Efficiency_Increase_Automated_Labour)^4 -> 0
B47: Backward Logistics | E47: IF query on Billing Type followed by SUM of Costs for Backward Logistic + Core Premium + Special_Costs_Backward_Logistic | F47: € | G47: =SUM(H47:M47) -> 0 | I47: =IF('Step 1 - Case Selection'!V41="as a Flat Rate",I48+I54+Special_Costs_Backward_Logistics,SUM(I48,I55,I61,I68)+Special_Costs_Backward_Logistics) -> 0 | J47: =IF('Step 1 - Case Selection'!V41="as a Flat Rate",J48+J54+Special_Costs_Backward_Logistics,SUM(J48,J55,J61,J68)+Special_Costs_Backward_Logistics) -> 0 | K47: =IF('Step 1 - Case Selection'!V41="as a Flat Rate",K48+K54+Special_Costs_Backward_Logistics,SUM(K48,K55,K61,K68)+Special_Costs_Backward_Logistics) -> 0 | L47: =IF('Step 1 - Case Selection'!V41="as a Flat Rate",L48+L54+Special_Costs_Backward_Logistics,SUM(L48,L55,L61,L68)+Special_Costs_Backward_Logistics) -> 0 | M47: =IF('Step 1 - Case Selection'!V41="as a Flat Rate",M48+M54+Special_Costs_Backward_Logistics,SUM(M48,M55,M61,M68)+Special_Costs_Backward_Logistics) -> 0
D48: Core Premiums | E48: Core_Premium*(x49+x51) | F48: € | G48: =SUM(H48:M48) -> 0 | I48: =Core_Premium*(I49+I51) -> 0 | J48: =Core_Premium*(J49+J51) -> 0 | K48: =Core_Premium*(K49+K51) -> 0 | L48: =Core_Premium*(L49+L51) -> 0 | M48: =Core_Premium*(M49+M51) -> 0
D49: Required Cores Product Basis (before Sorting) | E49: ROUND(IF('Step 1 - Case Selection'!V27<>"Recycle"; Sales_Year_t/Core_Reuse_Rate*Required_Input_Cores);0) | F49: I | I49: =ROUND(IF('Step 1 - Case Selection'!V27<>"Recycle", Sales_Year_1/Core_Reuse_Rate*Required_Input_Cores),0) -> 0 | J49: =ROUND(IF('Step 1 - Case Selection'!V27<>"Recycle", Sales_Year_2/Core_Reuse_Rate*Required_Input_Cores),0) -> 0 | K49: =ROUND(IF('Step 1 - Case Selection'!V27<>"Recycle", Sales_Year_3/Core_Reuse_Rate*Required_Input_Cores),0) -> 0 | L49: =ROUND(IF('Step 1 - Case Selection'!V27<>"Recycle", Sales_Year_4/Core_Reuse_Rate*Required_Input_Cores),0) -> 0 | M49: =ROUND(IF('Step 1 - Case Selection'!V27<>"Recycle", Sales_Year_5/Core_Reuse_Rate*Required_Input_Cores),0) -> 0
D50: Required Cores Product Basis (after Sorting) | E50: ROUND(IF('Step 1 - Case Selection'!V27<>"Recycle"; Sales_Year_t*Required_Input_Cores);0) | F50: I | I50: =ROUND(IF('Step 1 - Case Selection'!V27<>"Recycle", Sales_Year_1*Required_Input_Cores),0) -> 0 | J50: =ROUND(IF('Step 1 - Case Selection'!V27<>"Recycle", Sales_Year_2*Required_Input_Cores),0) -> 0 | K50: =ROUND(IF('Step 1 - Case Selection'!V27<>"Recycle", Sales_Year_3*Required_Input_Cores),0) -> 0 | L50: =ROUND(IF('Step 1 - Case Selection'!V27<>"Recycle", Sales_Year_4*Required_Input_Cores),0) -> 0 | M50: =ROUND(IF('Step 1 - Case Selection'!V27<>"Recycle", Sales_Year_5*Required_Input_Cores),0) -> 0
D51: Required Cores Material Basis (before Sorting) | E51: ROUND(IF('Step 1 - Case Selection'!V27="Recycle"; Sales_Year_t/Output_Core_Material_for_Recycling/Core_Reuse_Rate; 0);0) | F51: I | I51: =ROUND(IF('Step 1 - Case Selection'!V27="Recycle", Sales_Year_1/Output_Core_Material_for_Recycling/Core_Reuse_Rate, 0),0) -> 0 | J51: =ROUND(IF('Step 1 - Case Selection'!V27="Recycle", Sales_Year_2/Output_Core_Material_for_Recycling/Core_Reuse_Rate, 0),0) -> 0 | K51: =ROUND(IF('Step 1 - Case Selection'!V27="Recycle", Sales_Year_3/Output_Core_Material_for_Recycling/Core_Reuse_Rate, 0),0) -> 0 | L51: =ROUND(IF('Step 1 - Case Selection'!V27="Recycle", Sales_Year_4/Output_Core_Material_for_Recycling/Core_Reuse_Rate, 0),0) -> 0 | M51: =ROUND(IF('Step 1 - Case Selection'!V27="Recycle", Sales_Year_5/Output_Core_Material_for_Recycling/Core_Reuse_Rate, 0),0) -> 0
...

Sheet Calculation (sI)
A1: Type | B1: Category | C1: Sub-Categoy | D1: Auxiliary Calculations | E1: Unit | F1: Total Value | G1: Year 0 - Value | H1: Year 1 - Value | I1: Year 2 - Value | J1: Year 3 - Value | K1: Year 4 - Value | L1: Year 5 - Value | M1: After | N1: Auxiliary Column
A2: Income Flows | E2: € | F2: =SUM(G2:L2) -> 0 | G2: =SUM(G4,G13) -> 0 | H2: =SUM(H4,H13) -> 0 | I2: =SUM(I4,I13) -> 0 | J2: =SUM(J4,J13) -> 0 | K2: =SUM(K4,K13) -> 0 | L2: =SUM(L4,L13) -> 0
B4: Revenue | E4: € | F4: =SUM(G4:L4) -> 0 | H4: =SUM(H5+H9) -> 0 | I4: =SUM(I5+I9) -> 0 | J4: =SUM(J5+J9) -> 0 | K4: =SUM(K5+K9) -> 0 | L4: =SUM(L5+L9) -> 0
C5: Sales Revenue | E5: € | F5: =SUM(G5:L5) -> 0 | H5: =SUM(H6:H8) -> 0 | I5: =SUM(I6:I8) -> 0 | J5: =SUM(J6:J8) -> 0 | K5: =SUM(K6:K8) -> 0 | L5: =SUM(L6:L8) -> 0
D6: Product Sales Revenue | E6: € | F6: =SUM(G6:L6) -> 0 | H6: ='Step 2.2 - Data Input (Revenue)'!G9*'Step 2.2 - Data Input (Revenue)'!G6 -> 0 | I6: ='Step 2.2 - Data Input (Revenue)'!G10*'Step 2.2 - Data Input (Revenue)'!G6 -> 0 | J6: ='Step 2.2 - Data Input (Revenue)'!G11*'Step 2.2 - Data Input (Revenue)'!G6 -> 0 | K6: ='Step 2.2 - Data Input (Revenue)'!G12*'Step 2.2 - Data Input (Revenue)'!G6 -> 0 | L6: ='Step 2.2 - Data Input (Revenue)'!G13*'Step 2.2 - Data Input (Revenue)'!G6 -> 0
D7: Materials for Recycling Sales Revenue | E7: € | F7: =SUM(G7:L7) -> 0 | H7: ='Step 2.2 - Data Input (Revenue)'!G9*'Step 2.2 - Data Input (Revenue)'!G7 -> 0 | I7: ='Step 2.2 - Data Input (Revenue)'!G10*'Step 2.2 - Data Input (Revenue)'!G7 -> 0 | J7: ='Step 2.2 - Data Input (Revenue)'!G11*'Step 2.2 - Data Input (Revenue)'!G7 -> 0 | K7: ='Step 2.2 - Data Input (Revenue)'!G12*'Step 2.2 - Data Input (Revenue)'!G7 -> 0 | L7: ='Step 2.2 - Data Input (Revenue)'!G13*'Step 2.2 - Data Input (Revenue)'!G7 -> 0
D8: Service Sales Revenue | E8: € | F8: =SUM(G8:L8) -> 0 | H8: ='Step 2.2 - Data Input (Revenue)'!G9*'Step 2.2 - Data Input (Revenue)'!G8 -> 0 | I8: ='Step 2.2 - Data Input (Revenue)'!G10*'Step 2.2 - Data Input (Revenue)'!G8 -> 0 | J8: ='Step 2.2 - Data Input (Revenue)'!G11*'Step 2.2 - Data Input (Revenue)'!G8 -> 0 | K8: ='Step 2.2 - Data Input (Revenue)'!G12*'Step 2.2 - Data Input (Revenue)'!G8 -> 0 | L8: ='Step 2.2 - Data Input (Revenue)'!G13*'Step 2.2 - Data Input (Revenue)'!G8 -> 0
C9: Rental Agreements Revenue | E9: € | F9: =SUM(G9:L9) -> 0 | H9: =H10*'Step 2.2 - Data Input (Revenue)'!G16 -> 0 | I9: =I10*'Step 2.2 - Data Input (Revenue)'!G16 -> 0 | J9: =J10*'Step 2.2 - Data Input (Revenue)'!G16 -> 0 | K9: =K10*'Step 2.2 - Data Input (Revenue)'!G16 -> 0 | L9: =L10*'Step 2.2 - Data Input (Revenue)'!G16 -> 0
D10: Active Rental Agreements | E10: I | H10: ='Step 2.2 - Data Input (Revenue)'!G18 -> 0 | I10: =IF('Step 2.2 - Data Input (Revenue)'!G17>1,'Step 2.2 - Data Input (Revenue)'!G18+'Step 2.2 - Data Input (Revenue)'!G19,'Step 2.2 - Data Input (Revenue)'!G19) -> 0 | J10: {=_xlfn.IFS('Step 2.2 - Data Input (Revenue)'!G17>2, 'Step 2.2 - Data Input (Revenue)'!G18+'Step 2.2 - Data Input (Revenue)'!G19+'Step 2.2 - Data Input (Revenue)'!G20,'Step 2.2 - Data Input (Revenue)'!G17>1,'Step 2.2 - Data Input (Revenue)'!G19+'Step 2.2 - Data Input (Revenue)'!G20, 'Step 2.2 - Data Input (Revenue)'!G17<=1, 'Step 2.2 - Data Input (Revenue)'!G20)} -> 0 | K10: {=_xlfn.IFS('Step 2.2 - Data Input (Revenue)'!G17>3, 'Step 2.2 - Data Input (Revenue)'!G18+'Step 2.2 - Data Input (Revenue)'!G19+'Step 2.2 - Data Input (Revenue)'!G20+ 'Step 2.2 - Data Input (Revenue)'!G21, 'Step 2.2 - Data Input (Revenue)'!G17>2,'Step 2.2 - Data Input (Revenue)'!G19+'Step 2.2 - Data Input (Revenue)'!G20+'Step 2.2 - Data Input (Revenue)'!G21, 'Step 2.2 - Data Input (Revenue)'!G17>1, 'Step 2.2 - Data Input (Revenue)'!G20+'Step 2.2 - Data Input (Revenue)'!G21, 'Step 2.2 - Data Input (Revenue)'!G17<=1, 'Step 2.2 - Data Input (Revenue)'!G21)} -> 0 | L10: {=_xlfn.IFS('Step 2.2 - Data Input (Revenue)'!G17>4, 'Step 2.2 - Data Input (Revenue)'!G18+'Step 2.2 - Data Input (Revenue)'!G19+'Step 2.2 - Data Input (Revenue)'!G20+ 'Step 2.2 - Data Input (Revenue)'!G21+'Step 2.2 - Data Input (Revenue)'!G22, 'Step 2.2 - Data Input (Revenue)'!G17>3,'Step 2.2 - Data Input (Revenue)'!G19+'Step 2.2 - Data Input (Revenue)'!G20+'Step 2.2 - Data Input (Revenue)'!G21+'Step 2.2 - Data Input (Revenue)'!G22, 'Step 2.2 - Data Input (Revenue)'!G17>2, 'Step 2.2 - Data Input (Revenue)'!G20+'Step 2.2 - Data Input (Revenue)'!G21+'Step 2.2 - Data Input (Revenue)'!G22, 'Step 2.2 - Data Input (Revenue)'!G17>1, 'Step 2.2 - Data Input (Revenue)'!G21+'Step 2.2 - Data Input (Revenue)'!G22,'Step 2.2 - Data Input (Revenue)'!G17<=1, 'Step 2.2 - Data Input (Revenue)'!G22)} -> 0
D11: Residual Value after Period of Review | E11: € | F11: =SUM(G11:M11) -> 0 | M11: {=_xlfn.IFS('Step 2.2 - Data Input (Revenue)'!G17>5, (('Step 2.2 - Data Input (Revenue)'!G17-5)*'Step 2.2 - Data Input (Revenue)'!G18+('Step 2.2 - Data Input (Revenue)'!G17-4)*'Step 2.2 - Data Input (Revenue)'!G19+('Step 2.2 - Data Input (Revenue)'!G17-3)*'Step 2.2 - Data Input (Revenue)'!G20+('Step 2.2 - Data Input (Revenue)'!G17-2)*'Step 2.2 - Data Input (Revenue)'!G21+('Step 2.2 - Data Input (Revenue)'!G17-1)*'Step 2.2 - Data Input (Revenue)'!G22)*Annual_Price_Rental_Contract, 'Step 2.2 - Data Input (Revenue)'!G17>4, (('Step 2.2 - Data Input (Revenue)'!G17-4)*'Step 2.2 - Data Input (Revenue)'!G19+('Step 2.2 - Data Input (Revenue)'!G17-3)*'Step 2.2 - Data Input (Revenue)'!G20+('Step 2.2 - Data Input (Revenue)'!G17-2)*'Step 2.2 - Data Input (Revenue)'!G21+('Step 2.2 - Data Input (Revenue)'!G17-1)*'Step 2.2 - Data Input (Revenue)'!G22)*Annual_Price_Rental_Contract, 'Step 2.2 - Data Input (Revenue)'!G17>3, (('Step 2.2 - Data Input (Revenue)'!G17-3)*'Step 2.2 - Data Input (Revenue)'!G20+('Step 2.2 - Data Input (Revenue)'!G17-2)*'Step 2.2 - Data Input (Revenue)'!G21+('Step 2.2 - Data Input (Revenue)'!G17-1)*'Step 2.2 - Data Input (Revenue)'!G22)*Annual_Price_Rental_Contract, 'Step 2.2 - Data Input (Revenue)'!G17>2,(('Step 2.2 - Data Input (Revenue)'!G17-2)*'Step 2.2 - Data Input (Revenue)'!G21+('Step 2.2 - Data Input (Revenue)'!G17-1)*'Step 2.2 - Data Input (Revenue)'!G22)*Annual_Price_Rental_Contract, 'Step 2.2 - Data Input (Revenue)'!G17>1, ('Step 2.2 - Data Input (Revenue)'!G17-1)*'Step 2.2 - Data Input (Revenue)'!G22*Annual_Price_Rental_Contract, 'Step 2.2 - Data Input (Revenue)'!G17<=1, 0)} -> 0
B13: Other positive balance sheet positions | E13: € | F13: =SUM(G13:L13) -> 0 | G13: =SUM(G14:G15) -> 0 | H13: =SUM(H14:H15) -> 0 | I13: =SUM(I14:I15) -> 0 | J13: =SUM(J14:J15) -> 0 | K13: =SUM(K14:K15) -> 0 | L13: =SUM(L14:L15) -> 0
C14: Loans | E14: € | F14: =SUM(G14:L14) -> 0 | G14: ='Step 2.1 - Data Input (General)'!G16 -> 0
C15: Subsidies | E15: € | F15: =SUM(G15:L15) -> 0 | G15: ='Step 2.1 - Data Input (General)'!G12 -> 0 | H15: ='Step 2.1 - Data Input (General)'!G13 -> 0 | I15: ='Step 2.1 - Data Input (General)'!G13 -> 0 | J15: ='Step 2.1 - Data Input (General)'!G13 -> 0 | K15: ='Step 2.1 - Data Input (General)'!G13 -> 0 | L15: ='Step 2.1 - Data Input (General)'!G13 -> 0
A17: CapEx | E17: € | F17: =SUM(G17:L17) -> 0 | G17: =SUM(G19+G24) -> 0
B19: Assets | F19: =SUM(G19:L19) -> 0 | G19: =SUM(G20:G22) -> 0
C20: Tangible Assets | E20: € | F20: =SUM(G20:L20) -> 0 | G20: =SUM('Step 2.3 - Data Input (CapEx)'!G6+'Step 2.3 - Data Input (CapEx)'!G7+'Step 2.3 - Data Input (CapEx)'!G8) -> 0
C21: Intangible Assets | E21: € | F21: =SUM(G21:L21) -> 0 | G21: =SUM('Step 2.3 - Data Input (CapEx)'!G9+'Step 2.3 - Data Input (CapEx)'!G10+'Step 2.3 - Data Input (CapEx)'!G11) -> 0
C22: Equity Holdings | E22: € | F22: =SUM(G22:L22) -> 0 | G22: ='Step 2.3 - Data Input (CapEx)'!G12 -> 0
B24: Comissioning Costs | E24: € | F24: =SUM(G24:L24) -> 0 | G24: =SUM(G25:G28) -> 0
C25: Administrative Staff Costs | E25: € | F25: =SUM(G25:L25) -> 0 | G25: ='Step 2.3 - Data Input (CapEx)'!G16*'Step 2.4 - Data Input (OpEx)'!G7 -> 0
C26: Production Staff Costs | E26: € | F26: =SUM(G26:L26) -> 0 | G26: ='Step 2.3 - Data Input (CapEx)'!G17*'Step 2.4 - Data Input (OpEx)'!G6 -> 0
C27: Research and Development | E27: € | F27: =SUM(G27:L27) -> 0 | G27: ='Step 2.3 - Data Input (CapEx)'!G15 -> 0
C28: Other Comissioning Costs | E28: € | F28: =SUM(G28:L28) -> 0 | G28: ='Step 2.3 - Data Input (CapEx)'!G18 -> 0
A30: OpEx | E30: € | F30: =SUM(G30:L30) -> 0 | H30: =SUM(H32:H33) -> 0 | I30: =SUM(I32:I33) -> 0 | J30: =SUM(J32:J33) -> 0 | K30: =SUM(K32:K33) -> 0 | L30: =SUM(L32:L33) -> 0
B32: Administrative Overhead | E32: € | F32: =SUM(G32:L32) -> 0 | H32: =SUM(H33*'Step 2.1 - Data Input (General)'!G8) -> 0 | I32: =SUM(I33*'Step 2.1 - Data Input (General)'!G8) -> 0 | J32: =SUM(J33*'Step 2.1 - Data Input (General)'!G8) -> 0 | K32: =SUM(K33*'Step 2.1 - Data Input (General)'!G8) -> 0 | L32: =SUM(L33*'Step 2.1 - Data Input (General)'!G8) -> 0
D33: Subtotal OpEx | E33: € | H33: =SUM(H35,H37,H41,H47,H70,H74,H79,H83,H89,H93,H98,H103,H108)+'Step 2.4 - Data Input (OpEx)'!G11 -> 0 | I33: =SUM(I35,I37,I41,I47,I70,I74,I79,I83,I89,I93,I98,I103,I108)+'Step 2.4 - Data Input (OpEx)'!G11 -> 0 | J33: =SUM(J35,J37,J41,J47,J70,J74,J79,J83,J89,J93,J98,J103,J108)+'Step 2.4 - Data Input (OpEx)'!G11 -> 0 | K33: =SUM(K35,K37,K41,K47,K70,K74,K79,K83,K89,K93,K98,K103,K108)+'Step 2.4 - Data Input (OpEx)'!G11 -> 0 | L33: =SUM(L35,L37,L41,L47,L70,L74,L79,L83,L89,L93,L98,L103,L108)+'Step 2.4 - Data Input (OpEx)'!G11 -> 0
B35: Property Costs (exc. Energy) | E35: € | F35: =SUM(G35:L35) -> 0 | H35: ='Step 2.4 - Data Input (OpEx)'!G31+'Step 2.4 - Data Input (OpEx)'!G32+'Step 2.4 - Data Input (OpEx)'!G33 -> 0 | I35: ='Step 2.4 - Data Input (OpEx)'!G31+'Step 2.4 - Data Input (OpEx)'!G32+'Step 2.4 - Data Input (OpEx)'!G33 -> 0 | J35: ='Step 2.4 - Data Input (OpEx)'!G31+'Step 2.4 - Data Input (OpEx)'!G32+'Step 2.4 - Data Input (OpEx)'!G33 -> 0 | K35: ='Step 2.4 - Data Input (OpEx)'!G31+'Step 2.4 - Data Input (OpEx)'!G32+'Step 2.4 - Data Input (OpEx)'!G33 -> 0 | L35: ='Step 2.4 - Data Input (OpEx)'!G31+'Step 2.4 - Data Input (OpEx)'!G32+'Step 2.4 - Data Input (OpEx)'!G33 -> 0
B37: Energy Costs | E37: € | F37: =SUM(G37:L37) -> 0 | H37: =SUM(H38:H39) -> 0 | I37: =SUM(I38:I39) -> 0 | J37: =SUM(J38:J39) -> 0 | K37: =SUM(K38:K39) -> 0 | L37: =SUM(L38:L39) -> 0
C38: Electricity | E38: € | F38: =SUM(G38:L38) -> 0 | H38: =('Step 2.4 - Data Input (OpEx)'!G26+'Step 2.4 - Data Input (OpEx)'!G27*'Step 2.4 - Data Input (OpEx)'!G28)*(1+'Step 2.4 - Data Input (OpEx)'!G16)^0 -> 0 | I38: =('Step 2.4 - Data Input (OpEx)'!G26+'Step 2.4 - Data Input (OpEx)'!G27*'Step 2.4 - Data Input (OpEx)'!G28)*(1+'Step 2.4 - Data Input (OpEx)'!G16)^1 -> 0 | J38: =('Step 2.4 - Data Input (OpEx)'!G26+'Step 2.4 - Data Input (OpEx)'!G27*'Step 2.4 - Data Input (OpEx)'!G28)*(1+'Step 2.4 - Data Input (OpEx)'!G16)^2 -> 0 | K38: =('Step 2.4 - Data Input (OpEx)'!G26+'Step 2.4 - Data Input (OpEx)'!G27*'Step 2.4 - Data Input (OpEx)'!G28)*(1+'Step 2.4 - Data Input (OpEx)'!G16)^3 -> 0 | L38: =('Step 2.4 - Data Input (OpEx)'!G26+'Step 2.4 - Data Input (OpEx)'!G27*'Step 2.4 - Data Input (OpEx)'!G28)*(1+'Step 2.4 - Data Input (OpEx)'!G16)^4 -> 0
C39: Heating (Oil, Gas) | E39: € | F39: =SUM(G39:L39) -> 0 | H39: =('Step 2.4 - Data Input (OpEx)'!G23+'Step 2.4 - Data Input (OpEx)'!G24*'Step 2.4 - Data Input (OpEx)'!G25)*(1+'Step 2.4 - Data Input (OpEx)'!G15)^0 -> 0 | I39: =('Step 2.4 - Data Input (OpEx)'!G23+'Step 2.4 - Data Input (OpEx)'!G24*'Step 2.4 - Data Input (OpEx)'!G25)*(1+'Step 2.4 - Data Input (OpEx)'!G15)^1 -> 0 | J39: =('Step 2.4 - Data Input (OpEx)'!G23+'Step 2.4 - Data Input (OpEx)'!G24*'Step 2.4 - Data Input (OpEx)'!G25)*(1+'Step 2.4 - Data Input (OpEx)'!G15)^2 -> 0 | K39: =('Step 2.4 - Data Input (OpEx)'!G23+'Step 2.4 - Data Input (OpEx)'!G24*'Step 2.4 - Data Input (OpEx)'!G25)*(1+'Step 2.4 - Data Input (OpEx)'!G15)^3 -> 0 | L39: =('Step 2.4 - Data Input (OpEx)'!G23+'Step 2.4 - Data Input (OpEx)'!G24*'Step 2.4 - Data Input (OpEx)'!G25)*(1+'Step 2.4 - Data Input (OpEx)'!G15)^4 -> 0
B41: Linear Production Base Case | E41: € | F41: =SUM(G41:L41) -> 0 | H41: =SUM(H42:H45)+'Step 2.4 - Data Input (OpEx)'!G40 -> 0 | I41: =SUM(I42:I45)+'Step 2.4 - Data Input (OpEx)'!G40 -> 0 | J41: =SUM(J42:J45)+'Step 2.4 - Data Input (OpEx)'!G40 -> 0 | K41: =SUM(K42:K45)+'Step 2.4 - Data Input (OpEx)'!G40 -> 0 | L41: =SUM(L42:L45)+'Step 2.4 - Data Input (OpEx)'!G40 -> 0
C42: Material Costs | E42: € | F42: =SUM(G42:L42) -> 0 | H42: ='Step 2.2 - Data Input (Revenue)'!G9*'Step 2.4 - Data Input (OpEx)'!G36*(1+'Step 2.4 - Data Input (OpEx)'!G14)^0 -> 0 | I42: ='Step 2.2 - Data Input (Revenue)'!G10*'Step 2.4 - Data Input (OpEx)'!G36*(1+'Step 2.4 - Data Input (OpEx)'!G14)^1 -> 0 | J42: ='Step 2.2 - Data Input (Revenue)'!G11*'Step 2.4 - Data Input (OpEx)'!G36*(1+'Step 2.4 - Data Input (OpEx)'!G14)^2 -> 0 | K42: ='Step 2.2 - Data Input (Revenue)'!G12*'Step 2.4 - Data Input (OpEx)'!G36*(1+'Step 2.4 - Data Input (OpEx)'!G14)^3 -> 0 | L42: ='Step 2.2 - Data Input (Revenue)'!G13*'Step 2.4 - Data Input (OpEx)'!G36*(1+'Step 2.4 - Data Input (OpEx)'!G14)^4 -> 0
C43: Disposal Costs | E43: € | F43: =SUM(G43:L43) -> 0 | H43: ='Step 2.2 - Data Input (Revenue)'!G9*'Step 2.4 - Data Input (OpEx)'!G37 -> 0 | I43: ='Step 2.2 - Data Input (Revenue)'!G10*'Step 2.4 - Data Input (OpEx)'!G37 -> 0 | J43: ='Step 2.2 - Data Input (Revenue)'!G11*'Step 2.4 - Data Input (OpEx)'!G37 -> 0 | K43: ='Step 2.2 - Data Input (Revenue)'!G12*'Step 2.4 - Data Input (OpEx)'!G37 -> 0 | L43: ='Step 2.2 - Data Input (Revenue)'!G13*'Step 2.4 - Data Input (OpEx)'!G37 -> 0
C44: Personel Costs | E44: € | F44: =SUM(G44:L44) -> 0 | H44: ='Step 2.2 - Data Input (Revenue)'!G9*('Step 2.4 - Data Input (OpEx)'!G38*'Step 2.4 - Data Input (OpEx)'!G6)*(1-'Step 2.4 - Data Input (OpEx)'!G17)^0 -> 0 | I44: ='Step 2.2 - Data Input (Revenue)'!G10*('Step 2.4 - Data Input (OpEx)'!G38*'Step 2.4 - Data Input (OpEx)'!G6)*(1-'Step 2.4 - Data Input (OpEx)'!G17)^1 -> 0 | J44: ='Step 2.2 - Data Input (Revenue)'!G11*('Step 2.4 - Data Input (OpEx)'!G38*'Step 2.4 - Data Input (OpEx)'!G6)*(1-'Step 2.4 - Data Input (OpEx)'!G17)^2 -> 0 | K44: ='Step 2.2 - Data Input (Revenue)'!G12*('Step 2.4 - Data Input (OpEx)'!G38*'Step 2.4 - Data Input (OpEx)'!G6)*(1-'Step 2.4 - Data Input (OpEx)'!G17)^3 -> 0 | L44: ='Step 2.2 - Data Input (Revenue)'!G13*('Step 2.4 - Data Input (OpEx)'!G38*'Step 2.4 - Data Input (OpEx)'!G6)*(1-'Step 2.4 - Data Input (OpEx)'!G17)^4 -> 0
C45: Machine Costs | E45: € | F45: =SUM(G45:L45) -> 0 | H45: ='Step 2.2 - Data Input (Revenue)'!G9*('Step 2.4 - Data Input (OpEx)'!G39*'Step 2.4 - Data Input (OpEx)'!G8)*(1-'Step 2.4 - Data Input (OpEx)'!G18)^0 -> 0 | I45: ='Step 2.2 - Data Input (Revenue)'!G10*('Step 2.4 - Data Input (OpEx)'!G39*'Step 2.4 - Data Input (OpEx)'!G8)*(1-'Step 2.4 - Data Input (OpEx)'!G18)^1 -> 0 | J45: ='Step 2.2 - Data Input (Revenue)'!G11*('Step 2.4 - Data Input (OpEx)'!G39*'Step 2.4 - Data Input (OpEx)'!G8)*(1-'Step 2.4 - Data Input (OpEx)'!G18)^2 -> 0 | K45: ='Step 2.2 - Data Input (Revenue)'!G12*('Step 2.4 - Data Input (OpEx)'!G39*'Step 2.4 - Data Input (OpEx)'!G8)*(1-'Step 2.4 - Data Input (OpEx)'!G18)^3 -> 0 | L45: ='Step 2.2 - Data Input (Revenue)'!G13*('Step 2.4 - Data Input (OpEx)'!G39*'Step 2.4 - Data Input (OpEx)'!G8)*(1-'Step 2.4 - Data Input (OpEx)'!G18)^4 -> 0
B47: Backward Logistics | E47: € | F47: =SUM(G47:L47) -> 0 | H47: =IF('Step 1 - Case Selection'!V41="as a Flat Rate",H48+H54+Special_Costs_Backward_Logistics,SUM(H48,H55,H61,H68)+Special_Costs_Backward_Logistics) -> 0 | I47: =IF('Step 1 - Case Selection'!V41="as a Flat Rate",I48+I54+Special_Costs_Backward_Logistics,SUM(I48,I55,I61,I68)+Special_Costs_Backward_Logistics) -> 0 | J47: =IF('Step 1 - Case Selection'!V41="as a Flat Rate",J48+J54+Special_Costs_Backward_Logistics,SUM(J48,J55,J61,J68)+Special_Costs_Backward_Logistics) -> 0 | K47: =IF('Step 1 - Case Selection'!V41="as a Flat Rate",K48+K54+Special_Costs_Backward_Logistics,SUM(K48,K55,K61,K68)+Special_Costs_Backward_Logistics) -> 0 | L47: =IF('Step 1 - Case Selection'!V41="as a Flat Rate",L48+L54+Special_Costs_Backward_Logistics,SUM(L48,L55,L61,L68)+Special_Costs_Backward_Logistics) -> 0
D48: Core Premiums | E48: € | F48: =SUM(G48:L48) -> 0 | H48: ='Step 2.4 - Data Input (OpEx)'!G49*(H49+H51) -> 0 | I48: ='Step 2.4 - Data Input (OpEx)'!G49*(I49+I51) -> 0 | J48: ='Step 2.4 - Data Input (OpEx)'!G49*(J49+J51) -> 0 | K48: ='Step 2.4 - Data Input (OpEx)'!G49*(K49+K51) -> 0 | L48: ='Step 2.4 - Data Input (OpEx)'!G49*(L49+L51) -> 0
