Workbook

Sheet Input Parameters
B3: Plant Parameters
B4: Parameter | C4: Unit | D4: Value | E4: Source
B5: Clinker Production | C5: tClk/day | D5: 2896 | E5: CEMCAP
B6: Plant Capacity | C6: % | D6: 0.913 | E6: CEMCAP
B7: Operation | C7: days | D7: =365*D6 -> 333.245 | E7: Calculated
B8: Annual clinker production | C8: tons/year | D8: =D7*D5 -> 965077.52 | E8: Calculated
B9: Specific CO2 emissions | C9: tCO2/tClk | D9: 0.85 | E9: CEMCAP
B10: Plant Emissions | C10: tCO2 | D10: =D9*D8 -> 820315.89 | E10: Calculated
B12: Energy System Inputs
B13: Parameter | C13: Unit | D13: Value | E13: Source
B14: Denmark Natural Gas Price | C14: Euro/kWh | D14: 0.058 | E14: https://ec.europa.eu/eurostat/databrowser/view/nrg_pc_203__custom_20285923/default/table
B15: Germany Natural Gas Price | C15: Euro/kWh | D15: 0.05 | E15: https://ec.europa.eu/eurostat/databrowser/view/nrg_pc_203__custom_20285923/default/table
B16: Denmark Electricity Price | C16: Euro/kWh | D16: 0.126 | E16: https://ec.europa.eu/eurostat/statistics-explained/index.php?title=Electricity_price_statistics#Electricity_prices_for_non-household_consumers
B17: Germany Electricity Price | C17: Euro/kWh | D17: 0.1932 | E17: https://ec.europa.eu/eurostat/statistics-explained/index.php?title=Electricity_price_statistics#Electricity_prices_for_non-household_consumers
B18: Denmark Grid Emission Factor | C18: kgCO2/kWh | D18: 0.076 | E18: https://www.eea.europa.eu/en/analysis/indicators/greenhouse-gas-emission-intensity-of-1
B19: Germany Grid Emission Factor | C19: kgCO2/kWh | D19: 0.298 | E19: https://www.eea.europa.eu/en/analysis/indicators/greenhouse-gas-emission-intensity-of-1
B20: Natural Gas Emission Factor | C20: kgCO2/kWh | D20: 0.2 | E20: https://en.energinet.dk/media/nkmdwnwb/co2-emission-factor.pdf
B23: Cost Inputs
B24: Parameter | C24: Unit | D24: Value | E24: Source
B25: Capex without liquefication | C25: mEur/tCO2/h | D25: 2.8 | E25: DEA
B26: Fixed Opex | C26: % | D26: 0.03 | E26: DEA, 3% of Capex
B27: Variable Opex | C27: Eur/tCO2 | D27: 2.9 | E27: DEA, Includes Amine and other smaller consumables as well as waste disposal.
B29: Transport and Storage Inputs
B30: Parameter | C30: Unit | D30: Value | E30: Source
B31: Transport and Storage emission factor | C31: tCO2e/tCO2 | D31: 0.026 | E31: https://norlights.com/wp-content/uploads/2023/11/Report-Carbon-footprint-of-the-Northern-Lights-JV-co2-transport-and-storage-value-chain.pdf
B33: Financial Parameters
B34: Parameter | C34: Unit | D34: Value | E34: Source
B35: Lifetime | C35: years | D35: 25 | E35: CEMCAP
B36: WACC | C36: % | D36: ='Inflation and WACC'!C64 -> 0.0962 | E36: CEMCAP
B37: Inflation Rate | C37: % | D37: 0.015 | E37: CATF
B38: Construction Time | C38: years | D38: 3 | E38: CEMCAP
B39: CAPEX Split | C39: % | D39: 40-30-30 | E39: CEMCAP, Split over 3 years
B40: CRF | D40: =(D36*(1+D36)^D35)/(((1+D36)^D35)-1) -> 0.10696452 | E40: Calculated
B41: DKK - EUR Exchange rate 2025 average | D41: 7.4634 | E41: https://www.ecb.europa.eu/stats/policy_and_exchange_rates/euro_reference_exchange_rates/html/eurofxref-graph-dkk.en.html
B42: Germany Tax Rate | C42: % | D42: 0.3013 | E42: https://kpmg.com/dk/en/services/tax/corporate-tax/corporate-tax-rates-table.html
B43: Denmark Tax Rate | C43: % | D43: 0.22 | E43: https://kpmg.com/dk/en/services/tax/corporate-tax/corporate-tax-rates-table.html
B44: Danish CO2 Tax 2025 | C44: Euro/ton | D44: =114.9/D41 -> 15.395128 | E44: Danish CO2 tax, inflated to 2025, using the danish inflation calculator (https://www.dst.dk/en/Statistik/laer-om-statistik/prisberegner)
B45: Danish CO2 Tax 2026 | C45: Euro/ton | D45: =120.59/D41 -> 16.157515 | E45: Danish CO2 tax, inflated to 2025
B46: Danish CO2 Tax 2027 | C46: Euro/ton | D46: =126.4/D41 -> 16.935981 | E46: Danish CO2 tax, inflated to 2025
B47: Danish CO2 Tax 2028 | C47: Euro/ton | D47: =132.09/D41 -> 17.698368 | E47: Danish CO2 tax, inflated to 2025
...

Sheet Transport and Storage
B3: Transport and Storage Costs | K3: Cost Separation
B4: Pipeline? | C4: Country | D4: Location | E4: Mode of Transport | F4: Transport Hub | G4: Storage Type | H4: Sector Germany | I4: Cost per t/CO2 in 2024 | J4: Cost per t/CO2 in 2025 | K4: Conditioning Cost | L4: Storage Cost | M4: Transport Cost | R4: Country | S4: Pipeline | T4: T&S percentile | U4: Value | W4: Inflation Factor
B5: Pipeline Allowed | C5: Denmark | D5: Aalborg | E5: Located at storage hub | F5: Aalborg | G5: =IF(OR(F5="Ruby",F5="Aalborg"),"Onshore","Offshore") -> Onshore | H5: Denmark | I5: 33.3 | J5: =I5*$W$5 -> 34.1325 | K5: 15 | L5: =IF(G5="Onshore",15,30) -> 15 | M5: =J5-SUM(K5:L5) -> 4.1325 | R5: Denmark | S5: Pipeline allowed | T5: P25 | U5: =J5 -> 34.1325 | W5: 1.025
B6: Pipeline Disallowed | C6: Denmark | D6: Aalborg | E6: Located at storage hub | F6: Aalborg | G6: =IF(OR(F6="Ruby",F6="Aalborg"),"Onshore","Offshore") -> Onshore | H6: Denmark | I6: 33.86 | J6: =I6*$W$5 -> 34.7065 | K6: 15 | L6: =IF(G6="Onshore",15,30) -> 15 | M6: =J6-SUM(K6:L6) -> 4.7065 | R6: Denmark | S6: Pipeline disallowed | T6: P25 | U6: =J6 -> 34.7065
B7: Pipeline Disallowed | C7: Germany | D7: Kalkwerke Rüdersdorf | E7: Rail | F7: Esbjerg | G7: =IF(OR(F7="Ruby",F7="Aalborg"),"Onshore","Offshore") -> Offshore | H7: North | I7: 121.04 | J7: =I7*$W$5 -> 124.066 | K7: =IF(E7="Pipeline",15,17.5) -> 17.5 | L7: =IF(G7="Onshore",15,30) -> 30 | M7: =J7-SUM(K7:L7) -> 76.566 | R7: Denmark | S7: Pipeline allowed | T7: P50 | U7: =J5 -> 34.1325
B8: Pipeline Disallowed | C8: Germany | D8: Zementwerk Karsdorf | E8: Rail | F8: Esbjerg | G8: =IF(OR(F8="Ruby",F8="Aalborg"),"Onshore","Offshore") -> Offshore | H8: North | I8: 120.59 | J8: =I8*$W$5 -> 123.60475 | K8: =IF(E8="Pipeline",15,17.5) -> 17.5 | L8: =IF(G8="Onshore",15,30) -> 30 | M8: =J8-SUM(K8:L8) -> 76.10475 | R8: Denmark | S8: Pipeline disallowed | T8: P50 | U8: =J6 -> 34.7065
B9: Pipeline Disallowed | C9: Germany | D9: Zementwerk Rüdersdorf | E9: Rail | F9: Esbjerg | G9: =IF(OR(F9="Ruby",F9="Aalborg"),"Onshore","Offshore") -> Offshore | H9: North | I9: 120.38 | J9: =I9*$W$5 -> 123.3895 | K9: =IF(E9="Pipeline",15,17.5) -> 17.5 | L9: =IF(G9="Onshore",15,30) -> 30 | M9: =J9-SUM(K9:L9) -> 75.8895 | R9: Denmark | S9: Pipeline allowed | T9: P75 | U9: =J5 -> 34.1325
B10: Pipeline Disallowed | C10: Germany | D10: Zementwerk Bernburg | E10: Rail | F10: Esbjerg | G10: =IF(OR(F10="Ruby",F10="Aalborg"),"Onshore","Offshore") -> Offshore | H10: North | I10: 117.54 | J10: =I10*$W$5 -> 120.4785 | K10: =IF(E10="Pipeline",15,17.5) -> 17.5 | L10: =IF(G10="Onshore",15,30) -> 30 | M10: =J10-SUM(K10:L10) -> 72.9785 | R10: Denmark | S10: Pipeline disallowed | T10: P75 | U10: =J6 -> 34.7065
B11: Pipeline Disallowed | C11: Germany | D11: Fels KH NSO 1-5 Oberharz am Brocken | E11: Rail | F11: Esbjerg | G11: =IF(OR(F11="Ruby",F11="Aalborg"),"Onshore","Offshore") -> Offshore | H11: North | I11: 115.23 | J11: =I11*$W$5 -> 118.11075 | K11: =IF(E11="Pipeline",15,17.5) -> 17.5 | L11: =IF(G11="Onshore",15,30) -> 30 | M11: =J11-SUM(K11:L11) -> 70.61075 | R11: Germany | S11: Pipeline allowed | T11: P25 | U11: {=_xlfn.PERCENTILE.INC(_xlfn._xlws.FILTER($J$5:$J$98,($C$5:$C$98="Germany")*($B$5:B98="Pipeline Allowed")),0.25)} -> 52.784937
B12: Pipeline Disallowed | C12: Germany | D12: Fels KR NSO 1-8 Oberharz am Brocken | E12: Rail | F12: Esbjerg | G12: =IF(OR(F12="Ruby",F12="Aalborg"),"Onshore","Offshore") -> Offshore | H12: North | I12: 114.96 | J12: =I12*$W$5 -> 117.834 | K12: =IF(E12="Pipeline",15,17.5) -> 17.5 | L12: =IF(G12="Onshore",15,30) -> 30 | M12: =J12-SUM(K12:L12) -> 70.334 | R12: Germany | S12: Pipeline disallowed | T12: P25 | U12: {=_xlfn.PERCENTILE.INC(_xlfn._xlws.FILTER($J$5:$J$98,($C$5:$C$98="Germany")*($B$5:B98="Pipeline Disallowed")),0.25)} -> 97.308375
B13: Pipeline Disallowed | C13: Germany | D13: Fels KK GGR 6 Oberharz am Brocken | E13: Rail | F13: Esbjerg | G13: =IF(OR(F13="Ruby",F13="Aalborg"),"Onshore","Offshore") -> Offshore | H13: North | I13: 114.89 | J13: =I13*$W$5 -> 117.76225 | K13: =IF(E13="Pipeline",15,17.5) -> 17.5 | L13: =IF(G13="Onshore",15,30) -> 30 | M13: =J13-SUM(K13:L13) -> 70.26225 | R13: Germany | S13: Pipeline allowed | T13: P50 | U13: {=MEDIAN(_xlfn._xlws.FILTER(J5:J98,(C5:C98="Germany")*(B5:B98="Pipeline Allowed")))} -> 71.939625
B14: Pipeline Disallowed | C14: Germany | D14: Zementwerk Dotternhausen | E14: Rail | F14: Rotterdam | G14: =IF(OR(F14="Ruby",F14="Aalborg"),"Onshore","Offshore") -> Offshore | H14: South | I14: 114.01 | J14: =I14*$W$5 -> 116.86025 | K14: =IF(E14="Pipeline",15,17.5) -> 17.5 | L14: =IF(G14="Onshore",15,30) -> 30 | M14: =J14-SUM(K14:L14) -> 69.36025 | R14: Germany | S14: Pipeline disallowed | T14: P50 | U14: {=MEDIAN(_xlfn._xlws.FILTER(J5:J98,(C5:C98="Germany")*(B5:B98="Pipeline Disallowed")))} -> 105.575
B15: Pipeline Disallowed | C15: Germany | D15: Kalkwerk Seesen | E15: Rail | F15: Esbjerg | G15: =IF(OR(F15="Ruby",F15="Aalborg"),"Onshore","Offshore") -> Offshore | H15: North | I15: 113.63 | J15: =I15*$W$5 -> 116.47075 | K15: =IF(E15="Pipeline",15,17.5) -> 17.5 | L15: =IF(G15="Onshore",15,30) -> 30 | M15: =J15-SUM(K15:L15) -> 68.97075 | R15: Germany | S15: Pipeline allowed | T15: P75 | U15: {=_xlfn.PERCENTILE.INC(_xlfn._xlws.FILTER(J5:J98,(C5:C98="Germany")*(B5:B98="Pipeline Allowed")),0.75)} -> 78.960875
B16: Pipeline Disallowed | C16: Germany | D16: Zementwerk Burglengenfeld | E16: Rail | F16: Ravenna | G16: =IF(OR(F16="Ruby",F16="Aalborg"),"Onshore","Offshore") -> Offshore | H16: South | I16: 112.33 | J16: =I16*$W$5 -> 115.13825 | K16: =IF(E16="Pipeline",15,17.5) -> 17.5 | L16: =IF(G16="Onshore",15,30) -> 30 | M16: =J16-SUM(K16:L16) -> 67.63825 | R16: Germany | S16: Pipeline disallowed | T16: P75 | U16: {=_xlfn.PERCENTILE.INC(_xlfn._xlws.FILTER(J5:J98,(C5:C98="Germany")*(B5:B98="Pipeline Disallowed")),0.75)} -> 112.48862
B17: Pipeline Disallowed | C17: Germany | D17: Zementwerk Solnhofen | E17: Rail | F17: Ravenna | G17: =IF(OR(F17="Ruby",F17="Aalborg"),"Onshore","Offshore") -> Offshore | H17: South | I17: 109.89 | J17: =I17*$W$5 -> 112.63725 | K17: =IF(E17="Pipeline",15,17.5) -> 17.5 | L17: =IF(G17="Onshore",15,30) -> 30 | M17: =J17-SUM(K17:L17) -> 65.13725 | R17: Germany | S17: Pipeline allowed | T17: P0 | U17: {=MIN(_xlfn._xlws.FILTER(J5:J98,(C5:C98="Germany")*(B5:B98="Pipeline Allowed")))} -> 38.376
B18: Pipeline Disallowed | C18: Germany | D18: Zementwerk Sehnde | E18: Rail | F18: Esbjerg | G18: =IF(OR(F18="Ruby",F18="Aalborg"),"Onshore","Offshore") -> Offshore | H18: North | I18: 109.86 | J18: =I18*$W$5 -> 112.6065 | K18: =IF(E18="Pipeline",15,17.5) -> 17.5 | L18: =IF(G18="Onshore",15,30) -> 30 | M18: =J18-SUM(K18:L18) -> 65.1065 | R18: Germany | S18: Pipeline disallowed | T18: P0 | U18: {=MIN(_xlfn._xlws.FILTER(J5:J98,(C5:C98="Germany")*(B5:B98="Pipeline Disallowed")))} -> 79.868
B19: Pipeline Disallowed | C19: Germany | D19: Zementwerk Hannover | E19: Rail | F19: Esbjerg | G19: =IF(OR(F19="Ruby",F19="Aalborg"),"Onshore","Offshore") -> Offshore | H19: North | I19: 109.4 | J19: =I19*$W$5 -> 112.135 | K19: =IF(E19="Pipeline",15,17.5) -> 17.5 | L19: =IF(G19="Onshore",15,30) -> 30 | M19: =J19-SUM(K19:L19) -> 64.635 | R19: Germany | S19: Pipeline allowed | T19: P100 | U19: {=MAX(_xlfn._xlws.FILTER(J5:J98,(C5:C98="Germany")*(B5:B98="Pipeline Allowed")))} -> 116.86025
B20: Pipeline Disallowed | C20: Germany | D20: Kalkwerke Blaustein | E20: Rail | F20: Ravenna | G20: =IF(OR(F20="Ruby",F20="Aalborg"),"Onshore","Offshore") -> Offshore | H20: South | I20: 108.8 | J20: =I20*$W$5 -> 111.52 | K20: =IF(E20="Pipeline",15,17.5) -> 17.5 | L20: =IF(G20="Onshore",15,30) -> 30 | M20: =J20-SUM(K20:L20) -> 64.02 | R20: Germany | S20: Pipeline disallowed | T20: P100 | U20: {=MAX(_xlfn._xlws.FILTER(J5:J98,(C5:C98="Germany")*(B5:B98="Pipeline Disallowed")))} -> 124.066
B21: Pipeline Disallowed | C21: Germany | D21: Kalkwerke Harburg | E21: Rail | F21: Ravenna | G21: =IF(OR(F21="Ruby",F21="Aalborg"),"Onshore","Offshore") -> Offshore | H21: South | I21: 108.77 | J21: =I21*$W$5 -> 111.48925 | K21: =IF(E21="Pipeline",15,17.5) -> 17.5 | L21: =IF(G21="Onshore",15,30) -> 30 | M21: =J21-SUM(K21:L21) -> 63.98925
B22: Pipeline Disallowed | C22: Germany | D22: Zementwerk Schelklingen | E22: Rail | F22: Ravenna | G22: =IF(OR(F22="Ruby",F22="Aalborg"),"Onshore","Offshore") -> Offshore | H22: South | I22: 108.48 | J22: =I22*$W$5 -> 111.192 | K22: =IF(E22="Pipeline",15,17.5) -> 17.5 | L22: =IF(G22="Onshore",15,30) -> 30 | M22: =J22-SUM(K22:L22) -> 63.692 | R22: Pipeline? | S22: Pipeline Allowed | U22: Pipeline? | V22: Pipeline Disallowed | X22: Country | Y22: Germany | AA22: Country | AB22: Germany
B23: Pipeline Disallowed | C23: Germany | D23: Zementwerk Allmendingen | E23: Rail | F23: Ravenna | G23: =IF(OR(F23="Ruby",F23="Aalborg"),"Onshore","Offshore") -> Offshore | H23: South | I23: 108.45 | J23: =I23*$W$5 -> 111.16125 | K23: =IF(E23="Pipeline",15,17.5) -> 17.5 | L23: =IF(G23="Onshore",15,30) -> 30 | M23: =J23-SUM(K23:L23) -> 63.66125 | R23: Country | S23: Germany | U23: Country | V23: Germany
B24: Pipeline Disallowed | C24: Germany | D24: Zementwerk Heidenheim an der Brenz | E24: Rail | F24: Ravenna | G24: =IF(OR(F24="Ruby",F24="Aalborg"),"Onshore","Offshore") -> Offshore | H24: South | I24: 108.44 | J24: =I24*$W$5 -> 111.151 | K24: =IF(E24="Pipeline",15,17.5) -> 17.5 | L24: =IF(G24="Onshore",15,30) -> 30 | M24: =J24-SUM(K24:L24) -> 63.651 | X24: Row Labels | Y24: Average of Transport Cost | AA24: Row Labels | AB24: Average of Cost per t/CO2 in 2025 | AC24: Average of Conditioning Cost | AD24: Average of Storage Cost | AE24: Average of Transport Cost
B25: Pipeline Disallowed | C25: Germany | D25: Zementwerk Harburg | E25: Rail | F25: Ravenna | G25: =IF(OR(F25="Ruby",F25="Aalborg"),"Onshore","Offshore") -> Offshore | H25: South | I25: 108.24 | J25: =I25*$W$5 -> 110.946 | K25: =IF(E25="Pipeline",15,17.5) -> 17.5 | L25: =IF(G25="Onshore",15,30) -> 30 | M25: =J25-SUM(K25:L25) -> 63.446 | R25: Row Labels | S25: Sum of Cost per t/CO2 in 2025 | U25: Row Labels | V25: Sum of Cost per t/CO2 in 2025 | X25: Barge | Y25: 38.865036 | AA25: Pipeline Allowed | AB25: 68.947293 | AC25: 15.054348 | AD25: 25.76087 | AE25: 28.132076
B26: Pipeline Disallowed | C26: Germany | D26: Zementwerk Walzbachtal | E26: Rail | F26: Rotterdam | G26: =IF(OR(F26="Ruby",F26="Aalborg"),"Onshore","Offshore") -> Offshore | H26: South | I26: 108.1 | J26: =I26*$W$5 -> 110.8025 | K26: =IF(E26="Pipeline",15,17.5) -> 17.5 | L26: =IF(G26="Onshore",15,30) -> 30 | M26: =J26-SUM(K26:L26) -> 63.3025 | R26: Zementwerk Dotternhausen | S26: 116.394 | U26: Kalkwerke Rüdersdorf | V26: 123.541 | X26: South | Y26: 38.865036 | AA26: North | AB26: 57.419163 | AC26: 15 | AD26: 22.173913 | AE26: 20.24525
B27: Pipeline Disallowed | C27: Germany | D27: Zementwerk Niederorschel | E27: Rail | F27: Rotterdam | G27: =IF(OR(F27="Ruby",F27="Aalborg"),"Onshore","Offshore") -> Offshore | H27: North | I27: 106.94 | J27: =I27*$W$5 -> 109.6135 | K27: =IF(E27="Pipeline",15,17.5) -> 17.5 | L27: =IF(G27="Onshore",15,30) -> 30 | M27: =J27-SUM(K27:L27) -> 62.1135 | R27: Lhoist Istein | S27: 87.2955 | U27: Zementwerk Karsdorf | V27: 123.1326 | X27: Pipeline | Y27: 27.215894 | AA27: Pipeline | AB27: 57.419163 | AC27: 15 | AD27: 22.173913 | AE27: 20.24525
B28: Pipeline Disallowed | C28: Germany | D28: Zementwerk Großenlüder | E28: Rail | F28: Rotterdam | G28: =IF(OR(F28="Ruby",F28="Aalborg"),"Onshore","Offshore") -> Offshore | H28: South | I28: 104.75 | J28: =I28*$W$5 -> 107.36875 | K28: =IF(E28="Pipeline",15,17.5) -> 17.5 | L28: =IF(G28="Onshore",15,30) -> 30 | M28: =J28-SUM(K28:L28) -> 59.86875 | R28: Kalkwerke Harburg | S28: 85.6619 | U28: Zementwerk Rüdersdorf | V28: 122.9284 | X28: North | Y28: 20.24525 | AA28: Rotterdam | AB28: 70.008432 | AC28: 15 | AD28: 30 | AE28: 25.008432
B29: Pipeline Disallowed | C29: Germany | D29: Zementwerk Göllheim | E29: Rail | F29: Rotterdam | G29: =IF(OR(F29="Ruby",F29="Aalborg"),"Onshore","Offshore") -> Offshore | H29: South | I29: 103.33 | J29: =I29*$W$5 -> 105.91325 | K29: =IF(E29="Pipeline",15,17.5) -> 17.5 | L29: =IF(G29="Onshore",15,30) -> 30 | M29: =J29-SUM(K29:L29) -> 58.41325 | R29: Zementwerk Harburg | S29: 85.6619 | U29: Zementwerk Bernburg | V29: 119.9675 | X29: South | Y29: 34.503386 | AA29: Ruby | AB29: 45.879 | AC29: 15 | AD29: 15 | AE29: 15.879
B30: Pipeline Disallowed | C30: Germany | D30: Zementwerk Rohrdorf | E30: Rail | F30: Ravenna | G30: =IF(OR(F30="Ruby",F30="Aalborg"),"Onshore","Offshore") -> Offshore | H30: South | I30: 102.67 | J30: =I30*$W$5 -> 105.23675 | K30: =IF(E30="Pipeline",15,17.5) -> 17.5 | L30: =IF(G30="Onshore",15,30) -> 30 | M30: =J30-SUM(K30:L30) -> 57.73675 | R30: Zementwerk Solnhofen | S30: 85.4577 | U30: Fels KH NSO 1-5 Oberharz am Brocken | V30: 117.64983 | X30: Rail | Y30: 61.005731 | AA30: South | AB30: 80.475424 | AC30: 15.108696 | AD30: 29.347826 | AE30: 36.018902
B31: Pipeline Disallowed | C31: Germany | D31: Brennanlage Runkel | E31: Rail | F31: Rotterdam | G31: =IF(OR(F31="Ruby",F31="Aalborg"),"Onshore","Offshore") -> Offshore | H31: South | I31: 99.67 | J31: =I31*$W$5 -> 102.16175 | K31: =IF(E31="Pipeline",15,17.5) -> 17.5 | L31: =IF(G31="Onshore",15,30) -> 30 | M31: =J31-SUM(K31:L31) -> 54.66175 | R31: Zementwerk Heidenheim an der Brenz | S31: 84.5388 | U31: Fels KR NSO 1-8 Oberharz am Brocken | V31: 117.37416 | X31: North | Y31: 60.2685 | AA31: Pipeline | AB31: 78.821568 | AC31: 15 | AD31: 29.318182 | AE31: 34.503386
B32: Pipeline Disallowed | C32: Germany | D32: Kalkwerk Hahnstätten | E32: Rail | F32: Rotterdam | G32: =IF(OR(F32="Ruby",F32="Aalborg"),"Onshore","Offshore") -> Offshore | H32: South | I32: 99.67 | J32: =I32*$W$5 -> 102.16175 | K32: =IF(E32="Pipeline",15,17.5) -> 17.5 | L32: =IF(G32="Onshore",15,30) -> 30 | M32: =J32-SUM(K32:L32) -> 54.66175 | R32: Kalkwerke Blaustein | S32: 84.4367 | U32: Fels KK GGR 6 Oberharz am Brocken | V32: 117.30269 | X32: South | Y32: 62.003162 | AA32: Ravenna | AB32: 76.068667 | AC32: 15 | AD32: 30 | AE32: 31.068667
B33: Pipeline Disallowed | C33: Germany | D33: Zementwerk Paderborn | E33: Rail | F33: Rotterdam | G33: =IF(OR(F33="Ruby",F33="Aalborg"),"Onshore","Offshore") -> Offshore | H33: North | I33: 99.57 | J33: =I33*$W$5 -> 102.05925 | K33: =IF(E33="Pipeline",15,17.5) -> 17.5 | L33: =IF(G33="Onshore",15,30) -> 30 | M33: =J33-SUM(K33:L33) -> 54.55925 | R33: Zementwerk Schelklingen | S33: 84.4367 | U33: Zementwerk Dotternhausen | V33: 116.394 | X33: Grand Total | Y33: 42.793476 | AA33: Rotterdam | AB33: 80.283125 | AC33: 15 | AD33: 30 | AE33: 35.283125
B34: Pipeline Disallowed | C34: Germany | D34: Drehofen 11 Lägerdorf | E34: Rail | F34: Esbjerg | G34: =IF(OR(F34="Ruby",F34="Aalborg"),"Onshore","Offshore") -> Offshore | H34: North | I34: 99.02 | J34: =I34*$W$5 -> 101.4955 | K34: =IF(E34="Pipeline",15,17.5) -> 17.5 | L34: =IF(G34="Onshore",15,30) -> 30 | M34: =J34-SUM(K34:L34) -> 53.9955 | R34: Zementwerk Allmendingen | S34: 84.4367 | U34: Kalkwerk Seesen | V34: 115.9856 | AA34: Ruby | AB34: 60.77225 | AC34: 15 | AD34: 15 | AE34: 30.77225
B35: Pipeline Disallowed | C35: Germany | D35: Zementwerk Geseke | E35: Rail | F35: Rotterdam | G35: =IF(OR(F35="Ruby",F35="Aalborg"),"Onshore","Offshore") -> Offshore | H35: North | I35: 98.56 | J35: =I35*$W$5 -> 101.024 | K35: =IF(E35="Pipeline",15,17.5) -> 17.5 | L35: =IF(G35="Onshore",15,30) -> 30 | M35: =J35-SUM(K35:L35) -> 53.524 | R35: Zementwerk Walzbachtal | S35: 80.0464 | U35: Zementwerk Burglengenfeld | V35: 114.6583 | AA35: Rail | AB35: 116.86025 | AC35: 17.5 | AD35: 30 | AE35: 69.36025
B36: Pipeline Disallowed | C36: Germany | D36: Kalkwerk Warstein | E36: Rail | F36: Rotterdam | G36: =IF(OR(F36="Ruby",F36="Aalborg"),"Onshore","Offshore") -> Offshore | H36: North | I36: 98.44 | J36: =I36*$W$5 -> 100.901 | K36: =IF(E36="Pipeline",15,17.5) -> 17.5 | L36: =IF(G36="Onshore",15,30) -> 30 | M36: =J36-SUM(K36:L36) -> 53.401 | R36: Zementwerk Karlstadt | S36: 79.0254 | U36: Zementwerk Sehnde | V36: 112.2079 | AA36: Rotterdam | AB36: 116.86025 | AC36: 17.5 | AD36: 30 | AE36: 69.36025
B37: Pipeline Disallowed | C37: Germany | D37: Zementwerk Erwitte | E37: Rail | F37: Rotterdam | G37: =IF(OR(F37="Ruby",F37="Aalborg"),"Onshore","Offshore") -> Offshore | H37: North | I37: 97.24 | J37: =I37*$W$5 -> 99.671 | K37: =IF(E37="Pipeline",15,17.5) -> 17.5 | L37: =IF(G37="Onshore",15,30) -> 30 | M37: =J37-SUM(K37:L37) -> 52.171 | R37: Zementwerk Triefenstein | S37: 78.8212 | U37: Zementwerk Solnhofen | V37: 112.2079 | AA37: Pipeline Disallowed | AB37: 104.95487 | AC37: 17.5 | AD37: 30 | AE37: 57.454875
B38: Pipeline Disallowed | C38: Germany | D38: Zementwerk Üxheim | E38: Rail | F38: Rotterdam | G38: =IF(OR(F38="Ruby",F38="Aalborg"),"Onshore","Offshore") -> Offshore | H38: South | I38: 96.54 | J38: =I38*$W$5 -> 98.9535 | K38: =IF(E38="Pipeline",15,17.5) -> 17.5 | L38: =IF(G38="Onshore",15,30) -> 30 | M38: =J38-SUM(K38:L38) -> 51.4535 | R38: Kalkwerke Regensburg | S38: 78.2086 | U38: Zementwerk Hannover | V38: 111.6974 | AA38: North | AB38: 107.7685 | AC38: 17.5 | AD38: 30 | AE38: 60.2685
B39: Pipeline Disallowed | C39: Germany | D39: Zementwerk Beckum | E39: Rail | F39: Rotterdam | G39: =IF(OR(F39="Ruby",F39="Aalborg"),"Onshore","Offshore") -> Offshore | H39: North | I39: 96.1 | J39: =I39*$W$5 -> 98.5025 | K39: =IF(E39="Pipeline",15,17.5) -> 17.5 | L39: =IF(G39="Onshore",15,30) -> 30 | M39: =J39-SUM(K39:L39) -> 51.0025 | R39: Zementwerk Leimen | S39: 78.1065 | U39: Kalkwerke Blaustein | V39: 111.0848 | AA39: Rail | AB39: 107.7685 | AC39: 17.5 | AD39: 30 | AE39: 60.2685
B40: Pipeline Disallowed | C40: Germany | D40: Zementwerk Enningerloh | E40: Rail | F40: Rotterdam | G40: =IF(OR(F40="Ruby",F40="Aalborg"),"Onshore","Offshore") -> Offshore | H40: North | I40: 95.22 | J40: =I40*$W$5 -> 97.6005 | K40: =IF(E40="Pipeline",15,17.5) -> 17.5 | L40: =IF(G40="Onshore",15,30) -> 30 | M40: =J40-SUM(K40:L40) -> 50.1005 | R40: Kalkwerke Saal a. d. Donau | S40: 77.4939 | U40: Kalkwerke Harburg | V40: 111.0848 | AA40: Esbjerg | AB40: 117.08668 | AC40: 17.5 | AD40: 30 | AE40: 69.586682
B41: Pipeline Disallowed | C41: Germany | D41: Kalkwerk Lienen | E41: Rail | F41: Rotterdam | G41: =IF(OR(F41="Ruby",F41="Aalborg"),"Onshore","Offshore") -> Offshore | H41: North | I41: 94.84 | J41: =I41*$W$5 -> 97.211 | K41: =IF(E41="Pipeline",15,17.5) -> 17.5 | L41: =IF(G41="Onshore",15,30) -> 30 | M41: =J41-SUM(K41:L41) -> 49.711 | R41: Zementwerk Großenlüder | S41: 77.0855 | U41: Zementwerk Schelklingen | V41: 110.7785 | AA41: Rotterdam | AB41: 99.226833 | AC41: 17.5 | AD41: 30 | AE41: 51.726833
B42: Pipeline Disallowed | C42: Germany | D42: Brennen von Kalkstein Menden | E42: Rail | F42: Rotterdam | G42: =IF(OR(F42="Ruby",F42="Aalborg"),"Onshore","Offshore") -> Offshore | H42: North | I42: 94.43 | J42: =I42*$W$5 -> 96.79075 | K42: =IF(E42="Pipeline",15,17.5) -> 17.5 | L42: =IF(G42="Onshore",15,30) -> 30 | M42: =J42-SUM(K42:L42) -> 49.29075 | R42: Zementwerk Göllheim | S42: 75.3498 | U42: Zementwerk Allmendingen | V42: 110.7785 | AA42: South | AB42: 102.14125 | AC42: 17.5 | AD42: 30 | AE42: 54.64125
...

Sheet Capture Model
B3: Capture Performance
B4: Parameter | C4: Unit | D4: Value | E4: Source
B5: Capture Rate | C5: % | D5: 0.9 | E5: CEMCAP, Davila-Gallego
B6: CO2 captured | C6: tCO2 | D6: =D5*'Input Parameters'!D10 -> 738284.3 | E6: Calculated
B7: Specific Capture Performance | C7: tCO2/h | D7: =D6/(8760*'Input Parameters'!D6) -> 92.31 | E7: Calculated
B9: Capture Technology Energy Demand
B10: Parameter | C10: Unit | D10: Value | E10: Source
B11: Reboiler duty | C11: MWh/tCO2 | D11: 0.833 | E11: DEA
B12: Boiler efficiency | C12: % | D12: 0.9 | E12: CEMCAP
B13: Power demand MEA | C13: MWh/tCO2 | D13: 0.025 | E13: DEA
B14: Amine Make-up | C14: kg/tCO2 | D14: 0.3 | E14: DEA
B16: Steam Demand
B17: Parameter | C17: Unit | D17: Value | E17: Source
B18: Steam Generation from Waste heat | C18: % | D18: 0.04 | E18: CEMCAP, 4.6
B19: Steam Generation from Natural Gas boiler | C19: % | D19: 0.96 | E19: CEMCAP, 4.6
B20: Total Steam from Waste Heat | C20: MWh | D20: =D11*D6*D18 -> 24599.633 | E20: Calculated
B21: Total Steam from Natural Gas | C21: MWh | D21: =D11*D6*D19 -> 590391.19 | E21: Calculated
B22: Natural Gas Fuel Energy | C22: MWh | D22: =D21/D12 -> 655990.21 | E22: Calculated
B24: Extra Electricity
B25: Parameter | C25: Unit | D25: Value | E25: Source
B26: Extra Electricity Demand | C26: MWh/year | D26: =D13*D6 -> 18457.108 | E26: Calculated
B29: Additional Emissions
B30: Parameter | C30: Unit | D30: Value | E30: Source
B31: Additional Emissions Steam | C31: tCO2 | D31: =D22*'Input Parameters'!D20 -> 131198.04 | E31: Calculated
B32: Additional Emissions Electricity | C32: tCO2 | D32: =IF('Cost of CO2 Avoided'!C37="Germany",D26*'Input Parameters'!D19,D26*'Input Parameters'!D18) -> 5500.2181 | E32: Calculated
B33: Additional Emissons Transport and Storage | C33: tCO2 | D33: =D6*'Input Parameters'!D31 -> 19195.392 | E33: Calculated

Sheet ETS
B2: ETS Overview
D3: Source
B4: EU ETS 2025 low | C4: =MIN(G14:G226) -> 59.76
B5: EU ETS 2025 | C5: =MEDIAN(G14:G226) -> 72.16 | D5: Emission Spot Primary Market Auction Report 2025, Median
B6: EU ETS 2025 high | C6: =MAX(G14:G226) -> 84.6
B7: EU ETS 2030 projection | C7: 124 | D7: IEA World Energy Outlook
B10: More information | D10: =HYPERLINK("https://www.eex.com/en/markets/environmental-markets/emissions-auctions","https://www.eex.com/en/markets/environmental-markets/emissions-auctions") -> https://www.eex.com/en/markets/environmental-markets/emissions-auctions
L11: EEX Emissions market / Primary Market Auction
B12: References | G12: Prices | L12: Volumes | W12: Participants | Y12: Revenue | AA12: Revenue
B13: Date | C13: Time | D13: Auction Name | E13: Contract | F13: Status | G13: Auction Price €/tCO2 | H13: Minimum Bid €/tCO2 | I13: Maximum Bid €/tCO2 | J13: Mean €/tCO2 | K13: Median €/tCO2 | L13: Auction Volume tCO2 | M13: Total Amount of Bids | N13: Number of bids submitted | O13: Number of successful bids | P13: Average number of bids per bidder | Q13: Average bid size | R13: Average volume bid per bidder | S13: Standard deviation of bid volume per bidder | T13: Average volume won per bidder | U13: Standard deviation of volume won per bidder | V13: Cover Ratio | W13: Total Number of Bidders | X13: Number of Successful Bidders | Y13: Total Revenue € | Z13: Country | AA13: Austria (AT) | AB13: Belgium (BE) | AC13: Bulgaria (BG) | AD13: Cyprus (CY) | AE13: Czech Republic (CZ) | AF13: Germany (DE) | AG13: Denmark (DK) | AH13: Estonia (EE) | AI13: Greece (EL) | AJ13: Spain (ES) | AK13: Finland (FI) | AL13: France (FR) | AM13: Croatia (HR) | AN13: Hungary (HU) | AO13: Ireland (IE) | AP13: Innovation Fund (IF) | AQ13: Iceland (IS) | AR13: Italy (IT) | AS13: InnoFund RRF (IX) | AT13: Liechtenstein (LI) | AU13: Lithuania (LT) | AV13: Luxembourg (LU) | AW13: Latvia (LV) | AX13: Modernisation Fund (MF) | AY13: Malta (MT) | AZ13: MS RRF (MX) | BA13: Netherlands (NL) | BB13: Norway (NO) | BC13: Poland (PL) | BD13: Portugal (PT) | BE13: Romania (RO) | BF13: Sweden (SE) | BG13: Social Climate Fund (SF) | BH13: Slovenia (SI) | BI13: Slovakia (SK) | BJ13: Northern Ireland (XI)
B14: 46006 | C14: 46006.459 | D14: Auction 4. Period CAP3 EU | E14: T3PA | F14: successful | G14: 84.6 | H14: 64 | I14: 90 | J14: 84.04 | K14: 84.32 | L14: 3273000 | M14: 5084000 | N14: 100 | O14: 31 | P14: 4 | Q14: 50840 | R14: 203360 | S14: 310008 | T14: 181833 | U14: 309586 | V14: 1.55 | W14: 25 | X14: 18 | Y14: 276895800 | Z14: EU | AA14: 3045600 | AB14: 3722400 | AC14: 5795100 | AD14: 1776600 | AE14: 2157300 | AG14: 1988100 | AH14: 2241900 | AI14: 9855900 | AJ14: 21742200 | AK14: 1903500 | AL14: 11294100 | AM14: 253800 | AN14: 2538000 | AO14: 84600 | AP14: 20134800 | AQ14: 1480500 | AR14: 20177100 | AS14: 34263000 | AT14: 42300 | AU14: 1015200 | AV14: 0 | AW14: 846000 | AX14: 53171100 | AY14: 1099800 | AZ14: 22842000 | BA14: 7191000 | BB14: 676800 | BD14: 4949100 | BE14: 4018500 | BF14: 2072700 | BG14: 31132800 | BH14: 761400 | BI14: 2622600
B15: 46003 | C15: 46003.459 | D15: Auction 4. Period DE | E15: T3PA | F15: successful | G15: 83.65 | H15: 64 | I15: 150 | J15: 84.73 | K15: 83.45 | L15: 1696000 | M15: 3492000 | N15: 75 | O15: 23 | P15: 3 | Q15: 46560 | R15: 139680 | S15: 156013 | T15: 113067 | U15: 140961 | V15: 2.06 | W15: 25 | X15: 15 | Y15: 141870400 | Z15: DE | AF15: 141870400
B16: 46002 | C16: 46002.459 | D16: Auction 4. Period CAP3 EU | E16: T3PA | F16: successful | G16: 83.77 | H16: 64 | I16: 150 | J16: 84.51 | K16: 83.48 | L16: 3268000 | M16: 5580000 | N16: 97 | O16: 23 | P16: 3.73 | Q16: 57526 | R16: 214615 | S16: 295689 | T16: 217867 | U16: 322382 | V16: 1.71 | W16: 26 | X16: 15 | Y16: 273760360 | Z16: EU | AA16: 2429330 | AB16: 4230385 | AC16: 6869140 | AD16: 879585 | AE16: 4523580 | AG16: 2387445 | AH16: 2094250 | AI16: 9298470 | AJ16: 21193810 | AK16: 3350800 | AL16: 12565500 | AM16: 963355 | AN16: 3602110 | AO16: 1005240 | AP16: 20900615 | AQ16: 41885 | AR16: 21110040 | AS16: 30659820 | AT16: 0 | AU16: 670160 | AV16: 0 | AW16: 544505 | AX16: 52104940 | AY16: 418850 | AZ16: 20439880 | BA16: 7497415 | BB16: 1633515 | BD16: 4439810 | BE16: 3685880 | BF16: 1465975 | BG16: 29487040 | BH16: 1089010 | BI16: 2178020
B17: 46001 | C17: 46001.459 | D17: Auction 4. Period CAP3 PL | E17: T3PA | F17: successful | G17: 82.18 | H17: 64 | I17: 85 | J17: 81.8 | K17: 82.12 | L17: 2166000 | M17: 3405500 | N17: 84 | O17: 37 | P17: 3.65 | Q17: 40542 | R17: 148065 | S17: 175481 | T17: 103143 | U17: 145787 | V17: 1.57 | W17: 23 | X17: 21 | Y17: 178001880 | Z17: PL | BC17: 178001880
B18: 46000 | C18: 46000.459 | D18: Auction 4. Period CAP3 EU | E18: T3PA | F18: successful | G18: 82.22 | H18: 0.01 | I18: 150 | J18: 81.41 | K18: 82 | L18: 3268000 | M18: 5374500 | N18: 91 | O18: 21 | P18: 3.5 | Q18: 59060 | R18: 206712 | S18: 249747 | T18: 192235 | U18: 234054 | V18: 1.64 | W18: 26 | X18: 17 | Y18: 268694960 | Z18: EU | AA18: 2384380 | AB18: 4152110 | AC18: 6742040 | AD18: 863310 | AE18: 4439880 | AG18: 2343270 | AH18: 2055500 | AI18: 9126420 | AJ18: 20801660 | AK18: 3288800 | AL18: 12333000 | AM18: 945530 | AN18: 3535460 | AO18: 986640 | AP18: 20513890 | AQ18: 41110 | AR18: 20719440 | AS18: 30092520 | AT18: 0 | AU18: 657760 | AV18: 0 | AW18: 534430 | AX18: 51140840 | AY18: 411100 | AZ18: 20061680 | BA18: 7358690 | BB18: 1603290 | BD18: 4357660 | BE18: 3617680 | BF18: 1438850 | BG18: 28941440 | BH18: 1068860 | BI18: 2137720
B19: 45999 | C19: 45999.459 | D19: Auction 4. Period CAP3 EU | E19: T3PA | F19: successful | G19: 82.17 | H19: 64 | I19: 150 | J19: 83.85 | K19: 81.84 | L19: 3268000 | M19: 5324000 | N19: 86 | O19: 17 | P19: 3.91 | Q19: 61907 | R19: 242000 | S19: 344482 | T19: 326800 | U19: 410689 | V19: 1.63 | W19: 22 | X19: 10 | Y19: 268531560 | Z19: EU | AA19: 2382930 | AB19: 4149585 | AC19: 6737940 | AD19: 862785 | AE19: 4437180 | AG19: 2341845 | AH19: 2054250 | AI19: 9120870 | AJ19: 20789010 | AK19: 3286800 | AL19: 12325500 | AM19: 944955 | AN19: 3533310 | AO19: 986040 | AP19: 20501415 | AQ19: 41085 | AR19: 20706840 | AS19: 30074220 | AT19: 0 | AU19: 657360 | AV19: 0 | AW19: 534105 | AX19: 51109740 | AY19: 410850 | AZ19: 20049480 | BA19: 7354215 | BB19: 1602315 | BD19: 4355010 | BE19: 3615480 | BF19: 1437975 | BG19: 28923840 | BH19: 1068210 | BI19: 2136420
B20: 45996 | C20: 45996.459 | D20: Auction 4. Period DE | E20: T3PA | F20: successful | G20: 82.25 | H20: 64 | I20: 85 | J20: 81.39 | K20: 81.87 | L20: 1691000 | M20: 3494500 | N20: 80 | O20: 11 | P20: 3.33 | Q20: 43681 | R20: 145604 | S20: 191690 | T20: 169100 | U20: 218515 | V20: 2.07 | W20: 24 | X20: 10 | Y20: 139084750 | Z20: DE | AF20: 139084750
B21: 45995 | C21: 45995.459 | D21: Auction 4. Period CAP3 EU | E21: T3PA | F21: successful | G21: 81.39 | H21: 64 | I21: 120 | J21: 81.39 | K21: 81.2 | L21: 3268000 | M21: 5274500 | N21: 97 | O21: 27 | P21: 3.46 | Q21: 54376 | R21: 188375 | S21: 261535 | T21: 163400 | U21: 240275 | V21: 1.61 | W21: 28 | X21: 20 | Y21: 265982520 | Z21: EU | AA21: 2360310 | AB21: 4110195 | AC21: 6673980 | AD21: 854595 | AE21: 4395060 | AG21: 2319615 | AH21: 2034750 | AI21: 9034290 | AJ21: 20591670 | AK21: 3255600 | AL21: 12208500 | AM21: 935985 | AN21: 3499770 | AO21: 976680 | AP21: 20306805 | AQ21: 40695 | AR21: 20510280 | AS21: 29788740 | AT21: 0 | AU21: 651120 | AV21: 0 | AW21: 529035 | AX21: 50624580 | AY21: 406950 | AZ21: 19859160 | BA21: 7284405 | BB21: 1587105 | BD21: 4313670 | BE21: 3581160 | BF21: 1424325 | BG21: 28649280 | BH21: 1058070 | BI21: 2116140
B22: 45993 | C22: 45993.459 | D22: Auction 4. Period CAP3 EU | E22: T3PA | F22: successful | G22: 82.19 | H22: 64 | I22: 150 | J22: 83.33 | K22: 82.04 | L22: 3268000 | M22: 4548000 | N22: 91 | O22: 32 | P22: 3.96 | Q22: 49978 | R22: 197739 | S22: 270181 | T22: 181556 | U22: 272442 | V22: 1.39 | W22: 23 | X22: 18 | Y22: 268596920 | Z22: EU | AA22: 2383510 | AB22: 4150595 | AC22: 6739580 | AD22: 862995 | AE22: 4438260 | AG22: 2342415 | AH22: 2054750 | AI22: 9123090 | AJ22: 20794070 | AK22: 3287600 | AL22: 12328500 | AM22: 945185 | AN22: 3534170 | AO22: 986280 | AP22: 20506405 | AQ22: 41095 | AR22: 20711880 | AS22: 30081540 | AT22: 0 | AU22: 657520 | AV22: 0 | AW22: 534235 | AX22: 51122180 | AY22: 410950 | AZ22: 20054360 | BA22: 7356005 | BB22: 1602705 | BD22: 4356070 | BE22: 3616360 | BF22: 1438325 | BG22: 28930880 | BH22: 1068470 | BI22: 2136940
B23: 45992 | C23: 45992.459 | D23: Auction 4. Period CAP3 EU | E23: T3PA | F23: successful | G23: 83.01 | H23: 80 | I23: 150 | J23: 83.74 | K23: 82.97 | L23: 3268000 | M23: 4606000 | N23: 88 | O23: 37 | P23: 4 | Q23: 52341 | R23: 209364 | S23: 292814 | T23: 181556 | U23: 276565 | V23: 1.41 | W23: 22 | X23: 18 | Y23: 271276680 | Z23: EU | AA23: 2407290 | AB23: 4192005 | AC23: 6806820 | AD23: 871605 | AE23: 4482540 | AG23: 2365785 | AH23: 2075250 | AI23: 9214110 | AJ23: 21001530 | AK23: 3320400 | AL23: 12451500 | AM23: 954615 | AN23: 3569430 | AO23: 996120 | AP23: 20710995 | AQ23: 41505 | AR23: 20918520 | AS23: 30381660 | AT23: 0 | AU23: 664080 | AV23: 0 | AW23: 539565 | AX23: 51632220 | AY23: 415050 | AZ23: 20254440 | BA23: 7429395 | BB23: 1618695 | BD23: 4399530 | BE23: 3652440 | BF23: 1452675 | BG23: 29219520 | BH23: 1079130 | BI23: 2158260
B24: 45989 | C24: 45989.459 | D24: Auction 4. Period DE | E24: T3PA | F24: successful | G24: 82.6 | H24: 64 | I24: 85 | J24: 81.92 | K24: 82.32 | L24: 1691000 | M24: 3176500 | N24: 82 | O24: 18 | P24: 3.57 | Q24: 38738 | R24: 138109 | S24: 205238 | T24: 112733 | U24: 212229 | V24: 1.88 | W24: 23 | X24: 15 | Y24: 139676600 | Z24: DE | AF24: 139676600
B25: 45988 | C25: 45988.459 | D25: Auction 4. Period CAP3 EU | E25: T3PA | F25: successful | G25: 81.07 | H25: 64 | I25: 120 | J25: 81.62 | K25: 80.81 | L25: 3268000 | M25: 5308500 | N25: 105 | O25: 28 | P25: 4.2 | Q25: 50557 | R25: 212340 | S25: 247083 | T25: 192235 | U25: 224885 | V25: 1.62 | W25: 25 | X25: 17 | Y25: 264936760 | Z25: EU | AA25: 2351030 | AB25: 4094035 | AC25: 6647740 | AD25: 851235 | AE25: 4377780 | AG25: 2310495 | AH25: 2026750 | AI25: 8998770 | AJ25: 20510710 | AK25: 3242800 | AL25: 12160500 | AM25: 932305 | AN25: 3486010 | AO25: 972840 | AP25: 20226965 | AQ25: 40535 | AR25: 20429640 | AS25: 29671620 | AT25: 0 | AU25: 648560 | AV25: 0 | AW25: 526955 | AX25: 50425540 | AY25: 405350 | AZ25: 19781080 | BA25: 7255765 | BB25: 1580865 | BD25: 4296710 | BE25: 3567080 | BF25: 1418725 | BG25: 28536640 | BH25: 1053910 | BI25: 2107820
B26: 45987 | C26: 45987.459 | D26: Auction 4. Period CAP3 PL | E26: T3PA | F26: successful | G26: 81.51 | H26: 64 | I26: 150 | J26: 83.3 | K26: 81.46 | L26: 2162500 | M26: 3608500 | N26: 97 | O26: 40 | P26: 3.73 | Q26: 37201 | R26: 138788 | S26: 184516 | T26: 94022 | U26: 166352 | V26: 1.67 | W26: 26 | X26: 23 | Y26: 176265375 | Z26: PL | BC26: 176265375
B27: 45986 | C27: 45986.459 | D27: Auction 4. Period CAP3 EU | E27: T3PA | F27: successful | G27: 81.19 | H27: 64 | I27: 150 | J27: 81.86 | K27: 80.99 | L27: 3268000 | M27: 4897000 | N27: 95 | O27: 29 | P27: 3.96 | Q27: 51547 | R27: 204042 | S27: 245490 | T27: 192235 | U27: 246799 | V27: 1.5 | W27: 24 | X27: 17 | Y27: 265328920 | Z27: EU | AA27: 2354510 | AB27: 4100095 | AC27: 6657580 | AD27: 852495 | AE27: 4384260 | AG27: 2313915 | AH27: 2029750 | AI27: 9012090 | AJ27: 20541070 | AK27: 3247600 | AL27: 12178500 | AM27: 933685 | AN27: 3491170 | AO27: 974280 | AP27: 20256905 | AQ27: 40595 | AR27: 20459880 | AS27: 29715540 | AT27: 0 | AU27: 649520 | AV27: 0 | AW27: 527735 | AX27: 50500180 | AY27: 405950 | AZ27: 19810360 | BA27: 7266505 | BB27: 1583205 | BD27: 4303070 | BE27: 3572360 | BF27: 1420825 | BG27: 28578880 | BH27: 1055470 | BI27: 2110940
B28: 45985 | C28: 45985.459 | D28: Auction 4. Period CAP3 EU | E28: T3PA | F28: successful | G28: 80 | H28: 64 | I28: 150 | J28: 80.87 | K28: 79.72 | L28: 3268000 | M28: 4831000 | N28: 86 | O28: 21 | P28: 4.3 | Q28: 56174 | R28: 241550 | S28: 303027 | T28: 297091 | U28: 303202 | V28: 1.48 | W28: 20 | X28: 11 | Y28: 261440000 | Z28: EU | AA28: 2320000 | AB28: 4040000 | AC28: 6560000 | AD28: 840000 | AE28: 4320000 | AG28: 2280000 | AH28: 2000000 | AI28: 8880000 | AJ28: 20240000 | AK28: 3200000 | AL28: 12000000 | AM28: 920000 | AN28: 3440000 | AO28: 960000 | AP28: 19960000 | AQ28: 40000 | AR28: 20160000 | AS28: 29280000 | AT28: 0 | AU28: 640000 | AV28: 0 | AW28: 520000 | AX28: 49760000 | AY28: 400000 | AZ28: 19520000 | BA28: 7160000 | BB28: 1560000 | BD28: 4240000 | BE28: 3520000 | BF28: 1400000 | BG28: 28160000 | BH28: 1040000 | BI28: 2080000
B29: 45982 | C29: 45982.459 | D29: Auction 4. Period DE | E29: T3PA | F29: successful | G29: 80.47 | H29: 64 | I29: 85 | J29: 80.24 | K29: 80.26 | L29: 1691000 | M29: 3215500 | N29: 85 | O29: 23 | P29: 3.7 | Q29: 37829 | R29: 139804 | S29: 231743 | T29: 130077 | U29: 263141 | V29: 1.9 | W29: 23 | X29: 13 | Y29: 136074770 | Z29: DE | AF29: 136074770
B30: 45981 | C30: 45981.459 | D30: Auction 4. Period CAP3 EU | E30: T3PA | F30: successful | G30: 81.16 | H30: 64 | I30: 93 | J30: 80.78 | K30: 80.77 | L30: 3268000 | M30: 5488000 | N30: 114 | O30: 24 | P30: 4.22 | Q30: 48140 | R30: 203259 | S30: 279429 | T30: 192235 | U30: 249320 | V30: 1.68 | W30: 27 | X30: 17 | Y30: 265230880 | Z30: EU | AA30: 2353640 | AB30: 4098580 | AC30: 6655120 | AD30: 852180 | AE30: 4382640 | AG30: 2313060 | AH30: 2029000 | AI30: 9008760 | AJ30: 20533480 | AK30: 3246400 | AL30: 12174000 | AM30: 933340 | AN30: 3489880 | AO30: 973920 | AP30: 20249420 | AQ30: 40580 | AR30: 20452320 | AS30: 29704560 | AT30: 0 | AU30: 649280 | AV30: 0 | AW30: 527540 | AX30: 50481520 | AY30: 405800 | AZ30: 19803040 | BA30: 7263820 | BB30: 1582620 | BD30: 4301480 | BE30: 3571040 | BF30: 1420300 | BG30: 28568320 | BH30: 1055080 | BI30: 2110160
B31: 45979 | C31: 45979.459 | D31: Auction 4. Period CAP3 EU | E31: T3PA | F31: successful | G31: 80.41 | H31: 64 | I31: 83 | J31: 80.03 | K31: 80.16 | L31: 3268000 | M31: 5781000 | N31: 114 | O31: 26 | P31: 4.07 | Q31: 50711 | R31: 206464 | S31: 307796 | T31: 192235 | U31: 326450 | V31: 1.77 | W31: 28 | X31: 17 | Y31: 262779880 | Z31: EU | AA31: 2331890 | AB31: 4060705 | AC31: 6593620 | AD31: 844305 | AE31: 4342140 | AG31: 2291685 | AH31: 2010250 | AI31: 8925510 | AJ31: 20343730 | AK31: 3216400 | AL31: 12061500 | AM31: 924715 | AN31: 3457630 | AO31: 964920 | AP31: 20062295 | AQ31: 40205 | AR31: 20263320 | AS31: 29430060 | AT31: 0 | AU31: 643280 | AV31: 0 | AW31: 522665 | AX31: 50015020 | AY31: 402050 | AZ31: 19620040 | BA31: 7196695 | BB31: 1567995 | BD31: 4261730 | BE31: 3538040 | BF31: 1407175 | BG31: 28304320 | BH31: 1045330 | BI31: 2090660
B32: 45978 | C32: 45978.459 | D32: Auction 4. Period CAP3 EU | E32: T3PA | F32: successful | G32: 80.25 | H32: 64 | I32: 85 | J32: 79.8 | K32: 80.03 | L32: 3268000 | M32: 5601000 | N32: 104 | O32: 23 | P32: 4.52 | Q32: 53856 | R32: 243522 | S32: 292389 | T32: 192235 | U32: 236355 | V32: 1.71 | W32: 23 | X32: 17 | Y32: 262257000 | Z32: EU | AA32: 2327250 | AB32: 4052625 | AC32: 6580500 | AD32: 842625 | AE32: 4333500 | AG32: 2287125 | AH32: 2006250 | AI32: 8907750 | AJ32: 20303250 | AK32: 3210000 | AL32: 12037500 | AM32: 922875 | AN32: 3450750 | AO32: 963000 | AP32: 20022375 | AQ32: 40125 | AR32: 20223000 | AS32: 29371500 | AT32: 0 | AU32: 642000 | AV32: 0 | AW32: 521625 | AX32: 49915500 | AY32: 401250 | AZ32: 19581000 | BA32: 7182375 | BB32: 1564875 | BD32: 4253250 | BE32: 3531000 | BF32: 1404375 | BG32: 28248000 | BH32: 1043250 | BI32: 2086500
B33: 45975 | C33: 45975.459 | D33: Auction 4. Period DE | E33: T3PA | F33: successful | G33: 80.85 | H33: 64 | I33: 82.33 | J33: 80.3 | K33: 80.67 | L33: 1691000 | M33: 3672000 | N33: 101 | O33: 31 | P33: 4.81 | Q33: 36356 | R33: 174857 | S33: 220569 | T33: 112733 | U33: 228377 | V33: 2.17 | W33: 21 | X33: 15 | Y33: 136717350 | Z33: DE | AF33: 136717350
B34: 45974 | C34: 45974.459 | D34: Auction 4. Period CAP3 EU | E34: T3PA | F34: successful | G34: 81.31 | H34: 64 | I34: 150 | J34: 82.83 | K34: 81.28 | L34: 3268000 | M34: 4987500 | N34: 106 | O34: 50 | P34: 4.08 | Q34: 47052 | R34: 191827 | S34: 244887 | T34: 142087 | U34: 226024 | V34: 1.53 | W34: 26 | X34: 23 | Y34: 265721080 | Z34: EU | AA34: 2357990 | AB34: 4106155 | AC34: 6667420 | AD34: 853755 | AE34: 4390740 | AG34: 2317335 | AH34: 2032750 | AI34: 9025410 | AJ34: 20571430 | AK34: 3252400 | AL34: 12196500 | AM34: 935065 | AN34: 3496330 | AO34: 975720 | AP34: 20286845 | AQ34: 40655 | AR34: 20490120 | AS34: 29759460 | AT34: 0 | AU34: 650480 | AV34: 0 | AW34: 528515 | AX34: 50574820 | AY34: 406550 | AZ34: 19839640 | BA34: 7277245 | BB34: 1585545 | BD34: 4309430 | BE34: 3577640 | BF34: 1422925 | BG34: 28621120 | BH34: 1057030 | BI34: 2114060
B35: 45973 | C35: 45973.459 | D35: Auction 4. Period CAP3 PL | E35: T3PA | F35: successful | G35: 81.51 | H35: 64 | I35: 150 | J35: 82.46 | K35: 81.43 | L35: 2162500 | M35: 3680000 | N35: 101 | O35: 39 | P35: 4.39 | Q35: 36436 | R35: 160000 | S35: 226599 | T35: 120139 | U35: 233479 | V35: 1.7 | W35: 23 | X35: 18 | Y35: 176265375 | Z35: PL | BC35: 176265375
B36: 45972 | C36: 45972.459 | D36: Auction 4. Period CAP3 EU | E36: T3PA | F36: successful | G36: 79.91 | H36: 64 | I36: 150 | J36: 80.2 | K36: 79.75 | L36: 3268000 | M36: 5425500 | N36: 112 | O36: 32 | P36: 4.15 | Q36: 48442 | R36: 200944 | S36: 267977 | T36: 148545 | U36: 265836 | V36: 1.66 | W36: 27 | X36: 22 | Y36: 261145880 | Z36: EU | AA36: 2317390 | AB36: 4035455 | AC36: 6552620 | AD36: 839055 | AE36: 4315140 | AG36: 2277435 | AH36: 1997750 | AI36: 8870010 | AJ36: 20217230 | AK36: 3196400 | AL36: 11986500 | AM36: 918965 | AN36: 3436130 | AO36: 958920 | AP36: 19937545 | AQ36: 39955 | AR36: 20137320 | AS36: 29247060 | AT36: 0 | AU36: 639280 | AV36: 0 | AW36: 519415 | AX36: 49704020 | AY36: 399550 | AZ36: 19498040 | BA36: 7151945 | BB36: 1558245 | BD36: 4235230 | BE36: 3516040 | BF36: 1398425 | BG36: 28128320 | BH36: 1038830 | BI36: 2077660
B37: 45971 | C37: 45971.459 | D37: Auction 4. Period CAP3 EU | E37: T3PA | F37: successful | G37: 79.97 | H37: 64 | I37: 91.74 | J37: 79.76 | K37: 79.65 | L37: 3268000 | M37: 5037500 | N37: 110 | O37: 26 | P37: 4.78 | Q37: 45795 | R37: 219022 | S37: 310378 | T37: 217867 | U37: 315534 | V37: 1.54 | W37: 23 | X37: 15 | Y37: 261341960 | Z37: EU | AA37: 2319130 | AB37: 4038485 | AC37: 6557540 | AD37: 839685 | AE37: 4318380 | AG37: 2279145 | AH37: 1999250 | AI37: 8876670 | AJ37: 20232410 | AK37: 3198800 | AL37: 11995500 | AM37: 919655 | AN37: 3438710 | AO37: 959640 | AP37: 19952515 | AQ37: 39985 | AR37: 20152440 | AS37: 29269020 | AT37: 0 | AU37: 639760 | AV37: 0 | AW37: 519805 | AX37: 49741340 | AY37: 399850 | AZ37: 19512680 | BA37: 7157315 | BB37: 1559415 | BD37: 4238410 | BE37: 3518680 | BF37: 1399475 | BG37: 28149440 | BH37: 1039610 | BI37: 2079220
B38: 45968 | C38: 45968.459 | D38: Auction 4. Period DE | E38: T3PA | F38: successful | G38: 79.76 | H38: 64 | I38: 100 | J38: 79.77 | K38: 79.6 | L38: 1691000 | M38: 3252000 | N38: 90 | O38: 30 | P38: 4.09 | Q38: 36133 | R38: 147818 | S38: 182050 | T38: 99471 | U38: 171680 | V38: 1.92 | W38: 22 | X38: 17 | Y38: 134874160 | Z38: DE | AF38: 134874160
B39: 45967 | C39: 45967.459 | D39: Auction 4. Period CAP3 EU | E39: T3PA | F39: successful | G39: 80.07 | H39: 64 | I39: 120 | J39: 80.75 | K39: 80 | L39: 3268000 | M39: 5005000 | N39: 106 | O39: 40 | P39: 3.66 | Q39: 47217 | R39: 172586 | S39: 219399 | T39: 136167 | U39: 186718 | V39: 1.53 | W39: 29 | X39: 24 | Y39: 261668760 | Z39: EU | AA39: 2322030 | AB39: 4043535 | AC39: 6565740 | AD39: 840735 | AE39: 4323780 | AG39: 2281995 | AH39: 2001750 | AI39: 8887770 | AJ39: 20257710 | AK39: 3202800 | AL39: 12010500 | AM39: 920805 | AN39: 3443010 | AO39: 960840 | AP39: 19977465 | AQ39: 40035 | AR39: 20177640 | AS39: 29305620 | AT39: 0 | AU39: 640560 | AV39: 0 | AW39: 520455 | AX39: 49803540 | AY39: 400350 | AZ39: 19537080 | BA39: 7166265 | BB39: 1561365 | BD39: 4243710 | BE39: 3523080 | BF39: 1401225 | BG39: 28184640 | BH39: 1040910 | BI39: 2081820
B40: 45965 | C40: 45965.459 | D40: Auction 4. Period CAP3 EU | E40: T3PA | F40: successful | G40: 81.26 | H40: 64 | I40: 150 | J40: 81.48 | K40: 81.03 | L40: 3268000 | M40: 5237500 | N40: 100 | O40: 28 | P40: 3.85 | Q40: 52375 | R40: 201442 | S40: 237779 | T40: 204250 | U40: 205955 | V40: 1.6 | W40: 26 | X40: 16 | Y40: 265557680 | Z40: EU | AA40: 2356540 | AB40: 4103630 | AC40: 6663320 | AD40: 853230 | AE40: 4388040 | AG40: 2315910 | AH40: 2031500 | AI40: 9019860 | AJ40: 20558780 | AK40: 3250400 | AL40: 12189000 | AM40: 934490 | AN40: 3494180 | AO40: 975120 | AP40: 20274370 | AQ40: 40630 | AR40: 20477520 | AS40: 29741160 | AT40: 0 | AU40: 650080 | AV40: 0 | AW40: 528190 | AX40: 50543720 | AY40: 406300 | AZ40: 19827440 | BA40: 7272770 | BB40: 1584570 | BD40: 4306780 | BE40: 3575440 | BF40: 1422050 | BG40: 28603520 | BH40: 1056380 | BI40: 2112760
B41: 45964 | C41: 45964.459 | D41: Auction 4. Period CAP3 EU | E41: T3PA | F41: successful | G41: 79.3 | H41: 64 | I41: 85 | J41: 78.87 | K41: 78.99 | L41: 3268000 | M41: 5272000 | N41: 95 | O41: 23 | P41: 3.96 | Q41: 55495 | R41: 219667 | S41: 309204 | T41: 217867 | U41: 298303 | V41: 1.61 | W41: 24 | X41: 15 | Y41: 259152400 | Z41: EU | AA41: 2299700 | AB41: 4004650 | AC41: 6502600 | AD41: 832650 | AE41: 4282200 | AG41: 2260050 | AH41: 1982500 | AI41: 8802300 | AJ41: 20062900 | AK41: 3172000 | AL41: 11895000 | AM41: 911950 | AN41: 3409900 | AO41: 951600 | AP41: 19785350 | AQ41: 39650 | AR41: 19983600 | AS41: 29023800 | AT41: 0 | AU41: 634400 | AV41: 0 | AW41: 515450 | AX41: 49324600 | AY41: 396500 | AZ41: 19349200 | BA41: 7097350 | BB41: 1546350 | BD41: 4202900 | BE41: 3489200 | BF41: 1387750 | BG41: 27913600 | BH41: 1030900 | BI41: 2061800
B42: 45961 | C42: 45961.459 | D42: Auction 4. Period DE | E42: T3PA | F42: successful | G42: 78.66 | H42: 0.01 | I42: 85 | J42: 77.4 | K42: 78.51 | L42: 1691000 | M42: 3390500 | N42: 78 | O42: 24 | P42: 3.71 | Q42: 43468 | R42: 161452 | S42: 228933 | T42: 105688 | U42: 236311 | V42: 2.01 | W42: 21 | X42: 16 | Y42: 133014060 | Z42: DE | AF42: 133014060
B43: 45960 | C43: 45960.459 | D43: Auction 4. Period CAP3 EU | E43: T3PA | F43: successful | G43: 78.71 | H43: 64 | I43: 150 | J43: 80.16 | K43: 78.51 | L43: 3268000 | M43: 5240000 | N43: 88 | O43: 28 | P43: 4 | Q43: 59545 | R43: 238182 | S43: 324151 | T43: 217867 | U43: 327356 | V43: 1.6 | W43: 22 | X43: 15 | Y43: 257224280 | Z43: EU | AA43: 2282590 | AB43: 3974855 | AC43: 6454220 | AD43: 826455 | AE43: 4250340 | AG43: 2243235 | AH43: 1967750 | AI43: 8736810 | AJ43: 19913630 | AK43: 3148400 | AL43: 11806500 | AM43: 905165 | AN43: 3384530 | AO43: 944520 | AP43: 19638145 | AQ43: 39355 | AR43: 19834920 | AS43: 28807860 | AT43: 0 | AU43: 629680 | AV43: 0 | AW43: 511615 | AX43: 48957620 | AY43: 393550 | AZ43: 19205240 | BA43: 7044545 | BB43: 1534845 | BD43: 4171630 | BE43: 3463240 | BF43: 1377425 | BG43: 27705920 | BH43: 1023230 | BI43: 2046460
...

Sheet Inflation and WACC
B2: Denmark
D3: 2006M04 | E3: 2006M05 | F3: 2006M06 | G3: 2006M07 | H3: 2006M08 | I3: 2006M09 | J3: 2006M10 | K3: 2006M11 | L3: 2006M12 | M3: 2007M01 | N3: 2007M02 | O3: 2007M03 | P3: 2007M04 | Q3: 2007M05 | R3: 2007M06 | S3: 2007M07 | T3: 2007M08 | U3: 2007M09 | V3: 2007M10 | W3: 2007M11 | X3: 2007M12 | Y3: 2008M01 | Z3: 2008M02 | AA3: 2008M03 | AB3: 2008M04 | AC3: 2008M05 | AD3: 2008M06 | AE3: 2008M07 | AF3: 2008M08 | AG3: 2008M09 | AH3: 2008M10 | AI3: 2008M11 | AJ3: 2008M12 | AK3: 2009M01 | AL3: 2009M02 | AM3: 2009M03 | AN3: 2009M04 | AO3: 2009M05 | AP3: 2009M06 | AQ3: 2009M07 | AR3: 2009M08 | AS3: 2009M09 | AT3: 2009M10 | AU3: 2009M11 | AV3: 2009M12 | AW3: 2010M01 | AX3: 2010M02 | AY3: 2010M03 | AZ3: 2010M04 | BA3: 2010M05 | BB3: 2010M06 | BC3: 2010M07 | BD3: 2010M08 | BE3: 2010M09 | BF3: 2010M10 | BG3: 2010M11 | BH3: 2010M12 | BI3: 2011M01 | BJ3: 2011M02 | BK3: 2011M03 | BL3: 2011M04 | BM3: 2011M05 | BN3: 2011M06 | BO3: 2011M07 | BP3: 2011M08 | BQ3: 2011M09 | BR3: 2011M10 | BS3: 2011M11 | BT3: 2011M12 | BU3: 2012M01 | BV3: 2012M02 | BW3: 2012M03 | BX3: 2012M04 | BY3: 2012M05 | BZ3: 2012M06 | CA3: 2012M07 | CB3: 2012M08 | CC3: 2012M09 | CD3: 2012M10 | CE3: 2012M11 | CF3: 2012M12 | CG3: 2013M01 | CH3: 2013M02 | CI3: 2013M03 | CJ3: 2013M04 | CK3: 2013M05 | CL3: 2013M06 | CM3: 2013M07 | CN3: 2013M08 | CO3: 2013M09 | CP3: 2013M10 | CQ3: 2013M11 | CR3: 2013M12 | CS3: 2014M01 | CT3: 2014M02 | CU3: 2014M03 | CV3: 2014M04 | CW3: 2014M05 | CX3: 2014M06 | CY3: 2014M07 | CZ3: 2014M08 | DA3: 2014M09 | DB3: 2014M10 | DC3: 2014M11 | DD3: 2014M12 | DE3: 2015M01 | DF3: 2015M02 | DG3: 2015M03 | DH3: 2015M04 | DI3: 2015M05 | DJ3: 2015M06 | DK3: 2015M07 | DL3: 2015M08 | DM3: 2015M09 | DN3: 2015M10 | DO3: 2015M11 | DP3: 2015M12 | DQ3: 2016M01 | DR3: 2016M02 | DS3: 2016M03 | DT3: 2016M04 | DU3: 2016M05 | DV3: 2016M06 | DW3: 2016M07 | DX3: 2016M08 | DY3: 2016M09 | DZ3: 2016M10 | EA3: 2016M11 | EB3: 2016M12 | EC3: 2017M01 | ED3: 2017M02 | EE3: 2017M03 | EF3: 2017M04 | EG3: 2017M05 | EH3: 2017M06 | EI3: 2017M07 | EJ3: 2017M08 | EK3: 2017M09 | EL3: 2017M10 | EM3: 2017M11 | EN3: 2017M12 | EO3: 2018M01 | EP3: 2018M02 | EQ3: 2018M03 | ER3: 2018M04 | ES3: 2018M05 | ET3: 2018M06 | EU3: 2018M07 | EV3: 2018M08 | EW3: 2018M09 | EX3: 2018M10 | EY3: 2018M11 | EZ3: 2018M12 | FA3: 2019M01 | FB3: 2019M02 | FC3: 2019M03 | FD3: 2019M04 | FE3: 2019M05 | FF3: 2019M06 | FG3: 2019M07 | FH3: 2019M08 | FI3: 2019M09 | FJ3: 2019M10 | FK3: 2019M11 | FL3: 2019M12 | FM3: 2020M01 | FN3: 2020M02 | FO3: 2020M03 | FP3: 2020M04 | FQ3: 2020M05 | FR3: 2020M06 | FS3: 2020M07 | FT3: 2020M08 | FU3: 2020M09 | FV3: 2020M10 | FW3: 2020M11 | FX3: 2020M12 | FY3: 2021M01 | FZ3: 2021M02 | GA3: 2021M03 | GB3: 2021M04 | GC3: 2021M05 | GD3: 2021M06 | GE3: 2021M07 | GF3: 2021M08 | GG3: 2021M09 | GH3: 2021M10 | GI3: 2021M11 | GJ3: 2021M12 | GK3: 2022M01 | GL3: 2022M02 | GM3: 2022M03 | GN3: 2022M04 | GO3: 2022M05 | GP3: 2022M06 | GQ3: 2022M07 | GR3: 2022M08 | GS3: 2022M09 | GT3: 2022M10 | GU3: 2022M11 | GV3: 2022M12 | GW3: 2023M01 | GX3: 2023M02 | GY3: 2023M03 | GZ3: 2023M04 | HA3: 2023M05 | HB3: 2023M06 | HC3: 2023M07 | HD3: 2023M08 | HE3: 2023M09 | HF3: 2023M10 | HG3: 2023M11 | HH3: 2023M12 | HI3: 2024M01 | HJ3: 2024M02 | HK3: 2024M03 | HL3: 2024M04 | HM3: 2024M05 | HN3: 2024M06 | HO3: 2024M07 | HP3: 2024M08 | HQ3: 2024M09 | HR3: 2024M10 | HS3: 2024M11 | HT3: 2024M12 | HU3: 2025M01 | HV3: 2025M02 | HW3: 2025M03 | HX3: 2025M04 | HY3: 2025M05 | HZ3: 2025M06 | IA3: 2025M07 | IB3: 2025M08 | IC3: 2025M09 | ID3: 2025M10 | IE3: 2025M11 | IF3: 2025M12 | IG3: 2026M01 | IH3: 2026M02 | II3: 2026M03 | IJ3: 2026M04
B4: Percentage change compared to same month the year before (per cent) | C4: 00 Consumer price index, total | D4: 1.9 | E4: 2 | F4: 2.1 | G4: 2 | H4: 2 | I4: 1.6 | J4: 1.5 | K4: 1.8 | L4: 1.7 | M4: 1.8 | N4: 1.9 | O4: 2 | P4: 1.7 | Q4: 1.8 | R4: 1.4 | S4: 1.2 | T4: 1 | U4: 1.3 | V4: 1.7 | W4: 2.4 | X4: 2.4 | Y4: 2.9 | Z4: 3.1 | AA4: 3.1 | AB4: 3.2 | AC4: 3.4 | AD4: 3.8 | AE4: 4 | AF4: 4.4 | AG4: 4.2 | AH4: 3.7 | AI4: 2.7 | AJ4: 2.4 | AK4: 1.8 | AL4: 1.9 | AM4: 1.7 | AN4: 1.3 | AO4: 1.3 | AP4: 1.2 | AQ4: 1 | AR4: 1.1 | AS4: 0.8 | AT4: 1 | AU4: 1.3 | AV4: 1.4 | AW4: 2 | AX4: 2 | AY4: 2.3 | AZ4: 2.5 | BA4: 2.1 | BB4: 1.8 | BC4: 2.3 | BD4: 2.4 | BE4: 2.6 | BF4: 2.4 | BG4: 2.5 | BH4: 2.8 | BI4: 2.7 | BJ4: 2.7 | BK4: 2.7 | BL4: 2.9 | BM4: 3.1 | BN4: 3 | BO4: 3 | BP4: 2.6 | BQ4: 2.5 | BR4: 2.8 | BS4: 2.6 | BT4: 2.5 | BU4: 2.8 | BV4: 2.8 | BW4: 2.7 | BX4: 2.3 | BY4: 2.2 | BZ4: 2.2 | CA4: 2.3 | CB4: 2.7 | CC4: 2.6 | CD4: 2.3 | CE4: 2.3 | CF4: 2 | CG4: 1.2 | CH4: 1.2 | CI4: 0.9 | CJ4: 0.8 | CK4: 0.9 | CL4: 0.9 | CM4: 0.7 | CN4: 0.4 | CO4: 0.5 | CP4: 0.6 | CQ4: 0.6 | CR4: 0.8 | CS4: 1 | CT4: 0.5 | CU4: 0.4 | CV4: 0.7 | CW4: 0.5 | CX4: 0.6 | CY4: 0.7 | CZ4: 0.5 | DA4: 0.5 | DB4: 0.5 | DC4: 0.5 | DD4: 0.3 | DE4: -0.1 | DF4: 0.3 | DG4: 0.6 | DH4: 0.6 | DI4: 0.6 | DJ4: 0.6 | DK4: 0.7 | DL4: 0.6 | DM4: 0.5 | DN4: 0.4 | DO4: 0.3 | DP4: 0.5 | DQ4: 0.6 | DR4: 0.3 | DS4: -0.1 | DT4: 0 | DU4: 0.2 | DV4: 0.3 | DW4: 0.3 | DX4: 0.3 | DY4: 0 | DZ4: 0.3 | EA4: 0.4 | EB4: 0.5 | EC4: 0.9 | ED4: 1 | EE4: 1 | EF4: 1.1 | EG4: 0.8 | EH4: 0.6 | EI4: 1.5 | EJ4: 1.5 | EK4: 1.6 | EL4: 1.5 | EM4: 1.3 | EN4: 0.9 | EO4: 0.7 | EP4: 0.6 | EQ4: 0.6 | ER4: 0.8 | ES4: 1.1 | ET4: 1.1 | EU4: 1.1 | EV4: 1 | EW4: 0.6 | EX4: 0.8 | EY4: 0.8 | EZ4: 0.8 | FA4: 1.3 | FB4: 1 | FC4: 1.2 | FD4: 0.9 | FE4: 0.7 | FF4: 0.5 | FG4: 0.3 | FH4: 0.4 | FI4: 0.5 | FJ4: 0.5 | FK4: 0.7 | FL4: 0.8 | FM4: 0.7 | FN4: 0.8 | FO4: 0.4 | FP4: 0 | FQ4: -0.1 | FR4: 0.3 | FS4: 0.5 | FT4: 0.5 | FU4: 0.5 | FV4: 0.4 | FW4: 0.5 | FX4: 0.5 | FY4: 0.5 | FZ4: 0.6 | GA4: 0.9 | GB4: 1.4 | GC4: 1.8 | GD4: 1.8 | GE4: 1.6 | GF4: 1.8 | GG4: 2.2 | GH4: 2.9 | GI4: 3.4 | GJ4: 3.1 | GK4: 4.4 | GL4: 4.8 | GM4: 5.4 | GN4: 6.7 | GO4: 7.4 | GP4: 8.2 | GQ4: 8.7 | GR4: 8.9 | GS4: 10 | GT4: 10.2 | GU4: 8.9 | GV4: 8.7 | GW4: 7.7 | GX4: 7.6 | GY4: 6.8 | GZ4: 5.3 | HA4: 2.9 | HB4: 2.4 | HC4: 3.2 | HD4: 2.4 | HE4: 0.9 | HF4: 0 | HG4: 0.6 | HH4: 0.7 | HI4: 1.2 | HJ4: 0.8 | HK4: 0.9 | HL4: 0.7 | HM4: 2.1 | HN4: 1.8 | HO4: 1.1 | HP4: 1.4 | HQ4: 1.3 | HR4: 1.6 | HS4: 1.7 | HT4: 1.9 | HU4: 1.5 | HV4: 2 | HW4: 1.5 | HX4: 1.6 | HY4: 1.6 | HZ4: 1.8 | IA4: 2.2 | IB4: 2 | IC4: 2.2 | ID4: 2.1 | IE4: 2.1 | IF4: 1.9 | IG4: 0.8 | IH4: 0.7 | II4: 1.2 | IJ4: 1.4
B6: Average Inflation Denmark 2016-2025 | C6: =AVERAGE(DQ4:IF4) -> 1.9533333 | D6: %
B8: Net price index by unit, commodity group and time
B9: Unit: -
D10: 2006M05 | E10: 2006M06 | F10: 2006M07 | G10: 2006M08 | H10: 2006M09 | I10: 2006M10 | J10: 2006M11 | K10: 2006M12 | L10: 2007M01 | M10: 2007M02 | N10: 2007M03 | O10: 2007M04 | P10: 2007M05 | Q10: 2007M06 | R10: 2007M07 | S10: 2007M08 | T10: 2007M09 | U10: 2007M10 | V10: 2007M11 | W10: 2007M12 | X10: 2008M01 | Y10: 2008M02 | Z10: 2008M03 | AA10: 2008M04 | AB10: 2008M05 | AC10: 2008M06 | AD10: 2008M07 | AE10: 2008M08 | AF10: 2008M09 | AG10: 2008M10 | AH10: 2008M11 | AI10: 2008M12 | AJ10: 2009M01 | AK10: 2009M02 | AL10: 2009M03 | AM10: 2009M04 | AN10: 2009M05 | AO10: 2009M06 | AP10: 2009M07 | AQ10: 2009M08 | AR10: 2009M09 | AS10: 2009M10 | AT10: 2009M11 | AU10: 2009M12 | AV10: 2010M01 | AW10: 2010M02 | AX10: 2010M03 | AY10: 2010M04 | AZ10: 2010M05 | BA10: 2010M06 | BB10: 2010M07 | BC10: 2010M08 | BD10: 2010M09 | BE10: 2010M10 | BF10: 2010M11 | BG10: 2010M12 | BH10: 2011M01 | BI10: 2011M02 | BJ10: 2011M03 | BK10: 2011M04 | BL10: 2011M05 | BM10: 2011M06 | BN10: 2011M07 | BO10: 2011M08 | BP10: 2011M09 | BQ10: 2011M10 | BR10: 2011M11 | BS10: 2011M12 | BT10: 2012M01 | BU10: 2012M02 | BV10: 2012M03 | BW10: 2012M04 | BX10: 2012M05 | BY10: 2012M06 | BZ10: 2012M07 | CA10: 2012M08 | CB10: 2012M09 | CC10: 2012M10 | CD10: 2012M11 | CE10: 2012M12 | CF10: 2013M01 | CG10: 2013M02 | CH10: 2013M03 | CI10: 2013M04 | CJ10: 2013M05 | CK10: 2013M06 | CL10: 2013M07 | CM10: 2013M08 | CN10: 2013M09 | CO10: 2013M10 | CP10: 2013M11 | CQ10: 2013M12 | CR10: 2014M01 | CS10: 2014M02 | CT10: 2014M03 | CU10: 2014M04 | CV10: 2014M05 | CW10: 2014M06 | CX10: 2014M07 | CY10: 2014M08 | CZ10: 2014M09 | DA10: 2014M10 | DB10: 2014M11 | DC10: 2014M12 | DD10: 2015M01 | DE10: 2015M02 | DF10: 2015M03 | DG10: 2015M04 | DH10: 2015M05 | DI10: 2015M06 | DJ10: 2015M07 | DK10: 2015M08 | DL10: 2015M09 | DM10: 2015M10 | DN10: 2015M11 | DO10: 2015M12 | DP10: 2016M01 | DQ10: 2016M02 | DR10: 2016M03 | DS10: 2016M04 | DT10: 2016M05 | DU10: 2016M06 | DV10: 2016M07 | DW10: 2016M08 | DX10: 2016M09 | DY10: 2016M10 | DZ10: 2016M11 | EA10: 2016M12 | EB10: 2017M01 | EC10: 2017M02 | ED10: 2017M03 | EE10: 2017M04 | EF10: 2017M05 | EG10: 2017M06 | EH10: 2017M07 | EI10: 2017M08 | EJ10: 2017M09 | EK10: 2017M10 | EL10: 2017M11 | EM10: 2017M12 | EN10: 2018M01 | EO10: 2018M02 | EP10: 2018M03 | EQ10: 2018M04 | ER10: 2018M05 | ES10: 2018M06 | ET10: 2018M07 | EU10: 2018M08 | EV10: 2018M09 | EW10: 2018M10 | EX10: 2018M11 | EY10: 2018M12 | EZ10: 2019M01 | FA10: 2019M02 | FB10: 2019M03 | FC10: 2019M04 | FD10: 2019M05 | FE10: 2019M06 | FF10: 2019M07 | FG10: 2019M08 | FH10: 2019M09 | FI10: 2019M10 | FJ10: 2019M11 | FK10: 2019M12 | FL10: 2020M01 | FM10: 2020M02 | FN10: 2020M03 | FO10: 2020M04 | FP10: 2020M05 | FQ10: 2020M06 | FR10: 2020M07 | FS10: 2020M08 | FT10: 2020M09 | FU10: 2020M10 | FV10: 2020M11 | FW10: 2020M12 | FX10: 2021M01 | FY10: 2021M02 | FZ10: 2021M03 | GA10: 2021M04 | GB10: 2021M05 | GC10: 2021M06 | GD10: 2021M07 | GE10: 2021M08 | GF10: 2021M09 | GG10: 2021M10 | GH10: 2021M11 | GI10: 2021M12 | GJ10: 2022M01 | GK10: 2022M02 | GL10: 2022M03 | GM10: 2022M04 | GN10: 2022M05 | GO10: 2022M06 | GP10: 2022M07 | GQ10: 2022M08 | GR10: 2022M09 | GS10: 2022M10 | GT10: 2022M11 | GU10: 2022M12 | GV10: 2023M01 | GW10: 2023M02 | GX10: 2023M03 | GY10: 2023M04 | GZ10: 2023M05 | HA10: 2023M06 | HB10: 2023M07 | HC10: 2023M08 | HD10: 2023M09 | HE10: 2023M10 | HF10: 2023M11 | HG10: 2023M12 | HH10: 2024M01 | HI10: 2024M02 | HJ10: 2024M03 | HK10: 2024M04 | HL10: 2024M05 | HM10: 2024M06 | HN10: 2024M07 | HO10: 2024M08 | HP10: 2024M09 | HQ10: 2024M10 | HR10: 2024M11 | HS10: 2024M12 | HT10: 2025M01 | HU10: 2025M02 | HV10: 2025M03 | HW10: 2025M04 | HX10: 2025M05 | HY10: 2025M06 | HZ10: 2025M07 | IA10: 2025M08 | IB10: 2025M09 | IC10: 2025M10 | ID10: 2025M11 | IE10: 2025M12 | IF10: 2026M01 | IG10: 2026M02 | IH10: 2026M03 | II10: 2026M04 | IJ10: 2026M05
