Workbook

Sheet Index
C3: Offshore windfarm LCOE Model (DCF Method)
C8: ="-------->" -> --------> | D8: Input Values | I8: Index
I9: 1 | J9: CAPEX Inputs
I10: 2 | J10: Financial Parameter Inputs
B11: Color Indications (in Project Timeline) | I11: 3 | J11: OPEX Inputs
I12: 4 | J12: AEP Inputs
C13: ="-------->" -> --------> | D13: Development | I13: 5 | J13: Summary
C14: ="-------->" -> --------> | D14: Financial Close | I14: 6 | J14: DCF Calculations
C15: ="-------->" -> --------> | D15: Construction | I15: 7 | J15: Results
C16: ="-------->" -> --------> | D16: Operation
C17: ="-------->" -> --------> | D17: Decommissioned
B19: R | C19: ="-------->" -> --------> | D19: Real
B20: N | C20: ="-------->" -> --------> | D20: Nominal

Sheet CAPEX-Input
C2: (mil.EUR) | D2: (mil.EUR/MW)
B3: Cost Categories | C3: Total Cost | D3: Specific Cost | E3: % | K3: Offshore Wind farm parameters | L3: Inputs | M3: Units
A4: 1 | B4: Development cost | C4: 89.25 | D4: =C4/$L$5 -> 0.119 | E4: =CAPEX_result[[#This Row],[Specific Cost ]]/$D$29 -> 0.044403956 | K4: Name | L4: …
A5: 2 | B5: Turbine supply | C5: 1000 | D5: =C5/$L$5 -> 1.3333333 | E5: =CAPEX_result[[#This Row],[Specific Cost ]]/$D$29 -> 0.49752331 | K5: Farm Size | L5: 750 | M5: (MW)
B6: Monopile | C6: 145 | D6: =C6/$L$5 -> 0.19333333 | K6: Turbine Nameplate Capacity | L6: 10 | M6: (MW )
B7: Transition Piece | C7: 30 | D7: =C7/$L$5 -> 0.04 | K7: Number of Turbines | L7: =L5/L6 -> 75
B8: Secondary Steel Structures | C8: 39 | D8: =C8/$L$5 -> 0.052 | K8: Water Depth | L8: 35 | M8: (metres)
A9: 3 | B9: Foundation | C9: =SUM(C6:C8) -> 214 | D9: =C9/$L$5 -> 0.28533333 | E9: =CAPEX_result[[#This Row],[Specific Cost ]]/$D$29 -> 0.10646999 | K9: Distance to shore | L9: 70 | M9: (km)
B10: Dredging & Survey | C10: 8.35 | D10: =C10/$L$5 -> 0.011133333 | K10: Foundation Type | L10: Monopile
B11: Foundation & TP Install | C11: 59.742188 | D11: =C11/$L$5 -> 0.07965625 | K11: Rotor Diameter | L11: 154
B12: Turbine Install | C12: 59.94 | D12: =C12/$L$5 -> 0.07992 | K12: Hub Height | L12: 110
B13: Scour protection | C13: 11.25 | D13: =C13/$L$5 -> 0.015
B14: PLGR | C14: 0.1885 | D14: =C14/$L$5 -> 0.00025133333 | K14: Inter array Cable Voltage | L14: 66 | M14: (kV)
B15: Array Cable Install | C15: 29.75625 | D15: =C15/$L$5 -> 0.039675 | K15: Export Cable Voltage | L15: 220 | M15: (kV)
B16: Substation Install | C16: 12.15 | D16: =C16/$L$5 -> 0.0162 | K16: Export Cable Size | L16: 1600 | M16: (mm2)
B17: Export Cable Install | C17: 45.696 | D17: =C17/$L$5 -> 0.060928
B18: Onshore Electrical supply & install | C18: 45 | D18: =0.12 -> 0.12
A19: 4 | B19: Installation | C19: =SUM(C10:C18) -> 272.07294 | D19: =C19/$L$5 -> 0.36276392 | E19: =CAPEX_result[[#This Row],[Specific Cost ]]/$D$29 -> 0.13536263
B20: Inter-Array Cable Supply | C20: 24.602769 | D20: =C20/$L$5 -> 0.032803691 | L20: (mil.EUR)
B21: Offshore Substation Supply | C21: 61.305 | D21: =C21/$L$5 -> 0.08174 | K21: Transmission Cost (Connection to Grid) | L21: Total Cost
B22: Offshore Export Cable Supply | C22: 144.704 | D22: =C22/$L$5 -> 0.19293867 | K22: Substation supply | L22: =$C$21 -> 61.305
A23: 5 | B23: Electrical Infrastructure (Until Landfall) | C23: =SUM(C20:C22) -> 230.61177 | D23: =C23/$L$5 -> 0.30748236 | E23: =CAPEX_result[[#This Row],[Specific Cost ]]/$D$29 -> 0.11473473 | K23: Export cable supply | L23: =$C$22 -> 144.704
B24: Construction Insurance | C24: 33.75 | D24: =C24/$L$5 -> 0.045 | K24: Installation | L24: =SUM($C$16:$C$17) -> 57.846
B25: Project Management | C25: 83.059201 | D25: =C25/$L$5 -> 0.1107456 | K25: Onshore Electrical supply & install | L25: =$C$18 -> 45
B26: Contingency | C26: 87.212161 | D26: =C26/$L$5 -> 0.11628288 | K26: Total | L26: =SUM(L22:L25) -> 308.855
A27: 6 | B27: Other CAPEX | C27: =SUM(C24:C26) -> 204.02136 | D27: =C27/$L$5 -> 0.27202848 | E27: =CAPEX_result[[#This Row],[Specific Cost ]]/$D$29 -> 0.10150538 | K27: OPEX assumptions (1% of Transmission CAPEX ) | L27: =L26*1% -> 3.08855
B29: Total CAPEX | C29: =SUM(C4:C5,C9,C19,C23,C27) -> 2009.9561 | D29: =SUM(D4:D5,D9,D19,D23,D27) -> 2.6799414 | E29: 1
B31: DECOM (65% of installation Cost) | C31: =C19*0.65 -> 176.84741 | D31: =C31/L5 -> 0.23579655

Sheet FIN_Inputs&ProjectTimeline
B2: General Inputs
B3: Currency | C3: EUR
B4: FID Year | C4: Year 0 in project timeline
B5: Input Terms (EUR) | C5: Real EUR in FID Year
B6: Output Terms (EUR) | C6: Real EUR in FID Year
B7: Inflation rate % | C7: 0.02
B8: Operational Years | C8: 25
B10: Capital Structure (Project Finance)
B11: Debt | C11: 0.7
B12: Equity | C12: =1-$C$11 -> 0.3
B13: Debt-to-Equity Ratio | C13: =C11/C12 -> 2.3333333
B14: Debt rate | C14: 0.04
B15: Equity rate | C15: 0.08
B16: Effective Corporate Tax Rate | C16: 0.25
B18: WACC
B19: WACC (Nominal Pre-tax) | C19: =C11*C14+C12*C15 -> 0.052
B20: WACC (Nominal Post-tax) | C20: =(C11*C14*(1-C16))+C12*C15 -> 0.045
B21: WACC (Real Pre-tax) | C21: =((1+C19)/(1+C7))-1 -> 0.031372549
B22: WACC (Real Post-tax) | C22: =((1+C20)/(1+C7))-1 -> 0.024509804
B24: Depreciation
B25: Method | C25: Straight Line | G25: Depreciation options
B26: (Dep. Rate if Declining Balance Method) | C26: 0.2 | G26: Straight Line | H26: Declining Balance
B28: Windfarm Earnings Assumptions
B29: Subsidy | C29: 53.25 | D29: (EUR/MWh)
B30: Subsidy Period | C30: 15 | D30: (Years) | F30: (Change the binary values in Earnings Assumption below, if different subsidy periods are considered)
B31: Electricity Price | C31: 50 | D31: (EUR/MWh)
B33: Project Timeline | C33: (Proportion in the table represents the expenditure/plant operation)
B34: Asset life (Year) | D34: -4 | E34: -3 | F34: -2 | G34: -1 | H34: 0 | I34: 1 | J34: 2 | K34: 3 | L34: 4 | M34: 5 | N34: 6 | O34: 7 | P34: 8 | Q34: 9 | R34: 10 | S34: 11 | T34: 12 | U34: 13 | V34: 14 | W34: 15 | X34: 16 | Y34: 17 | Z34: 18 | AA34: 19 | AB34: 20 | AC34: 21 | AD34: 22 | AE34: 23 | AF34: 24 | AG34: 25 | AH34: 26 | AI34: 27 | AJ34: 28
B35: Wind Farm Operation (1/0) | D35: 0 | E35: 0 | F35: 0 | G35: 0 | H35: 0 | I35: 0 | J35: 1 | K35: 1 | L35: 1 | M35: 1 | N35: 1 | O35: 1 | P35: 1 | Q35: 1 | R35: 1 | S35: 1 | T35: 1 | U35: 1 | V35: 1 | W35: 1 | X35: 1 | Y35: 1 | Z35: 1 | AA35: 1 | AB35: 1 | AC35: 1 | AD35: 1 | AE35: 1 | AF35: 1 | AG35: 1 | AH35: 1 | AI35: 0 | AJ35: 0
B36: Project Development | D36: 0.1 | E36: 0.1 | F36: 0.4 | G36: 0.4 | H36: 0 | I36: 0 | J36: 0 | K36: 0 | L36: 0 | M36: 0 | N36: 0 | O36: 0 | P36: 0 | Q36: 0 | R36: 0 | S36: 0 | T36: 0 | U36: 0 | V36: 0 | W36: 0 | X36: 0 | Y36: 0 | Z36: 0 | AA36: 0 | AB36: 0 | AC36: 0 | AD36: 0 | AE36: 0 | AF36: 0 | AG36: 0 | AH36: 0 | AI36: 0 | AJ36: 0
B37: Financial Close | D37: 0 | E37: 0 | F37: 0 | G37: 0 | H37: ="FID" -> FID | I37: 0 | J37: 0 | K37: 0 | L37: 0 | M37: 0 | N37: 0 | O37: 0 | P37: 0 | Q37: 0 | R37: 0 | S37: 0 | T37: 0 | U37: 0 | V37: 0 | W37: 0 | X37: 0 | Y37: 0 | Z37: 0 | AA37: 0 | AB37: 0 | AC37: 0 | AD37: 0 | AE37: 0 | AF37: 0 | AG37: 0 | AH37: 0 | AI37: 0 | AJ37: 0
B38: Construction | D38: 0 | E38: 0 | F38: 0 | G38: 0 | H38: 0.4 | I38: 0.4 | J38: 0.2 | K38: 0 | L38: 0 | M38: 0 | N38: 0 | O38: 0 | P38: 0 | Q38: 0 | R38: 0 | S38: 0 | T38: 0 | U38: 0 | V38: 0 | W38: 0 | X38: 0 | Y38: 0 | Z38: 0 | AA38: 0 | AB38: 0 | AC38: 0 | AD38: 0 | AE38: 0 | AF38: 0 | AG38: 0 | AH38: 0 | AI38: 0 | AJ38: 0
B39: Operation | D39: =IF(D$35=1,100%,0%) -> 0 | E39: =IF(E$35=1,100%,0%) -> 0 | F39: =IF(F$35=1,100%,0%) -> 0 | G39: =IF(G$35=1,100%,0%) -> 0 | H39: =IF(H$35=1,100%,0%) -> 0 | I39: =IF(I$35=1,100%,0%) -> 0 | J39: =IF(J$35=1,100%,0%) -> 1 | K39: =IF(K$35=1,100%,0%) -> 1 | ... AJ39: =IF(AJ$35=1,100%,0%) -> 0
B40: Decommission | D40: 0 | E40: 0 | F40: 0 | G40: 0 | H40: 0 | I40: 0 | J40: 0 | K40: 0 | L40: 0 | M40: 0 | N40: 0 | O40: 0 | P40: 0 | Q40: 0 | R40: 0 | S40: 0 | T40: 0 | U40: 0 | V40: 0 | W40: 0 | X40: 0 | Y40: 0 | Z40: 0 | AA40: 0 | AB40: 0 | AC40: 0 | AD40: 0 | AE40: 0 | AF40: 0 | AG40: 0 | AH40: 0 | AI40: 0.5 | AJ40: 0.5
B43: Earnings Assumption
B44: Asset life (year) - from above | D44: =D$34 -> -4 | E44: =E$34 -> -3 | F44: =F$34 -> -2 | G44: =G$34 -> -1 | H44: =H$34 -> 0 | I44: =I$34 -> 1 | J44: =J$34 -> 2 | K44: =K$34 -> 3 | ... AJ44: =AJ$34 -> 28
B45: Periods with subsidy (year) - 1/0 | D45: 0 | E45: 0 | F45: 0 | G45: 0 | H45: 0 | I45: 0 | J45: 1 | K45: 1 | L45: 1 | M45: 1 | N45: 1 | O45: 1 | P45: 1 | Q45: 1 | R45: 1 | S45: 1 | T45: 1 | U45: 1 | V45: 1 | W45: 1 | X45: 0 | Y45: 0 | Z45: 0 | AA45: 0 | AB45: 0 | AC45: 0 | AD45: 0 | AE45: 0 | AF45: 0 | AG45: 0 | AH45: 0 | AI45: 0 | AJ45: 0
B46: Windfarm Revenue - from Subsidy €/MWh | D46: =D$45*$C$29*D$39 -> 0 | E46: =E$45*$C$29*E$39 -> 0 | F46: =F$45*$C$29*F$39 -> 0 | G46: =G$45*$C$29*G$39 -> 0 | H46: =H$45*$C$29*H$39 -> 0 | I46: =I$45*$C$29*I$39 -> 0 | J46: =J$45*$C$29*J$39 -> 53.25 | K46: =K$45*$C$29*K$39 -> 53.25 | ... W46: =W$45*$C$29*W$39 -> 53.25 | X46: 1 | Y46: =Y$45*$C$29*Y$39 -> 0 | Z46: =Z$45*$C$29*Z$39 -> 0 | AA46: =AA$45*$C$29*AA$39 -> 0 | AB46: =AB$45*$C$29*AB$39 -> 0 | AC46: =AC$45*$C$29*AC$39 -> 0 | AD46: =AD$45*$C$29*AD$39 -> 0 | AE46: =AE$45*$C$29*AE$39 -> 0 | AF46: =AF$45*$C$29*AF$39 -> 0 | ... AJ46: =AJ$45*$C$29*AJ$39 -> 0
B47: Market electricity price €/MWh | D47: 50 | E47: 50 | F47: 50 | G47: 50 | H47: 50 | I47: 50 | J47: 50 | K47: 50 | L47: 50 | M47: 50 | N47: 50 | O47: 50 | P47: 50 | Q47: 50 | R47: 50 | S47: 50 | T47: 50 | U47: 50 | V47: 50 | W47: 50 | X47: 50 | Y47: 50 | Z47: 50 | AA47: 50 | AB47: 50 | AC47: 50 | AD47: 50 | AE47: 50 | AF47: 50 | AG47: 50 | AH47: 50 | AI47: 50 | AJ47: 50
B48: Windfarm Revenue - from Market electricity price €/MWh | D48: =D$47*D$39*NOT(D$45) -> 0 | E48: =E$47*E$39*NOT(E$45) -> 0 | F48: =F$47*F$39*NOT(F$45) -> 0 | G48: =G$47*G$39*NOT(G$45) -> 0 | H48: =H$47*H$39*NOT(H$45) -> 0 | I48: =I$47*I$39*NOT(I$45) -> 0 | J48: =J$47*J$39*NOT(J$45) -> 0 | K48: =K$47*K$39*NOT(K$45) -> 0 | ... AJ48: =AJ$47*AJ$39*NOT(AJ$45) -> 0

Sheet OPEX Input
B2: ="FID Year -------->" -> FID Year --------> | C2: Year 0 in the timeline
B3: All Values are Real in FID Year
B7: OPEX Assumptions
L8: OPEX milEUR per year per MW | O8: 60000 | P8: EUR
B9: OPEX (Offshore windfarm) | C9: =O8*'CAPEX-Input'!L5/1000000 -> 45 | D9: (mil.EUR/Year)
B10: OPEX (transmission) | C10: ='CAPEX-Input'!L27 -> 3.08855 | D10: (mil.EUR/Year)
B11: Total OPEX Cost | C11: =SUM(C9:C10) -> 48.08855 | D11: (mil.EUR/Year)
D15: (mil.EUR)
D16: (Development) | H16: (FID) | J16: (Operation) | AI16: (Decom)
B17: Project Life Cycle (Year) | D17: ='FIN_Inputs&ProjectTimeline'!D$34 -> -4 | E17: ='FIN_Inputs&ProjectTimeline'!E$34 -> -3 | F17: ='FIN_Inputs&ProjectTimeline'!F$34 -> -2 | G17: ='FIN_Inputs&ProjectTimeline'!G$34 -> -1 | H17: ='FIN_Inputs&ProjectTimeline'!H$34 -> 0 | I17: ='FIN_Inputs&ProjectTimeline'!I$34 -> 1 | J17: ='FIN_Inputs&ProjectTimeline'!J$34 -> 2 | K17: ='FIN_Inputs&ProjectTimeline'!K$34 -> 3 | ... AJ17: ='FIN_Inputs&ProjectTimeline'!AJ$34 -> 28
B18: Wind Farm Operation (1/0) | D18: ='FIN_Inputs&ProjectTimeline'!D$35 -> 0 | E18: ='FIN_Inputs&ProjectTimeline'!E$35 -> 0 | F18: ='FIN_Inputs&ProjectTimeline'!F$35 -> 0 | G18: ='FIN_Inputs&ProjectTimeline'!G$35 -> 0 | H18: ='FIN_Inputs&ProjectTimeline'!H$35 -> 0 | I18: ='FIN_Inputs&ProjectTimeline'!I$35 -> 0 | J18: ='FIN_Inputs&ProjectTimeline'!J$35 -> 1 | K18: ='FIN_Inputs&ProjectTimeline'!K$35 -> 1 | ... AJ18: ='FIN_Inputs&ProjectTimeline'!AJ$35 -> 0
B19: OPEX Expenditure - R | D19: =$C$11*'FIN_Inputs&ProjectTimeline'!D$39 -> 0 | E19: =$C$11*'FIN_Inputs&ProjectTimeline'!E$39 -> 0 | F19: =$C$11*'FIN_Inputs&ProjectTimeline'!F$39 -> 0 | G19: =$C$11*'FIN_Inputs&ProjectTimeline'!G$39 -> 0 | H19: =$C$11*'FIN_Inputs&ProjectTimeline'!H$39 -> 0 | I19: =$C$11*'FIN_Inputs&ProjectTimeline'!I$39 -> 0 | J19: =$C$11*'FIN_Inputs&ProjectTimeline'!J$39 -> 48.08855 | K19: =$C$11*'FIN_Inputs&ProjectTimeline'!K$39 -> 48.08855 | ... AJ19: =$C$11*'FIN_Inputs&ProjectTimeline'!AJ$39 -> 0

Sheet AEP_Calculation
B2: Weibull Distribution & AEP calculation
C4: Mean Wind Speed
C5: ="@100m height" -> @100m height | E5: 9.8 | G5: (m/s) | J5: Total Hours | K5: 8760 | L5: (hrs)
C6: Wind Shear | E6: 0.1 | F6: (Exponent for open waters) | J6: Average PBA (availability) | K6: 0.98
C7: ="@ Hub height" -> @ Hub height | E7: =E5*('CAPEX-Input'!$L$12/100)^E6 -> 9.8938505 | G7: (m/s)
C9: Weibull Assumptions | J9: Loss Factor Assumptions
C10: Shape Factor | E10: 2.4 | J10: Turbine Availability & Performance loss | K10: =1-K6 -> 0.02
C11: Mean Wind Speed | E11: =E7 -> 9.8938505 | G11: (m/s) | J11: Wake Loss | K11: 0.09
C12: Scale Parameter | E12: =E11/_xlfn.GAMMA(1+(1/E10)) -> 11.160801 | J12: Array Cable loss | K12: 0.02
C13: Turbine | E13: ='CAPEX-Input'!$L$6 -> 10 | G13: (MW) | J13: Export cable loss | K13: 0
J14: Turbine Transformer Loss | K14: 0
J15: OHVS loss | K15: 0
J16: Curtailment & BOP availability | K16: 0
J18: Efficiency (%) | K18: =(1-K10)*(1-K11)*(1-K12)*(1-K13)*(1-K14)*(1-K15)*(1-K16) -> 0.873964
B19: Wind Speed | C19: PDF | D19: Hours | E19: Power Curve Values (KW) | F19: Power Curve Values (MW) | G19: Energy Production
B20: 0 | C20: =_xlfn.WEIBULL.DIST(B20,$E$10,$E$12,FALSE) -> 0 | D20: =$K$5*C20 -> 0 | E20: 0 | F20: =E20/1000 -> 0 | G20: =F20*D20 -> 0
B21: 1 | C21: =_xlfn.WEIBULL.DIST(B21,$E$10,$E$12,FALSE) -> 0.0073183638 | D21: =$K$5*C21 -> 64.108867 | E21: 0 | F21: =E21/1000 -> 0 | G21: =F21*D21 -> 0
B22: 2 | C22: =_xlfn.WEIBULL.DIST(B22,$E$10,$E$12,FALSE) -> 0.019062209 | D22: =$K$5*C22 -> 166.98495 | E22: 0 | F22: =E22/1000 -> 0 | G22: =F22*D22 -> 0
B23: 3 | C23: =_xlfn.WEIBULL.DIST(B23,$E$10,$E$12,FALSE) -> 0.032746089 | D23: =$K$5*C23 -> 286.85574 | E23: 0 | F23: =E23/1000 -> 0 | G23: =F23*D23 -> 0
B24: 4 | C24: =_xlfn.WEIBULL.DIST(B24,$E$10,$E$12,FALSE) -> 0.046948468 | D24: =$K$5*C24 -> 411.26858 | E24: 131.25 | F24: =E24/1000 -> 0.13125 | G24: =F24*D24 -> 53.979001
B25: 5 | C25: =_xlfn.WEIBULL.DIST(B25,$E$10,$E$12,FALSE) -> 0.060406263 | D25: =$K$5*C25 -> 529.15886 | E25: 625 | F25: =E25/1000 -> 0.625 | G25: =F25*D25 -> 330.72429
B26: 6 | C26: =_xlfn.WEIBULL.DIST(B26,$E$10,$E$12,FALSE) -> 0.071983428 | D26: =$K$5*C26 -> 630.57483 | E26: 1375 | F26: =E26/1000 -> 1.375 | G26: =F26*D26 -> 867.04038
B27: 7 | C27: =_xlfn.WEIBULL.DIST(B27,$E$10,$E$12,FALSE) -> 0.08074592 | D27: =$K$5*C27 -> 707.33426 | E27: 2312.5 | F27: =E27/1000 -> 2.3125 | G27: =F27*D27 -> 1635.7105
B28: 8 | C28: =_xlfn.WEIBULL.DIST(B28,$E$10,$E$12,FALSE) -> 0.086050862 | D28: =$K$5*C28 -> 753.80555 | E28: 3562.5 | F28: =E28/1000 -> 3.5625 | G28: =F28*D28 -> 2685.4323
B29: 9 | C29: =_xlfn.WEIBULL.DIST(B29,$E$10,$E$12,FALSE) -> 0.087612071 | D29: =$K$5*C29 -> 767.48175 | E29: 5000 | F29: =E29/1000 -> 5 | G29: =F29*D29 -> 3837.4087
B30: 10 | C30: =_xlfn.WEIBULL.DIST(B30,$E$10,$E$12,FALSE) -> 0.085521181 | D30: =$K$5*C30 -> 749.16554 | E30: 6875 | F30: =E30/1000 -> 6.875 | G30: =F30*D30 -> 5150.5131
B31: 11 | C31: =_xlfn.WEIBULL.DIST(B31,$E$10,$E$12,FALSE) -> 0.080216495 | D31: =$K$5*C31 -> 702.69649 | E31: 8750 | F31: =E31/1000 -> 8.75 | G31: =F31*D31 -> 6148.5943
... B50: 30 | C50: =_xlfn.WEIBULL.DIST(B50,$E$10,$E$12,FALSE) -> 1.8771196e-05 | D50: =$K$5*C50 -> 0.16443568 | E50: 0 | F50: =E50/1000 -> 0 | G50: =F50*D50 -> 0
D54: Total AEP (from Power Curve) | G54: =SUM(G20:G50) -> 50414.205 | H54: (MWh)
D55: AEP (After all losses) | G55: =G54*K18 -> 44060.2 | H55: (MWh)
D56: Max Energy (from windspeed) | G56: =E13*K5 -> 87600 | H56: (MWh)
D57: Effective CF (%) | G57: =G55/G56 -> 0.50297032
D59: Power Curve CF | G59: =G54/G56 -> 0.57550462

Sheet AEP Input
B2: AEP Calculation
B4: Gross Capacity factor | C4: =AEP_Calculation!$G$59 -> 0.57550462
B5: Availability loss | C5: =AEP_Calculation!$K$10 -> 0.02
B6: Wake Loss | C6: =AEP_Calculation!$K$11 -> 0.09
B7: Array Cable loss | C7: =AEP_Calculation!$K$12 -> 0.02
B8: Export cable loss | C8: =AEP_Calculation!$K$13 -> 0
B9: Turbine Transformer Loss | C9: =AEP_Calculation!$K$14 -> 0
B10: OHVS loss | C10: =AEP_Calculation!$K$15 -> 0
B11: Curtailment & BOP availability | C11: =AEP_Calculation!$K$16 -> 0
B13: Net Capacity Factor | C13: =AEP_Calculation!$G$57 -> 0.50297032
B15: Gros AEP (GWh) | C15: ='CAPEX-Input'!$L$5*8760*'AEP Input'!C4/1000 -> 3781.0653
B16: Efficiency (1 - loss%) | C16: =AEP_Calculation!$K$18 -> 0.873964
B17: Net AEP (GWh) | C17: =C15*C16 -> 3304.515
D19: (GWh)
D20: (Development) | H20: (FID) | J20: (Operation) | AI20: (Decom)
B21: Project Life Cycle (Year) | D21: ='FIN_Inputs&ProjectTimeline'!D$34 -> -4 | E21: ='FIN_Inputs&ProjectTimeline'!E$34 -> -3 | F21: ='FIN_Inputs&ProjectTimeline'!F$34 -> -2 | G21: ='FIN_Inputs&ProjectTimeline'!G$34 -> -1 | H21: ='FIN_Inputs&ProjectTimeline'!H$34 -> 0 | I21: ='FIN_Inputs&ProjectTimeline'!I$34 -> 1 | J21: ='FIN_Inputs&ProjectTimeline'!J$34 -> 2 | K21: ='FIN_Inputs&ProjectTimeline'!K$34 -> 3 | ... AJ21: ='FIN_Inputs&ProjectTimeline'!AJ$34 -> 28
B22: Wind Farm Operation (1/0) | D22: ='FIN_Inputs&ProjectTimeline'!D$35 -> 0 | E22: ='FIN_Inputs&ProjectTimeline'!E$35 -> 0 | F22: ='FIN_Inputs&ProjectTimeline'!F$35 -> 0 | G22: ='FIN_Inputs&ProjectTimeline'!G$35 -> 0 | H22: ='FIN_Inputs&ProjectTimeline'!H$35 -> 0 | I22: ='FIN_Inputs&ProjectTimeline'!I$35 -> 0 | J22: ='FIN_Inputs&ProjectTimeline'!J$35 -> 1 | K22: ='FIN_Inputs&ProjectTimeline'!K$35 -> 1 | ... AJ22: ='FIN_Inputs&ProjectTimeline'!AJ$35 -> 0
B23: Gross AEP (GWh) | D23: =$C$15*'FIN_Inputs&ProjectTimeline'!D$39 -> 0 | E23: =$C$15*'FIN_Inputs&ProjectTimeline'!E$39 -> 0 | F23: =$C$15*'FIN_Inputs&ProjectTimeline'!F$39 -> 0 | G23: =$C$15*'FIN_Inputs&ProjectTimeline'!G$39 -> 0 | H23: =$C$15*'FIN_Inputs&ProjectTimeline'!H$39 -> 0 | I23: =$C$15*'FIN_Inputs&ProjectTimeline'!I$39 -> 0 | J23: =$C$15*'FIN_Inputs&ProjectTimeline'!J$39 -> 3781.0653 | K23: =$C$15*'FIN_Inputs&ProjectTimeline'!K$39 -> 3781.0653 | ... AJ23: =$C$15*'FIN_Inputs&ProjectTimeline'!AJ$39 -> 0
B24: Efficiency (1 - losses) | D24: =$C$16 -> 0.873964 | E24: =$C$16 -> 0.873964 | F24: =$C$16 -> 0.873964 | G24: =$C$16 -> 0.873964 | H24: =$C$16 -> 0.873964 | I24: =$C$16 -> 0.873964 | J24: =$C$16 -> 0.873964 | K24: =$C$16 -> 0.873964 | ... AJ24: =$C$16 -> 0.873964
B25: Net AEP (GWh) | D25: =('CAPEX-Input'!$L$5*8760*$C$13/1000)*'FIN_Inputs&ProjectTimeline'!D$39 -> 0 | E25: =('CAPEX-Input'!$L$5*8760*$C$13/1000)*'FIN_Inputs&ProjectTimeline'!E$39 -> 0 | F25: =('CAPEX-Input'!$L$5*8760*$C$13/1000)*'FIN_Inputs&ProjectTimeline'!F$39 -> 0 | G25: =('CAPEX-Input'!$L$5*8760*$C$13/1000)*'FIN_Inputs&ProjectTimeline'!G$39 -> 0 | H25: =('CAPEX-Input'!$L$5*8760*$C$13/1000)*'FIN_Inputs&ProjectTimeline'!H$39 -> 0 | I25: =('CAPEX-Input'!$L$5*8760*$C$13/1000)*'FIN_Inputs&ProjectTimeline'!I$39 -> 0 | J25: =('CAPEX-Input'!$L$5*8760*$C$13/1000)*'FIN_Inputs&ProjectTimeline'!J$39 -> 3304.515 | K25: =('CAPEX-Input'!$L$5*8760*$C$13/1000)*'FIN_Inputs&ProjectTimeline'!K$39 -> 3304.515 | ... AJ25: =('CAPEX-Input'!$L$5*8760*$C$13/1000)*'FIN_Inputs&ProjectTimeline'!AJ$39 -> 0

Sheet Summary
B2: Inflation & Tax rate
B3: Inflation rate | C3: ='FIN_Inputs&ProjectTimeline'!$C$7 -> 0.02
B4: Effective Corporate Tax Rate | C4: ='FIN_Inputs&ProjectTimeline'!$C$16 -> 0.25
B6: WACC Summary
B7: WACC (Nominal Pre-tax) | C7: ='FIN_Inputs&ProjectTimeline'!$C19 -> 0.052
B8: WACC (Nominal Post-tax) | C8: ='FIN_Inputs&ProjectTimeline'!$C20 -> 0.045
B9: WACC (Real - Pre tax) | C9: ='FIN_Inputs&ProjectTimeline'!$C21 -> 0.031372549
B10: WACC (Real - Post tax) | C10: ='FIN_Inputs&ProjectTimeline'!$C22 -> 0.024509804
B12: Earnings Assumption
B13: Subsidy | C13: ='FIN_Inputs&ProjectTimeline'!$C$29 -> 53.25 | D13: (EUR/MWh)
B14: Subdidy Period | C14: ='FIN_Inputs&ProjectTimeline'!$C$30 -> 15 | D14: (Years)
B15: Electricity Price | C15: ='FIN_Inputs&ProjectTimeline'!$C$31 -> 50 | D15: (EUR/MWh)
B18: Project Timeline | C18: (Proportion stated in the timeline represents the spending percentage/operation percentage)
B19: Project Life Cycle (Year) | D19: ='FIN_Inputs&ProjectTimeline'!D$34 -> -4 | E19: ='FIN_Inputs&ProjectTimeline'!E$34 -> -3 | F19: ='FIN_Inputs&ProjectTimeline'!F$34 -> -2 | G19: ='FIN_Inputs&ProjectTimeline'!G$34 -> -1 | H19: ='FIN_Inputs&ProjectTimeline'!H$34 -> 0 | I19: ='FIN_Inputs&ProjectTimeline'!I$34 -> 1 | J19: ='FIN_Inputs&ProjectTimeline'!J$34 -> 2 | K19: ='FIN_Inputs&ProjectTimeline'!K$34 -> 3 | ... AJ19: ='FIN_Inputs&ProjectTimeline'!AJ$34 -> 28
B20: Wind Farm Operation (1/0) | D20: ='FIN_Inputs&ProjectTimeline'!D$35 -> 0 | E20: ='FIN_Inputs&ProjectTimeline'!E$35 -> 0 | F20: ='FIN_Inputs&ProjectTimeline'!F$35 -> 0 | G20: ='FIN_Inputs&ProjectTimeline'!G$35 -> 0 | H20: ='FIN_Inputs&ProjectTimeline'!H$35 -> 0 | I20: ='FIN_Inputs&ProjectTimeline'!I$35 -> 0 | J20: ='FIN_Inputs&ProjectTimeline'!J$35 -> 1 | K20: ='FIN_Inputs&ProjectTimeline'!K$35 -> 1 | ... AJ20: ='FIN_Inputs&ProjectTimeline'!AJ$35 -> 0
B21: Project Development | D21: ='FIN_Inputs&ProjectTimeline'!D36 -> 0.1 | E21: ='FIN_Inputs&ProjectTimeline'!E36 -> 0.1 | F21: ='FIN_Inputs&ProjectTimeline'!F36 -> 0.4 | G21: ='FIN_Inputs&ProjectTimeline'!G36 -> 0.4 | H21: ='FIN_Inputs&ProjectTimeline'!H36 -> 0 | I21: ='FIN_Inputs&ProjectTimeline'!I36 -> 0 | J21: ='FIN_Inputs&ProjectTimeline'!J36 -> 0 | K21: ='FIN_Inputs&ProjectTimeline'!K36 -> 0 | ... AJ21: ='FIN_Inputs&ProjectTimeline'!AJ36 -> 0
B22: Financial Close | D22: ='FIN_Inputs&ProjectTimeline'!D37 -> 0 | E22: ='FIN_Inputs&ProjectTimeline'!E37 -> 0 | F22: ='FIN_Inputs&ProjectTimeline'!F37 -> 0 | G22: ='FIN_Inputs&ProjectTimeline'!G37 -> 0 | H22: ='FIN_Inputs&ProjectTimeline'!H37 -> FID | I22: ='FIN_Inputs&ProjectTimeline'!I37 -> 0 | J22: ='FIN_Inputs&ProjectTimeline'!J37 -> 0 | K22: ='FIN_Inputs&ProjectTimeline'!K37 -> 0 | ... AJ22: ='FIN_Inputs&ProjectTimeline'!AJ37 -> 0
B23: Construction | D23: ='FIN_Inputs&ProjectTimeline'!D38 -> 0 | E23: ='FIN_Inputs&ProjectTimeline'!E38 -> 0 | F23: ='FIN_Inputs&ProjectTimeline'!F38 -> 0 | G23: ='FIN_Inputs&ProjectTimeline'!G38 -> 0 | H23: 0.4 | I23: 0.4 | J23: 0.2 | K23: ='FIN_Inputs&ProjectTimeline'!K38 -> 0 | L23: ='FIN_Inputs&ProjectTimeline'!L38 -> 0 | M23: ='FIN_Inputs&ProjectTimeline'!M38 -> 0 | N23: ='FIN_Inputs&ProjectTimeline'!N38 -> 0 | O23: ='FIN_Inputs&ProjectTimeline'!O38 -> 0 | P23: ='FIN_Inputs&ProjectTimeline'!P38 -> 0 | Q23: ='FIN_Inputs&ProjectTimeline'!Q38 -> 0 | R23: ='FIN_Inputs&ProjectTimeline'!R38 -> 0 | ... AJ23: ='FIN_Inputs&ProjectTimeline'!AJ38 -> 0
B24: Operation | D24: ='FIN_Inputs&ProjectTimeline'!D39 -> 0 | E24: ='FIN_Inputs&ProjectTimeline'!E39 -> 0 | F24: ='FIN_Inputs&ProjectTimeline'!F39 -> 0 | G24: ='FIN_Inputs&ProjectTimeline'!G39 -> 0 | H24: ='FIN_Inputs&ProjectTimeline'!H39 -> 0 | I24: ='FIN_Inputs&ProjectTimeline'!I39 -> 0 | J24: ='FIN_Inputs&ProjectTimeline'!J39 -> 1 | K24: ='FIN_Inputs&ProjectTimeline'!K39 -> 1 | ... AJ24: ='FIN_Inputs&ProjectTimeline'!AJ39 -> 0
B25: Decommission | D25: ='FIN_Inputs&ProjectTimeline'!D40 -> 0 | E25: ='FIN_Inputs&ProjectTimeline'!E40 -> 0 | F25: ='FIN_Inputs&ProjectTimeline'!F40 -> 0 | G25: ='FIN_Inputs&ProjectTimeline'!G40 -> 0 | H25: ='FIN_Inputs&ProjectTimeline'!H40 -> 0 | I25: ='FIN_Inputs&ProjectTimeline'!I40 -> 0 | J25: ='FIN_Inputs&ProjectTimeline'!J40 -> 0 | K25: ='FIN_Inputs&ProjectTimeline'!K40 -> 0 | ... AJ25: ='FIN_Inputs&ProjectTimeline'!AJ40 -> 0.5
D27: (mil. EUR)
B28: Cost Summary - R
B29: DEVEX | D29: =D21*'CAPEX-Input'!$C$4 -> 8.925 | E29: =E21*'CAPEX-Input'!$C$4 -> 8.925 | F29: =F21*'CAPEX-Input'!$C$4 -> 35.7 | G29: =G21*'CAPEX-Input'!$C$4 -> 35.7 | H29: =H21*'CAPEX-Input'!$C$4 -> 0 | I29: =I21*'CAPEX-Input'!$C$4 -> 0 | J29: =J21*'CAPEX-Input'!$C$4 -> 0 | K29: =K21*'CAPEX-Input'!$C$4 -> 0 | ... AJ29: =AJ21*'CAPEX-Input'!$C$4 -> 0
B30: Turbine Supply | D30: 0 | E30: 0 | F30: 0 | G30: 0 | H30: ='CAPEX-Input'!$C$5 -> 1000 | I30: 0 | J30: 0 | K30: 0 | L30: 0 | M30: 0 | N30: 0 | O30: 0 | P30: 0 | Q30: 0 | R30: 0 | S30: 0 | T30: 0 | U30: 0 | V30: 0 | W30: 0 | X30: 0 | Y30: 0 | Z30: 0 | AA30: 0 | AB30: 0 | AC30: 0 | AD30: 0 | AE30: 0 | AF30: 0 | AG30: 0 | AH30: 0 | AI30: 0 | AJ30: 0
B31: Foundation Supply | D31: 0 | E31: 0 | F31: 0 | G31: 0 | H31: ='CAPEX-Input'!$C$9 -> 214 | I31: 0 | J31: 0 | K31: 0 | L31: 0 | M31: 0 | N31: 0 | O31: 0 | P31: 0 | Q31: 0 | R31: 0 | S31: 0 | T31: 0 | U31: 0 | V31: 0 | W31: 0 | X31: 0 | Y31: 0 | Z31: 0 | AA31: 0 | AB31: 0 | AC31: 0 | AD31: 0 | AE31: 0 | AF31: 0 | AG31: 0 | AH31: 0 | AI31: 0 | AJ31: 0
B32: Installation | D32: 0 | E32: 0 | F32: 0 | G32: 0 | H32: ='CAPEX-Input'!$C$19 -> 272.07294 | I32: 0 | J32: 0 | K32: 0 | L32: 0 | M32: 0 | N32: 0 | O32: 0 | P32: 0 | Q32: 0 | R32: 0 | S32: 0 | T32: 0 | U32: 0 | V32: 0 | W32: 0 | X32: 0 | Y32: 0 | Z32: 0 | AA32: 0 | AB32: 0 | AC32: 0 | AD32: 0 | AE32: 0 | AF32: 0 | AG32: 0 | AH32: 0 | AI32: 0 | AJ32: 0
B33: Electrical Supply (Until Landfall) | D33: 0 | E33: 0 | F33: 0 | G33: 0 | H33: ='CAPEX-Input'!$C$23 -> 230.61177 | I33: 0 | J33: 0 | K33: 0 | L33: 0 | M33: 0 | N33: 0 | O33: 0 | P33: 0 | Q33: 0 | R33: 0 | S33: 0 | T33: 0 | U33: 0 | V33: 0 | W33: 0 | X33: 0 | Y33: 0 | Z33: 0 | AA33: 0 | AB33: 0 | AC33: 0 | AD33: 0 | AE33: 0 | AF33: 0 | AG33: 0 | AH33: 0 | AI33: 0 | AJ33: 0
B34: Other CAPEX | D34: 0 | E34: 0 | F34: 0 | G34: 0 | H34: ='CAPEX-Input'!$C$27 -> 204.02136 | I34: 0 | J34: 0 | K34: 0 | L34: 0 | M34: 0 | N34: 0 | O34: 0 | P34: 0 | Q34: 0 | R34: 0 | S34: 0 | T34: 0 | U34: 0 | V34: 0 | W34: 0 | X34: 0 | Y34: 0 | Z34: 0 | AA34: 0 | AB34: 0 | AC34: 0 | AD34: 0 | AE34: 0 | AF34: 0 | AG34: 0 | AH34: 0 | AI34: 0 | AJ34: 0
B35: CAPEX | D35: =D23*('CAPEX-Input'!$C$29-'CAPEX-Input'!$C$4) -> 0 | E35: =E23*('CAPEX-Input'!$C$29-'CAPEX-Input'!$C$4) -> 0 | F35: =F23*('CAPEX-Input'!$C$29-'CAPEX-Input'!$C$4) -> 0 | G35: =G23*('CAPEX-Input'!$C$29-'CAPEX-Input'!$C$4) -> 0 | H35: =H23*('CAPEX-Input'!$C$29-'CAPEX-Input'!$C$4) -> 768.28243 | I35: =I23*('CAPEX-Input'!$C$29-'CAPEX-Input'!$C$4) -> 768.28243 | J35: =J23*('CAPEX-Input'!$C$29-'CAPEX-Input'!$C$4) -> 384.14121 | K35: =K23*('CAPEX-Input'!$C$29-'CAPEX-Input'!$C$4) -> 0 | ... AJ35: =AJ23*('CAPEX-Input'!$C$29-'CAPEX-Input'!$C$4) -> 0
B36: OPEX | D36: ='OPEX Input'!D$19*D24 -> 0 | E36: ='OPEX Input'!E$19*E24 -> 0 | F36: ='OPEX Input'!F$19*F24 -> 0 | G36: ='OPEX Input'!G$19*G24 -> 0 | H36: ='OPEX Input'!H$19*H24 -> 0 | I36: ='OPEX Input'!I$19*I24 -> 0 | J36: ='OPEX Input'!J$19*J24 -> 48.08855 | K36: ='OPEX Input'!K$19*K24 -> 48.08855 | ... AJ36: ='OPEX Input'!AJ$19*AJ24 -> 0
B37: DECOM | D37: =D25*'CAPEX-Input'!$C$19 -> 0 | E37: =E25*'CAPEX-Input'!$C$19 -> 0 | F37: =F25*'CAPEX-Input'!$C$19 -> 0 | G37: =G25*'CAPEX-Input'!$C$19 -> 0 | H37: =H25*'CAPEX-Input'!$C$19 -> 0 | I37: =I25*'CAPEX-Input'!$C$19 -> 0 | J37: =J25*'CAPEX-Input'!$C$19 -> 0 | K37: =K25*'CAPEX-Input'!$C$19 -> 0 | ... AH37: =AH25*'CAPEX-Input'!$C$19 -> 0 | AI37: =AI25*'CAPEX-Input'!$C$31 -> 88.423705 | AJ37: =AJ25*'CAPEX-Input'!$C$31 -> 88.423705
C39: Total
B40: Capital Expenditures - R | C40: =SUM(D40:AJ40) -> 2009.9561 | D40: =SUM(D29,D35) -> 8.925 | E40: =SUM(E29,E35) -> 8.925 | F40: =SUM(F29,F35) -> 35.7 | G40: =SUM(G29,G35) -> 35.7 | H40: =SUM(H29,H35) -> 768.28243 | I40: =SUM(I29,I35) -> 768.28243 | J40: =SUM(J29,J35) -> 384.14121 | K40: =SUM(K29,K35) -> 0 | ... AJ40: =SUM(AJ29,AJ35) -> 0
B41: OPEX & DECOM Expenditures - R | C41: =SUM(D41:AJ41) -> 1379.0612 | D41: =SUM(D36:D37) -> 0 | E41: =SUM(E36:E37) -> 0 | F41: =SUM(F36:F37) -> 0 | G41: =SUM(G36:G37) -> 0 | H41: =SUM(H36:H37) -> 0 | I41: =SUM(I36:I37) -> 0 | J41: =SUM(J36:J37) -> 48.08855 | K41: =SUM(K36:K37) -> 48.08855 | ... AJ41: =SUM(AJ36:AJ37) -> 88.423705
B42: Capital Expenditures (per MW) - R | C42: =C40/'CAPEX-Input'!L5 -> 2.6799414
B44: AEP
B45: Net (GWh) | C45: =SUM(D45:AJ45) -> 82612.875 | D45: ='AEP Input'!D25*D24 -> 0 | E45: ='AEP Input'!E25*E24 -> 0 | F45: ='AEP Input'!F25*F24 -> 0 | G45: ='AEP Input'!G25*G24 -> 0 | H45: ='AEP Input'!H25*H24 -> 0 | I45: ='AEP Input'!I25*I24 -> 0 | J45: ='AEP Input'!J25*J24 -> 3304.515 | K45: ='AEP Input'!K25*K24 -> 3304.515 | ... AJ45: ='AEP Input'!AJ25*AJ24 -> 0
B47: Earnings Assumption
B48: Asset life (year) - from above | D48: ='FIN_Inputs&ProjectTimeline'!D44 -> -4 | E48: ='FIN_Inputs&ProjectTimeline'!E44 -> -3 | F48: ='FIN_Inputs&ProjectTimeline'!F44 -> -2 | G48: ='FIN_Inputs&ProjectTimeline'!G44 -> -1 | H48: ='FIN_Inputs&ProjectTimeline'!H44 -> 0 | I48: ='FIN_Inputs&ProjectTimeline'!I44 -> 1 | J48: ='FIN_Inputs&ProjectTimeline'!J44 -> 2 | K48: ='FIN_Inputs&ProjectTimeline'!K44 -> 3 | ... AJ48: ='FIN_Inputs&ProjectTimeline'!AJ44 -> 28
B49: Periods with subsidy (year) - 1/0 | D49: ='FIN_Inputs&ProjectTimeline'!D45 -> 0 | E49: ='FIN_Inputs&ProjectTimeline'!E45 -> 0 | F49: ='FIN_Inputs&ProjectTimeline'!F45 -> 0 | G49: ='FIN_Inputs&ProjectTimeline'!G45 -> 0 | H49: ='FIN_Inputs&ProjectTimeline'!H45 -> 0 | I49: ='FIN_Inputs&ProjectTimeline'!I45 -> 0 | J49: ='FIN_Inputs&ProjectTimeline'!J45 -> 1 | K49: ='FIN_Inputs&ProjectTimeline'!K45 -> 1 | ... AJ49: ='FIN_Inputs&ProjectTimeline'!AJ45 -> 0
...

Sheet DCF_Calculations
B1: (All cells are referenced from Summary Sheet)
D3: (Development) | H3: (FID) | J3: (Operation) | AI3: (Decom)
B4: Project Life Cycle (Year) | D4: =Summary!D$19 -> -4 | E4: =Summary!E$19 -> -3 | F4: =Summary!F$19 -> -2 | G4: =Summary!G$19 -> -1 | H4: =Summary!H$19 -> 0 | I4: =Summary!I$19 -> 1 | J4: =Summary!J$19 -> 2 | K4: =Summary!K$19 -> 3 | ... AJ4: =Summary!AJ$19 -> 28
B5: Wind Farm Operation (1/0) | D5: =Summary!D$20 -> 0 | E5: =Summary!E$20 -> 0 | F5: =Summary!F$20 -> 0 | G5: =Summary!G$20 -> 0 | H5: =Summary!H$20 -> 0 | I5: =Summary!I$20 -> 0 | J5: =Summary!J$20 -> 1 | K5: =Summary!K$20 -> 1 | ... AJ5: =Summary!AJ$20 -> 0
B7: Farm Operation (%) | D7: =Summary!D$24 -> 0 | E7: =Summary!E$24 -> 0 | F7: =Summary!F$24 -> 0 | G7: =Summary!G$24 -> 0 | H7: =Summary!H$24 -> 0 | I7: =Summary!I$24 -> 0 | J7: =Summary!J$24 -> 1 | K7: =Summary!K$24 -> 1 | ... AJ7: =Summary!AJ$24 -> 0
B9: Financial Inputs
B10: Inflation rate | D10: =Summary!$C$3 -> 0.02 | E10: =Summary!$C$3 -> 0.02 | F10: =Summary!$C$3 -> 0.02 | G10: =Summary!$C$3 -> 0.02 | H10: =Summary!$C$3 -> 0.02 | I10: =Summary!$C$3 -> 0.02 | J10: =Summary!$C$3 -> 0.02 | K10: =Summary!$C$3 -> 0.02 | ... AJ10: =Summary!$C$3 -> 0.02
B11: Effective Corporate Tax rate | D11: =Summary!$C$4 -> 0.25 | E11: =Summary!$C$4 -> 0.25 | F11: =Summary!$C$4 -> 0.25 | G11: =Summary!$C$4 -> 0.25 | H11: =Summary!$C$4 -> 0.25 | I11: =Summary!$C$4 -> 0.25 | J11: =Summary!$C$4 -> 0.25 | K11: =Summary!$C$4 -> 0.25 | ... AJ11: =Summary!$C$4 -> 0.25
B12: WACC (Nominal Pre Tax) | D12: =Summary!$C$7 -> 0.052 | E12: =Summary!$C$7 -> 0.052 | F12: =Summary!$C$7 -> 0.052 | G12: =Summary!$C$7 -> 0.052 | H12: =Summary!$C$7 -> 0.052 | I12: =Summary!$C$7 -> 0.052 | J12: =Summary!$C$7 -> 0.052 | K12: =Summary!$C$7 -> 0.052 | ... AJ12: =Summary!$C$7 -> 0.052
B13: WACC (Nominal Post Tax) | D13: =Summary!$C$8 -> 0.045 | E13: =Summary!$C$8 -> 0.045 | F13: =Summary!$C$8 -> 0.045 | G13: =Summary!$C$8 -> 0.045 | H13: =Summary!$C$8 -> 0.045 | I13: =Summary!$C$8 -> 0.045 | J13: =Summary!$C$8 -> 0.045 | K13: =Summary!$C$8 -> 0.045 | ... AJ13: =Summary!$C$8 -> 0.045
B14: WACC (Real Pre Tax) | D14: =Summary!$C$9 -> 0.031372549 | E14: =Summary!$C$9 -> 0.031372549 | F14: =Summary!$C$9 -> 0.031372549 | G14: =Summary!$C$9 -> 0.031372549 | H14: =Summary!$C$9 -> 0.031372549 | I14: =Summary!$C$9 -> 0.031372549 | J14: =Summary!$C$9 -> 0.031372549 | K14: =Summary!$C$9 -> 0.031372549 | ... AJ14: =Summary!$C$9 -> 0.031372549
B15: WACC (Real Post Tax) | D15: =Summary!$C$10 -> 0.024509804 | E15: =Summary!$C$10 -> 0.024509804 | F15: =Summary!$C$10 -> 0.024509804 | G15: =Summary!$C$10 -> 0.024509804 | H15: =Summary!$C$10 -> 0.024509804 | I15: =Summary!$C$10 -> 0.024509804 | J15: =Summary!$C$10 -> 0.024509804 | K15: =Summary!$C$10 -> 0.024509804 | ... AJ15: =Summary!$C$10 -> 0.024509804
B17: Discount Factor (multiplier)
B18: Discount factor (Nominal Pre Tax) | D18: =(1+D12)^-D4 -> 1.2247937 | E18: =(1+E12)^-E4 -> 1.1642526 | F18: =(1+F12)^-F4 -> 1.106704 | G18: =(1+G12)^-G4 -> 1.052 | H18: =(1+H12)^-H4 -> 1 | I18: =(1+I12)^-I4 -> 0.95057034 | J18: =(1+J12)^-J4 -> 0.90358398 | K18: =(1+K12)^-K4 -> 0.85892013 | ... AJ18: =(1+AJ12)^-AJ4 -> 0.24185735
B19: Discount factor (Nominal Post Tax) | D19: =(1+D13)^-D4 -> 1.1925186 | E19: =(1+E13)^-E4 -> 1.1411661 | F19: =(1+F13)^-F4 -> 1.092025 | G19: =(1+G13)^-G4 -> 1.045 | H19: =(1+H13)^-H4 -> 1 | I19: =(1+I13)^-I4 -> 0.9569378 | J19: =(1+J13)^-J4 -> 0.91572995 | K19: =(1+K13)^-K4 -> 0.8762966 | ... AJ19: =(1+AJ13)^-AJ4 -> 0.29157069
B20: Discount factor (Real Pre Tax) | D20: =(1+D14)^-D4 -> 1.1315201 | E20: =(1+E14)^-E4 -> 1.0971012 | F20: =(1+F14)^-F4 -> 1.0637293 | G20: =(1+G14)^-G4 -> 1.0313725 | H20: =(1+H14)^-H4 -> 1 | I20: =(1+I14)^-I4 -> 0.96958175 | J20: =(1+J14)^-J4 -> 0.94008877 | K20: =(1+K14)^-K4 -> 0.91149291 | ... AJ20: =(1+AJ14)^-AJ4 -> 0.4210795
B21: Discount factor (Real Post Tax ) | D21: =(1+D15)^-D4 -> 1.1017029 | E21: =(1+E15)^-E4 -> 1.0753463 | F21: =(1+F15)^-F4 -> 1.0496203 | G21: =(1+G15)^-G4 -> 1.0245098 | H21: =(1+H15)^-H4 -> 1 | I21: =(1+I15)^-I4 -> 0.97607656 | J21: =(1+J15)^-J4 -> 0.95272544 | K21: =(1+K15)^-K4 -> 0.92993297 | ... AJ21: =(1+AJ15)^-AJ4 -> 0.50763163
B23: Free Cash Flow & IRR Calculation
B25: AEP | C25: (GWh)
B26: Net AEP - R | C26: =SUM(D26:AJ26) -> 82612.875 | D26: =Summary!D$45 -> 0 | E26: =Summary!E$45 -> 0 | F26: =Summary!F$45 -> 0 | G26: =Summary!G$45 -> 0 | H26: =Summary!H$45 -> 0 | I26: =Summary!I$45 -> 0 | J26: =Summary!J$45 -> 3304.515 | K26: =Summary!K$45 -> 3304.515 | ... AJ26: =Summary!AJ$45 -> 0
B28: Earnings/Revenue | C28: (mil. EUR)
B29: Periods with subsidy (year) - (1/0) | D29: =Summary!D$49 -> 0 | E29: =Summary!E$49 -> 0 | F29: =Summary!F$49 -> 0 | G29: =Summary!G$49 -> 0 | H29: =Summary!H$49 -> 0 | I29: =Summary!I$49 -> 0 | J29: =Summary!J$49 -> 1 | K29: =Summary!K$49 -> 1 | ... AJ29: =Summary!AJ$49 -> 0
B30: Subsidy revenue | D30: =D$26*Summary!D$50/1000 -> 0 | E30: =E$26*Summary!E$50/1000 -> 0 | F30: =F$26*Summary!F$50/1000 -> 0 | G30: =G$26*Summary!G$50/1000 -> 0 | H30: =H$26*Summary!H$50/1000 -> 0 | I30: =I$26*Summary!I$50/1000 -> 0 | J30: =J$26*Summary!J$50/1000 -> 175.96542 | K30: =K$26*Summary!K$50/1000 -> 175.96542 | ... AJ30: =AJ$26*Summary!AJ$50/1000 -> 0
B31: Market revenue | D31: =D$26*Summary!D$51/1000 -> 0 | E31: =E$26*Summary!E$51/1000 -> 0 | F31: =F$26*Summary!F$51/1000 -> 0 | G31: =G$26*Summary!G$51/1000 -> 0 | H31: =H$26*Summary!H$51/1000 -> 0 | I31: =I$26*Summary!I$51/1000 -> 0 | J31: =J$26*Summary!J$51/1000 -> 0 | K31: =K$26*Summary!K$51/1000 -> 0 | ... AJ31: =AJ$26*Summary!AJ$51/1000 -> 0
B32: Total Earnings (Subsidy + Market Revenue) - R | C32: =SUM(D32:AJ32) -> 4284.3037 | D32: =SUM(D30:D31) -> 0 | E32: =SUM(E30:E31) -> 0 | F32: =SUM(F30:F31) -> 0 | G32: =SUM(G30:G31) -> 0 | H32: =SUM(H30:H31) -> 0 | I32: =SUM(I30:I31) -> 0 | J32: =SUM(J30:J31) -> 175.96542 | K32: =SUM(K30:K31) -> 175.96542 | ... AJ32: =SUM(AJ30:AJ31) -> 0
B34: EBITDA Calculation
B35: Earnings - R | C35: =SUM(D35:AJ35) -> 4284.3037 | D35: =D$32 -> 0 | E35: =E$32 -> 0 | F35: =F$32 -> 0 | G35: =G$32 -> 0 | H35: =H$32 -> 0 | I35: =I$32 -> 0 | J35: =J$32 -> 175.96542 | K35: =K$32 -> 175.96542 | ... AJ35: =AJ$32 -> 0
B36: OPEX Expenditure - R | C36: =SUM(D36:AJ36) -> -1202.2137 | D36: =-Summary!D$36 -> 0 | E36: =-Summary!E$36 -> 0 | F36: =-Summary!F$36 -> 0 | G36: =-Summary!G$36 -> 0 | H36: =-Summary!H$36 -> 0 | I36: =-Summary!I$36 -> 0 | J36: =-Summary!J$36 -> -48.08855 | K36: =-Summary!K$36 -> -48.08855 | ... AJ36: =-Summary!AJ$36 -> 0
B37: EBITDA - R | C37: =SUM(C35:C36) -> 3082.0899 | D37: =SUM(D35:D36) -> 0 | E37: =SUM(E35:E36) -> 0 | F37: =SUM(F35:F36) -> 0 | G37: =SUM(G35:G36) -> 0 | H37: =SUM(H35:H36) -> 0 | I37: =SUM(I35:I36) -> 0 | J37: =SUM(J35:J36) -> 127.87687 | ... AJ37: =SUM(AJ35:AJ36) -> 0
B39: Depreciation Calculation | C39: (mil. EUR)
B40: Depreciation (Straight Line Method)
B41: Opening Balance | D41: 0 | E41: =D45 -> 8.925 | F41: =E45 -> 17.85 | G41: =F45 -> 53.55 | H41: =G45 -> 89.25 | I41: =H45 -> 857.53243 | J41: =I45 -> 1625.8149 | K41: =J45 -> 1929.5578 | L41: =K45 -> 1849.1596 | ... AJ41: =AI45 -> 0
B42: Investment - R Input | C42: =SUM(D42:AJ42) -> 2009.9561 | D42: =Summary!D$40 -> 8.925 | E42: =Summary!E$40 -> 8.925 | F42: =Summary!F$40 -> 35.7 | G42: =Summary!G$40 -> 35.7 | H42: =Summary!H$40 -> 768.28243 | I42: =Summary!I$40 -> 768.28243 | J42: =Summary!J$40 -> 384.14121 | K42: =Summary!K$40 -> 0 | ... AJ42: =Summary!AJ$40 -> 0
B43: Depreciation - R Input | D43: 0 | E43: 0 | F43: 0 | G43: 0 | H43: 0 | I43: 0 | J43: =$C$42/'FIN_Inputs&ProjectTimeline'!$C$8 -> 80.398243 | K43: =$C$42/'FIN_Inputs&ProjectTimeline'!$C$8 -> 80.398243 | L43: =$C$42/'FIN_Inputs&ProjectTimeline'!$C$8 -> 80.398243 | M43: =$C$42/'FIN_Inputs&ProjectTimeline'!$C$8 -> 80.398243 | N43: =$C$42/'FIN_Inputs&ProjectTimeline'!$C$8 -> 80.398243 | O43: =$C$42/'FIN_Inputs&ProjectTimeline'!$C$8 -> 80.398243 | P43: =$C$42/'FIN_Inputs&ProjectTimeline'!$C$8 -> 80.398243 | Q43: =$C$42/'FIN_Inputs&ProjectTimeline'!$C$8 -> 80.398243 | ... AH43: =$C$42/'FIN_Inputs&ProjectTimeline'!$C$8 -> 80.398243 | AI43: 0 | AJ43: 0
B44: Asset Value (Before Depreciation) | D44: =D41 -> 0 | E44: =E41 -> 8.925 | F44: =F41 -> 17.85 | G44: =G41 -> 53.55 | H44: =H41 -> 89.25 | I44: =I41 -> 857.53243 | J44: =J41 -> 1625.8149 | K44: =K41 -> 1929.5578 | ... AJ44: =AJ41 -> 0
B45: Asset Value (After Depreciation) | D45: =D42+D44-D43 -> 8.925 | E45: =E42+E44-E43 -> 17.85 | F45: =F42+F44-F43 -> 53.55 | G45: =G42+G44-G43 -> 89.25 | H45: =H42+H44-H43 -> 857.53243 | I45: =I42+I44-I43 -> 1625.8149 | J45: =J42+J44-J43 -> 1929.5578 | K45: =K42+K44-K43 -> 1849.1596 | ... AH45: =AH42+AH44-AH43 -> 1.1937118e-12 | AI45: 0 | AJ45: 0
B47: Depreciation (Declining Balance Method)
B48: Residual Asset Value (Assumption) | C48: 0
B49: Depreciation Rate | D49: ='FIN_Inputs&ProjectTimeline'!$C$26 -> 0.2 | E49: ='FIN_Inputs&ProjectTimeline'!$C$26 -> 0.2 | F49: ='FIN_Inputs&ProjectTimeline'!$C$26 -> 0.2 | G49: ='FIN_Inputs&ProjectTimeline'!$C$26 -> 0.2 | H49: ='FIN_Inputs&ProjectTimeline'!$C$26 -> 0.2 | I49: ='FIN_Inputs&ProjectTimeline'!$C$26 -> 0.2 | J49: ='FIN_Inputs&ProjectTimeline'!$C$26 -> 0.2 | K49: ='FIN_Inputs&ProjectTimeline'!$C$26 -> 0.2 | ... AJ49: ='FIN_Inputs&ProjectTimeline'!$C$26 -> 0.2
B51: Opening Balance | D51: 0 | E51: =D55 -> 8.925 | F51: =E55 -> 17.85 | G51: =F55 -> 53.55 | H51: =G55 -> 89.25 | I51: =H55 -> 857.53243 | J51: =I55 -> 1625.8149 | K51: =J55 -> 1684.7931 | L51: =K55 -> 1347.8345 | ... AJ51: =AI55 -> 0
...

Sheet Results
B2: Results
B4: Summary
B5: Capital Investment | C5: =Summary!C40 -> 2009.9561 | D5: (mil.EUR)
B6: Specific Investment | C6: =Summary!C42 -> 2.6799414 | D6: (mil.EUR/MW)
B7: NPV (Pre Tax) | C7: =DCF_Calculations!C90 -> 21.680135 | D7: (mil.EUR)
B8: NPV (Post Tax) | C8: =DCF_Calculations!C89 -> -22.302506 | D8: (mil.EUR)
B9: IRR (Pre Tax) | C9: =DCF_Calculations!C95 -> 0.032408388 | D9: (%)
B10: IRR (Post Tax) | C10: =DCF_Calculations!C94 -> 0.023473749 | D10: (%)
B13: LCOE (Real Pre-Tax) | J13: LCOE (Real Post-Tax)
C14: EUR/MWh | D14: Numerator | E14: Denominator | K14: EUR/MWh | L14: Numerator | M14: Denominator
B15: DEVEX | C15: =D15/E15 -> 1.7231872 | D15: =SUM(DCF_Calculations!D101:AJ101) -> 94.685583 | E15: =DCF_Calculations!$C$125/1000 -> 54.947938 | J15: DEVEX | K15: =L15/M15 -> 1.5641571 | L15: =SUM(DCF_Calculations!D113:AJ113) -> 93.47661 | M15: =DCF_Calculations!$C$126/1000 -> 59.76165
B16: Turbine | C16: =D16/E16 -> 18.199045 | D16: =SUM(DCF_Calculations!D102:AJ102) -> 1000 | E16: =DCF_Calculations!$C$125/1000 -> 54.947938 | J16: Turbine | K16: =L16/M16 -> 16.733139 | L16: =SUM(DCF_Calculations!D114:AJ114) -> 1000 | M16: =DCF_Calculations!$C$126/1000 -> 59.76165 | Q16: Note: Due to the differences in the year of discounting, the total contribution of individual CAPEX components to the LCOE can differ from the Final CAPEX contribution to the LCOE. Refer to the DCF_Calculations sheet.
B17: Foundation | C17: =D17/E17 -> 3.8945957 | D17: =SUM(DCF_Calculations!D103:AJ103) -> 214 | E17: =DCF_Calculations!$C$125/1000 -> 54.947938 | J17: Foundation | K17: =L17/M17 -> 3.5808918 | L17: =SUM(DCF_Calculations!D115:AJ115) -> 214 | M17: =DCF_Calculations!$C$126/1000 -> 59.76165
B18: Installation | C18: =D18/E18 -> 4.9514677 | D18: =SUM(DCF_Calculations!D104:AJ104) -> 272.07294 | E18: =DCF_Calculations!$C$125/1000 -> 54.947938 | J18: Installation | K18: =L18/M18 -> 4.5526343 | L18: =SUM(DCF_Calculations!D116:AJ116) -> 272.07294 | M18: =DCF_Calculations!$C$126/1000 -> 59.76165
B19: Electrical | C19: =D19/E19 -> 4.196914 | D19: =SUM(DCF_Calculations!D105:AJ105) -> 230.61177 | E19: =DCF_Calculations!$C$125/1000 -> 54.947938 | J19: Electrical | K19: =L19/M19 -> 3.8588588 | L19: =SUM(DCF_Calculations!D117:AJ117) -> 230.61177 | M19: =DCF_Calculations!$C$126/1000 -> 59.76165
B20: Other CAPEX | C20: =D20/E20 -> 3.712994 | D20: =SUM(DCF_Calculations!D106:AJ106) -> 204.02136 | E20: =DCF_Calculations!$C$125/1000 -> 54.947938 | J20: Other CAPEX | K20: =L20/M20 -> 3.4139178 | L20: =SUM(DCF_Calculations!D118:AJ118) -> 204.02136 | M20: =DCF_Calculations!$C$126/1000 -> 59.76165
B21: CAPEX (Total) | C21: =D21/E21 -> 34.110869 | D21: =SUM(DCF_Calculations!D107:AJ107) -> 1874.3219 | E21: =DCF_Calculations!$C$125/1000 -> 54.947938 | J21: CAPEX (Total) | K21: =L21/M21 -> 31.528012 | L21: =SUM(DCF_Calculations!D119:AJ119) -> 1884.166 | M21: =DCF_Calculations!$C$126/1000 -> 59.76165
B22: OPEX | C22: =D22/E22 -> 14.552378 | D22: =SUM(DCF_Calculations!D108:AJ108) -> 799.62314 | E22: =DCF_Calculations!$C$125/1000 -> 54.947938 | J22: OPEX | K22: =L22/M22 -> 14.552378 | L22: =SUM(DCF_Calculations!D120:AJ120) -> 869.6741 | M22: =DCF_Calculations!$C$126/1000 -> 59.76165
B23: DECOM | C23: =D23/E23 -> 1.3764834 | D23: =SUM(DCF_Calculations!D109:AJ109) -> 75.634925 | E23: =DCF_Calculations!$C$125/1000 -> 54.947938 | J23: DECOM | K23: =L23/M23 -> 1.520599 | L23: =SUM(DCF_Calculations!D121:AJ121) -> 90.873503 | M23: =DCF_Calculations!$C$126/1000 -> 59.76165
B24: LCOE | C24: =D24/E24 -> 51.762917 | D24: =DCF_Calculations!$C$110 -> 2844.2655 | E24: =DCF_Calculations!$C$125/1000 -> 54.947938 | J24: Tax Payments | K24: =L24/M24 -> 3.3032535 | L24: =SUM(DCF_Calculations!D128:AJ128) -> 197.40788 | M24: =DCF_Calculations!$C$126/1000 -> 59.76165
J25: LCOE | K25: =L25/M25 -> 52.468399 | L25: =SUM(DCF_Calculations!$C$122+DCF_Calculations!$C$128) -> 3135.5981 | M25: =DCF_Calculations!$C$126/1000 -> 59.76165
B27: Levelized Revenue (Real Pre-Tax) | J27: Levelized Revenue (Real Post-Tax)
B28: Revenues | C28: =D28/E28 -> 52.157475 | D28: =DCF_Calculations!C131 -> 2865.9457 | E28: =DCF_Calculations!$C$125/1000 -> 54.947938 | J28: Revenue | K28: =L28/M28 -> 52.095208 | L28: =DCF_Calculations!C132 -> 3113.2956 | M28: =DCF_Calculations!$C$126/1000 -> 59.76165
B29: Profit | C29: =C28-C24 -> 0.39455775 | J29: Profit | K29: =K28-K25 -> -0.37319093
B30: Check (profit/loss) | C30: =IF(C7>0&C29>0,"OK","LOSS") -> OK | J30: Check (profit/loss) | K30: =IF(C8>0&K29>0,"OK","LOSS") -> OK
